Workbook

Sheet ECRITURES
A1: JOURNAL | B1: LIBELLE JOURNAL | C1: DATE | D1: N° PIECE | E1: REFERENCE | F1: COMPTE | G1: INTITULE COMPTE | H1: CODE TIERS | I1: NOM TIERS | J1: LIBELLE | K1: DEBIT | L1: CREDIT
A2: 01001 | B2: REOUVERTURE | C2: 46022 | F2: 10100 | G2: CAPITAL EMIS | J2: REOUVERTURE AU 01/01/26 | K2: 0 | L2: 106000000
A3: 01001 | B3: REOUVERTURE | C3: 46022 | F3: 10500 | G3: Ecart de réévaluation | J3: REOUVERTURE AU 01/01/26 | K3: 0 | L3: 120163.5
A4: 01001 | B4: REOUVERTURE | C4: 46022 | F4: 10610 | G4: RESERVES LEGALES | J4: REOUVERTURE AU 01/01/26 | K4: 0 | L4: 7003771.4
A5: 01001 | B5: REOUVERTURE | C5: 46022 | F5: 10611 | G5: BENEFICES A REINVESTIR | J5: REOUVERTURE AU 01/01/26 | K5: 0 | L5: 25922342
A6: 01001 | B6: REOUVERTURE | C6: 46022 | F6: 10620 | G6: RESERVES STATUTAIRES | J6: REOUVERTURE AU 01/01/26 | K6: 0 | L6: 211183
A7: 01001 | B7: REOUVERTURE | C7: 46022 | F7: 10630 | G7: RESERVES FACULTATIVES | J7: REOUVERTURE AU 01/01/26 | K7: 0 | L7: 44091060
A8: 01001 | B8: REOUVERTURE | C8: 46022 | F8: 11000 | G8: REPORT A NOUVEAU | J8: REOUVERTURE AU 01/01/26 | K8: 1508496.6 | L8: 0
A9: 01001 | B9: REOUVERTURE | C9: 46022 | F9: 11001 | G9: AJUST RESUL CH METHODE CPTE | J9: REOUVERTURE AU 01/01/26 | K9: 150790.11 | L9: 0
A10: 01001 | B10: REOUVERTURE | C10: 46022 | F10: 21100 | G10: TERRAINS | J10: REOUVERTURE AU 01/01/26 | K10: 21600000 | L10: 0
A11: 01001 | B11: REOUVERTURE | C11: 46022 | F11: 21300 | G11: Constructions | J11: REOUVERTURE AU 01/01/26 | K11: 13891000 | L11: 0
A12: 01001 | B12: REOUVERTURE | C12: 46022 | F12: 21301 | G12: CHARPENTE METALIQUE | J12: REOUVERTURE AU 01/01/26 | K12: 20222222 | L12: 0
A13: 01001 | B13: REOUVERTURE | C13: 46022 | F13: 21500 | G13: INSTALATIONS TECHNIQUES,MAERIE | J13: REOUVERTURE AU 01/01/26 | K13: 2713848.8 | L13: 0
... A25: 01001 | B25: REOUVERTURE | C25: 46022 | F25: 30002 | G25: ST IMPORTATION | J25: REOUVERTURE AU 01/01/26 | K25: 2.2873401e+08 | L25: 0
A26: 01001 | B26: REOUVERTURE | C26: 46022 | F26: 40100 | G26: Fournisseurs de stocks et serv | H26: FL001 | I26: DJENNADI ABD ELKADER | J26: REOUVERTURE AU 01/01/26 | K26: 0 | L26: 2510665
A27: 01001 | B27: REOUVERTURE | C27: 46022 | F27: 40100 | G27: Fournisseurs de stocks et serv | H27: FL002 | I27: EURL HAROUNE TRANSE | J27: REOUVERTURE AU 01/01/26 | K27: 0 | L27: 826173.63
A28: 01001 | B28: REOUVERTURE | C28: 46022 | F28: 40100 | G28: Fournisseurs de stocks et serv | H28: FL003 | I28: SARL CCI | J28: REOUVERTURE AU 01/01/26 | K28: 0 | L28: 3302997.5
A29: 01001 | B29: REOUVERTURE | C29: 46022 | F29: 40100 | G29: Fournisseurs de stocks et serv | H29: FL005 | I29: KARIM TRANS | J29: REOUVERTURE AU 01/01/26 | K29: 0 | L29: 177751.46
A30: 01001 | B30: REOUVERTURE | C30: 46022 | F30: 40100 | G30: Fournisseurs de stocks et serv | H30: FL025 | I30: SAIGH ABDEL KAMEL | J30: REOUVERTURE AU 01/01/26 | K30: 0 | L30: 142700
A31: 01001 | B31: REOUVERTURE | C31: 46022 | F31: 40100 | G31: Fournisseurs de stocks et serv | H31: FL031 | I31: SARL DPR AXXAM | J31: REOUVERTURE AU 01/01/26 | K31: 0 | L31: 1984749
A32: 01001 | B32: REOUVERTURE | C32: 46022 | F32: 40100 | G32: Fournisseurs de stocks et serv | H32: FL044 | I32: SNC AIT AISSA ET FILS | J32: REOUVERTURE AU 01/01/26 | K32: 0 | L32: 14832876
A33: 01001 | B33: REOUVERTURE | C33: 46022 | F33: 40100 | G33: Fournisseurs de stocks et serv | H33: FL045 | I33: GAMMA LUBRIFIANTS | J33: REOUVERTURE AU 01/01/26 | K33: 0 | L33: 926579.49
A34: 01001 | B34: REOUVERTURE | C34: 46022 | F34: 40100 | G34: Fournisseurs de stocks et serv | H34: FL051 | I34: DJERMOULI KAMAL ABDENNOUR | J34: REOUVERTURE AU 01/01/26 | K34: 0 | L34: 9100
A35: 01001 | B35: REOUVERTURE | C35: 46022 | F35: 40100 | G35: Fournisseurs de stocks et serv | H35: FL064 | I35: STATION GAMMA 4 | J35: REOUVERTURE AU 01/01/26 | K35: 0 | L35: 153309.95
A36: 01001 | B36: REOUVERTURE | C36: 46022 | F36: 40100 | G36: Fournisseurs de stocks et serv | H36: FL076 | I36: SNC DEBBOUZ ET FRERES | J36: REOUVERTURE AU 01/01/26 | K36: 0 | L36: 738432.49
A37: 01001 | B37: REOUVERTURE | C37: 46022 | F37: 40100 | G37: Fournisseurs de stocks et serv | H37: FL078 | I37: TRANSIT HAMMACHE DJAMEL | J37: REOUVERTURE AU 01/01/26 | K37: 0 | L37: 62000
... A95: 01001 | B95: REOUVERTURE | C95: 46022 | F95: 41100 | G95: Clients | H95: C978 | I95: SPA AGGLOMERES DE L'EST | J95: REOUVERTURE AU 01/01/26 | K95: 67830 | L95: 0
A96: 01001 | B96: REOUVERTURE | C96: 46022 | F96: 41170 | G96: CLIENTS-RETENUES DE GARANTIE | J96: REOUVERTURE AU 01/01/26 | K96: 490717.68 | L96: 0
A97: 01001 | B97: REOUVERTURE | C97: 46022 | F97: 41900 | G97: Clients créditeurs -avances re | H97: AC002 | I97: DJENNADI AHCENE | J97: REOUVERTURE AU 01/01/26 | K97: 0 | L97: 500000
A98: 01001 | B98: REOUVERTURE | C98: 46022 | F98: 41900 | G98: Clients créditeurs -avances re | H98: AC009 | I98: SARL DPR AXXAM | J98: REOUVERTURE AU 01/01/26 | K98: 0 | L98: 9821942.2
A99: 01001 | B99: REOUVERTURE | C99: 46022 | F99: 41900 | G99: Clients créditeurs -avances re | H99: AC014 | I99: SARL TRANS FAID | J99: REOUVERTURE AU 01/01/26 | K99: 0 | L99: 1843316.1
A100: 01001 | B100: REOUVERTURE | C100: 46022 | F100: 41900 | G100: Clients créditeurs -avances re | H100: AC048 | I100: MADI ALLAOUA | J100: REOUVERTURE AU 01/01/26 | K100: 0 | L100: 2660000
A101: 01001 | B101: REOUVERTURE | C101: 46022 | F101: 41900 | G101: Clients créditeurs -avances re | H101: AC067 | I101: DJENNADI REYAD | J101: REOUVERTURE AU 01/01/26 | K101: 0 | L101: 17609544
A102: 01001 | B102: REOUVERTURE | C102: 46022 | F102: 41900 | G102: Clients créditeurs -avances re | H102: AC111 | I102: SNC NASAF GALOUL ET CIE | J102: REOUVERTURE AU 01/01/26 | K102: 0 | L102: 1929169.5
A103: 01001 | B103: REOUVERTURE | C103: 46022 | F103: 41900 | G103: Clients créditeurs -avances re | H103: AC129 | I103: HAGROUD ABD ELAZIZE | J103: REOUVERTURE AU 01/01/26 | K103: 0 | L103: 48000
A104: 01001 | B104: REOUVERTURE | C104: 46022 | F104: 41900 | G104: Clients créditeurs -avances re | H104: AC144 | I104: SELLAH ABD ELGHANI | J104: REOUVERTURE AU 01/01/26 | K104: 0 | L104: 300000
A105: 01001 | B105: REOUVERTURE | C105: 46022 | F105: 41900 | G105: Clients créditeurs -avances re | H105: AC145 | I105: EURL CARRIER LES BIBIANS | J105: REOUVERTURE AU 01/01/26 | K105: 0 | L105: 800000
A106: 01001 | B106: REOUVERTURE | C106: 46022 | F106: 41900 | G106: Clients créditeurs -avances re | H106: AC189 | I106: MECHREF MOUHOUB | J106: REOUVERTURE AU 01/01/26 | K106: 0 | L106: 3509008.3
A107: 01001 | B107: REOUVERTURE | C107: 46022 | F107: 41900 | G107: Clients créditeurs -avances re | H107: AC191 | I107: OUKHALED YASSINE | J107: REOUVERTURE AU 01/01/26 | K107: 0 | L107: 5638.26
A108: 01001 | B108: REOUVERTURE | C108: 46022 | F108: 41900 | G108: Clients créditeurs -avances re | H108: AC206 | I108: CHEBBAH NACER | J108: REOUVERTURE AU 01/01/26 | K108: 0 | L108: 100000
...

Sheet JOURNAUX
A1: JOURNAL | B1: LIBELLE | C1: NB LIGNES | D1: TOTAL DEBIT | E1: TOTAL CREDIT | F1: ECART
A2: 01001 | B2: REOUVERTURE | C2: =SUMPRODUCT((ECRITURES!$A$2:$A$3071=A2)*1) | D2: =SUMPRODUCT((ECRITURES!$A$2:$A$3071=A2)*ECRITURES!$K$2:$K$3071) | E2: =SUMPRODUCT((ECRITURES!$A$2:$A$3071=A2)*ECRITURES!$L$2:$L$3071) | F2: =D2-E2
A3: 07001 | B3: JOURNAL DE REGULARISATION | C3: =SUMPRODUCT((ECRITURES!$A$2:$A$3071=A3)*1) | D3: =SUMPRODUCT((ECRITURES!$A$2:$A$3071=A3)*ECRITURES!$K$2:$K$3071) | E3: =SUMPRODUCT((ECRITURES!$A$2:$A$3071=A3)*ECRITURES!$L$2:$L$3071) | F3: =D3-E3
A4: 02001 | B4: BANQUE CPA | C4: =SUMPRODUCT((ECRITURES!$A$2:$A$3071=A4)*1) | D4: =SUMPRODUCT((ECRITURES!$A$2:$A$3071=A4)*ECRITURES!$K$2:$K$3071) | E4: =SUMPRODUCT((ECRITURES!$A$2:$A$3071=A4)*ECRITURES!$L$2:$L$3071) | F4: =D4-E4
A5: 16001 | B5: BANQUE SOCIETE GENERALE | C5: =SUMPRODUCT((ECRITURES!$A$2:$A$3071=A5)*1) | D5: =SUMPRODUCT((ECRITURES!$A$2:$A$3071=A5)*ECRITURES!$K$2:$K$3071) | E5: =SUMPRODUCT((ECRITURES!$A$2:$A$3071=A5)*ECRITURES!$L$2:$L$3071) | F5: =D5-E5
A6: 05001 | B6: ACHATS IMPORTATION | C6: =SUMPRODUCT((ECRITURES!$A$2:$A$3071=A6)*1) | D6: =SUMPRODUCT((ECRITURES!$A$2:$A$3071=A6)*ECRITURES!$K$2:$K$3071) | E6: =SUMPRODUCT((ECRITURES!$A$2:$A$3071=A6)*ECRITURES!$L$2:$L$3071) | F6: =D6-E6
A7: 10001 | B7: STOCKS | C7: =SUMPRODUCT((ECRITURES!$A$2:$A$3071=A7)*1) | D7: =SUMPRODUCT((ECRITURES!$A$2:$A$3071=A7)*ECRITURES!$K$2:$K$3071) | E7: =SUMPRODUCT((ECRITURES!$A$2:$A$3071=A7)*ECRITURES!$L$2:$L$3071) | F7: =D7-E7
A8: 06002 | B8: VENTES | C8: =SUMPRODUCT((ECRITURES!$A$2:$A$3071=A8)*1) | D8: =SUMPRODUCT((ECRITURES!$A$2:$A$3071=A8)*ECRITURES!$K$2:$K$3071) | E8: =SUMPRODUCT((ECRITURES!$A$2:$A$3071=A8)*ECRITURES!$L$2:$L$3071) | F8: =D8-E8
A9: 15001 | B9: VENTES DETAIL FENAIA | C9: =SUMPRODUCT((ECRITURES!$A$2:$A$3071=A9)*1) | D9: =SUMPRODUCT((ECRITURES!$A$2:$A$3071=A9)*ECRITURES!$K$2:$K$3071) | E9: =SUMPRODUCT((ECRITURES!$A$2:$A$3071=A9)*ECRITURES!$L$2:$L$3071) | F9: =D9-E9
A10: 08002 | B10: OPPERATION DIVERS | C10: =SUMPRODUCT((ECRITURES!$A$2:$A$3071=A10)*1) | D10: =SUMPRODUCT((ECRITURES!$A$2:$A$3071=A10)*ECRITURES!$K$2:$K$3071) | E10: =SUMPRODUCT((ECRITURES!$A$2:$A$3071=A10)*ECRITURES!$L$2:$L$3071) | F10: =D10-E10
A11: 14002 | B11: OD TPM ET LOCATION | C11: =SUMPRODUCT((ECRITURES!$A$2:$A$3071=A11)*1) | D11: =SUMPRODUCT((ECRITURES!$A$2:$A$3071=A11)*ECRITURES!$K$2:$K$3071) | E11: =SUMPRODUCT((ECRITURES!$A$2:$A$3071=A11)*ECRITURES!$L$2:$L$3071) | F11: =D11-E11

Sheet BALANCE
A1: COMPTE | B1: INTITULE | C1: DEBIT | D1: CREDIT | E1: SOLDE DEBITEUR | F1: SOLDE CREDITEUR
A2: 10100 | B2: CAPITAL EMIS | C2: =SUMPRODUCT((ECRITURES!$F$2:$F$3071=A2)*ECRITURES!$K$2:$K$3071) | D2: =SUMPRODUCT((ECRITURES!$F$2:$F$3071=A2)*ECRITURES!$L$2:$L$3071) | E2: =MAX(C2-D2,0) | F2: =MAX(D2-C2,0)
A3: 10500 | B3: Ecart de réévaluation | C3: =SUMPRODUCT((ECRITURES!$F$2:$F$3071=A3)*ECRITURES!$K$2:$K$3071) | D3: =SUMPRODUCT((ECRITURES!$F$2:$F$3071=A3)*ECRITURES!$L$2:$L$3071) | E3: =MAX(C3-D3,0) | F3: =MAX(D3-C3,0)
A4: 10610 | B4: RESERVES LEGALES | C4: =SUMPRODUCT((ECRITURES!$F$2:$F$3071=A4)*ECRITURES!$K$2:$K$3071) | D4: =SUMPRODUCT((ECRITURES!$F$2:$F$3071=A4)*ECRITURES!$L$2:$L$3071) | E4: =MAX(C4-D4,0) | F4: =MAX(D4-C4,0)
A5: 10611 | B5: BENEFICES A REINVESTIR | C5: =SUMPRODUCT((ECRITURES!$F$2:$F$3071=A5)*ECRITURES!$K$2:$K$3071) | D5: =SUMPRODUCT((ECRITURES!$F$2:$F$3071=A5)*ECRITURES!$L$2:$L$3071) | E5: =MAX(C5-D5,0) | F5: =MAX(D5-C5,0)
A6: 10620 | B6: RESERVES STATUTAIRES | C6: =SUMPRODUCT((ECRITURES!$F$2:$F$3071=A6)*ECRITURES!$K$2:$K$3071) | D6: =SUMPRODUCT((ECRITURES!$F$2:$F$3071=A6)*ECRITURES!$L$2:$L$3071) | E6: =MAX(C6-D6,0) | F6: =MAX(D6-C6,0)
A7: 10630 | B7: RESERVES FACULTATIVES | C7: =SUMPRODUCT((ECRITURES!$F$2:$F$3071=A7)*ECRITURES!$K$2:$K$3071) | D7: =SUMPRODUCT((ECRITURES!$F$2:$F$3071=A7)*ECRITURES!$L$2:$L$3071) | E7: =MAX(C7-D7,0) | F7: =MAX(D7-C7,0)
A8: 11000 | B8: REPORT A NOUVEAU | C8: =SUMPRODUCT((ECRITURES!$F$2:$F$3071=A8)*ECRITURES!$K$2:$K$3071) | D8: =SUMPRODUCT((ECRITURES!$F$2:$F$3071=A8)*ECRITURES!$L$2:$L$3071) | E8: =MAX(C8-D8,0) | F8: =MAX(D8-C8,0)
A9: 11001 | B9: AJUST RESUL CH METHODE CPTE | C9: =SUMPRODUCT((ECRITURES!$F$2:$F$3071=A9)*ECRITURES!$K$2:$K$3071) | D9: =SUMPRODUCT((ECRITURES!$F$2:$F$3071=A9)*ECRITURES!$L$2:$L$3071) | E9: =MAX(C9-D9,0) | F9: =MAX(D9-C9,0)
A10: 12000 | B10: RESULTAT DE L'EXERCICE | C10: =SUMPRODUCT((ECRITURES!$F$2:$F$3071=A10)*ECRITURES!$K$2:$K$3071) | D10: =SUMPRODUCT((ECRITURES!$F$2:$F$3071=A10)*ECRITURES!$L$2:$L$3071) | E10: =MAX(C10-D10,0) | F10: =MAX(D10-C10,0)
A11: 21100 | B11: TERRAINS | C11: =SUMPRODUCT((ECRITURES!$F$2:$F$3071=A11)*ECRITURES!$K$2:$K$3071) | D11: =SUMPRODUCT((ECRITURES!$F$2:$F$3071=A11)*ECRITURES!$L$2:$L$3071) | E11: =MAX(C11-D11,0) | F11: =MAX(D11-C11,0)
A12: 21300 | B12: Constructions | C12: =SUMPRODUCT((ECRITURES!$F$2:$F$3071=A12)*ECRITURES!$K$2:$K$3071) | D12: =SUMPRODUCT((ECRITURES!$F$2:$F$3071=A12)*ECRITURES!$L$2:$L$3071) | E12: =MAX(C12-D12,0) | F12: =MAX(D12-C12,0)
A13: 21301 | B13: CHARPENTE METALIQUE | C13: =SUMPRODUCT((ECRITURES!$F$2:$F$3071=A13)*ECRITURES!$K$2:$K$3071) | D13: =SUMPRODUCT((ECRITURES!$F$2:$F$3071=A13)*ECRITURES!$L$2:$L$3071) | E13: =MAX(C13-D13,0) | F13: =MAX(D13-C13,0)
... A91: 76800 | B91: Autres produits financiers | C91: =SUMPRODUCT((ECRITURES!$F$2:$F$3071=A91)*ECRITURES!$K$2:$K$3071) | D91: =SUMPRODUCT((ECRITURES!$F$2:$F$3071=A91)*ECRITURES!$L$2:$L$3071) | E91: =MAX(C91-D91,0) | F91: =MAX(D91-C91,0)
B92: TOTAL | C92: =SUM(C2:C91) | D92: =SUM(D2:D91) | E92: =SUM(E2:E91) | F92: =SUM(F2:F91)

Sheet PLAN COMPTABLE
A1: COMPTE | B1: INTITULE
A2: 10100 | B2: CAPITAL EMIS
A3: 10500 | B3: Ecart de réévaluation
A4: 10610 | B4: RESERVES LEGALES
A5: 10611 | B5: BENEFICES A REINVESTIR
A6: 10620 | B6: RESERVES STATUTAIRES
A7: 10630 | B7: RESERVES FACULTATIVES
A8: 10700 | B8: Ecart d'équivalence
A9: 10800
A10: 11000 | B10: REPORT A NOUVEAU
A11: 11001 | B11: AJUST RESUL CH METHODE CPTE
A12: 12000 | B12: RESULTAT DE L'EXERCICE
A13: 13300 | B13: Impôts différés actif
A14: 16400 | B14: Emprunts auprès des établissem
A15: 16401 | B15: EMPRUNT ENGINS
A16: 16402 | B16: EMPRUNT 2016
A17: 18100 | B17: Comptes de liaison entre établ
A18: 21100 | B18: TERRAINS
A19: 21200 | B19: Agencements et aménagements de
A20: 21220 | B20: MATERIEL PROT. CONTRE INCENDIE
A21: 21300 | B21: Constructions
... A218: 76800 | B218: Autres produits financiers

Sheet TIERS
A1: CODE TIERS | B1: NOM
A2: 00X00 | B2: CODE DIVERS CREE PAR PCCOMPTAP
A3: AC | B3: ACOMPTES/SALAIRES
A4: AC001 | B4: SNC BAPIVAET CIE
A5: AC002 | B5: DJENNADI AHCENE
A6: AC003 | B6: KADRI REDOUANE
A7: AC004 | B7: MEGROUS HOCINE
A8: AC005 | B8: DJENNADI ABDELKRIM
A9: AC006 | B9: ISAADI LAID
A10: AC007 | B10: SNC FRERES CHABAT
A11: AC008 | B11: TEI AHMED
A12: AC009 | B12: SARL DPR AXXAM
... A421: AF40 | B421: ZHENJIANG AUTO
A422: C
A423: C001 | B423: BENKHELIFA CHEIKH
A424: C002 | B424: DJENNADI LYAZID
A425: C003 | B425: DJENNADI ABDELKADER
A426: C004 | B426: DJENNADI ABDELKRIM
A427: C005 | B427: EURL AMAD EDDINE SABLIERE
A428: C006 | B428: GUESSOUME MASSAOUD
A429: C007 | B429: KHALDI OMAR
A430: C008 | B430: NAFTAL GPL TIARET
A431: C009 | B431: NAFTAL DMR ORAN
A432: C010 | B432: NAFTAL SPA-BRANCHE GPL-DIRECTI
A433: C011 | B433: NAFTAL UNM EST CONSTANTINE
A434: C012 | B434: SARL HAMOUDI TRANS
... A1517: CD001 | B1517: CLIENTS COMPTOIR DETAIL
A1518: DC
A1519: DCT004 | B1519: BATROUNI MOKHTAR
A1520: DCT006 | B1520: BRAHMI SAID
A1521: DCT008 | B1521: TOUAZI HACENE
A1522: DCT013 | B1522: EL HOUANNES ZAHIR
A1523: DCT014 | B1523: EL HOUANNES BOUALEM
A1524: FE001 | B1524: BS MOTORS
A1525: FE002 | B1525: QINGDAO RULONG
A1526: FE003 | B1526: SAMPA OTOMOTIVE
A1527: FE004 | B1527: NINGGUO FEIYING AUTO SPARE
A1528: FE005 | B1528: UNION INTERNATIONAL
A1529: FE006 | B1529: SIPROF
A1530: FE007 | B1530: YPS DIS TICARET TURQUIE
...

Sheet CODES JOURNAUX
A1: JOURNAL | B1: LIBELLE
A2: 01001 | B2: REOUVERTURE
A3: 02001 | B3: BANQUE CPA
A4: 03001 | B4: BANQUE EL BARAKA
A5: 04001 | B5: CAISSE
A6: 05001 | B6: ACHATS IMPORTATION
A7: 06002 | B7: VENTES
A8: 07001 | B8: JOURNAL DE REGULARISATION
A9: 08002 | B9: OPPERATION DIVERS
A10: 09001 | B10: INVESTISSEMENTS
A11: 10001 | B11: STOCKS
A12: 11001 | B12: ACHATS LOCAUX
... A18: 16001 | B18: BANQUE SOCIETE GENERALE
