Workbook

Sheet Lisez-moi
A1: Journal des ventes au détail — SARL DPR COMPAGNY, établissement de Fenaia Il Maten
A3: Rubrique | B3: Détail
A4: Établissement | B4: Lieu-dit Abadou, commune de Fenaia Il Maten, wilaya de Béjaïa (cachet « Pièces détachées et Réparation mécanique »)
A5: Registre de commerce | B5: Établissement secondaire 06/04-0184232 B 03, inscrit le 10/09/2024 (extrait n° 920064572 du 11/09/2024)
A6: Activités inscrites | B6: 506003 pièces détachées et accessoires auto, 506002 outillage, 506006 pneumatiques, 506007 batteries, 506008 huiles et graisses, 613204 réparation mécanique, 605024 salle d'exposition
A7: Fiscalité | B7: NIF 000306018423274 ; article d'imposition 06180778071 ; déclaration d'existence du 03/03/2026 (début d'activité déclaré 10/09/2024) ; IBS
A8: Ce qui change | B8: Un nouveau journal 15001 « VENTES DETAIL FENAIA » ; banque (51220) et caisse (53000) inchangées
A10: Contrôles
A11: Journal 15001 équilibré | B11: =IF(ABS('JOURNAL 15001'!L904)<0.01,"OK","ERREUR")
A12: Encaissements équilibrés | B12: =IF(ABS('Encaissements comptant'!L603-'Encaissements comptant'!M603)<0.01,"OK","ERREUR")
A13: CA HT du journal = brouillard | B13: =IF(ABS(SUMIFS('JOURNAL 15001'!M2:M901,'JOURNAL 15001'!G2:G901,Paramètres!$B$8)+SUMIFS('JOURNAL 15001'!M2:M901,'JOURNAL 15001'!G2:G901,Paramètres!$B$9)-'Brouillard ventes'!F306)<0.01,"OK","ERREUR")
A14: Récapitulatif = brouillard (année de suivi seule) | B14: =IF(ABS('Récap mensuel G50'!D17-SUMIFS('Brouillard ventes'!$F$6:$F$305,'Brouillard ventes'!$A$6:$A$305,">="&DATE('Récap mensuel G50'!B2,1,1),'Brouillard ventes'!$A$6:$A$305,"<"&DATE('Récap mensuel G50'!B2+1,1,1)))<0.01,"OK","ÉCART")
A16: Mode d'emploi
A17: 1. Créer dans PCCOMPTA le journal et les comptes listés dans « Paramètres » (lignes 17 à 24).
A18: 2. Saisir chaque jour les ventes dans « Brouillard ventes » (une ligne par facture ou ticket ; la ligne 6 est un exemple à remplacer).
A19: 3. Copier « JOURNAL 15001 » (lignes non vides) dans PCCOMPTA ; les règlements comptant sont dans « Encaissements comptant » (journaux 04001 / 02001).
A20: 4. En fin de mois, reporter « Récap mensuel G50 » sur la G50 de l'établissement et passer la constatation de TVA (Écritures types).
A21: 5. Régulariser les ventes au détail réalisées depuis le 10/09/2024 : aucune n'apparaît dans les journaux 2024 et 2025.

Sheet Paramètres
A1: Paramètres et création du journal dans PCCOMPTA
A2: Cellules jaunes = hypothèses modifiables. Banque (51220, journal 02001) et caisse (53000, journal 04001) : inchangées.
A4: Paramètre | B4: Valeur | C4: Source / commentaire
A5: Taux de TVA (revente en l'état et réparation) | B5: 0.19 | C5: Taux porté sur les G50 2026 (ligne E3B22)
A6: Taux du droit de timbre sur paiements en espèces | B6: 0.01 | C6: Taux appliqué sur la G50 IMPORT de février 2026 (63 720 / 6 372 000) ; barème à confirmer avec l'inspection
A7: Compte client par défaut (vente comptoir) | B7: 41100 | C7: Avec le code auxiliaire CD001 « CLIENTS COMPTOIR DETAIL »
A8: Compte de ventes de marchandises au détail | B8: 70003 | C8: Nouveau compte
A9: Compte de prestations de réparation mécanique | B9: 70604 | C9: Nouveau compte (activité 613204)
A10: Compte de TVA collectée ventes détail | B10: 44519 | C10: Nouveau compte : TVA du détail suivie à part, soldée mensuellement par la G50
A11: Code unité (établissement) | B11: FEN | C11: Code_UNT PCCOMPTA pour isoler Fenaia dans toutes les écritures
A12: Article d'imposition de l'établissement | B12: 06180778071 | C12: Déclaration d'existence du 03/03/2026
A15: Lignes à ajouter dans les tables PCCOMPTA
A16: Table | B16: CODE | C16: LIBELLE | D16: NATURE / Remarque
A17: TAB_JRN | B17: 15001 | C17: VENTES DETAIL FENAIA | D17: Divers
A18: TAB_COM | B18: 70003 | C18: VENTES M/SES DETAIL FENAIA | D18: Produits
A19: TAB_COM | B19: 70604 | C19: PRESTATIONS REPARATION MECANIQUE | D19: Produits (activité 613204)
A20: TAB_COM | B20: 44519 | C20: TVA COLLECTEE VENTES DETAIL | D20: Dette fiscale
A21: TAB_COM | B21: 30003 | C21: STOCK MAGASIN DETAIL FENAIA | D21: Stock du magasin (transferts depuis 30002)
A22: TAB_AUX | B22: CD001 | C22: CLIENTS COMPTOIR DETAIL | D22: Clients de passage ; créer CD002, CD003… pour les clients à crédit
A23: TAB_UNT | B23: FEN | C23: ETABLISSEMENT FENAIA IL MATEN (DETAIL) | D23: Établissement secondaire RC 06/04-0184232 B 03
A24: TAB_UNT | B24: SIE | C24: SIEGE TIZI SMAOUN (IMPORT) | D24: Pour l'activité d'importation

Sheet Brouillard ventes
A1: Brouillard des ventes au détail — établissement de Fenaia Il Maten
A2: Saisir une ligne par facture ou ticket (colonnes jaunes). TVA, TTC et écritures sont calculées. La ligne 6 est un EXEMPLE : la remplacer par la première vraie vente.
A3: Mode de règlement : Espèces / Chèque / Virement / À crédit. Nature : Marchandises / Réparation.
A5: Date | B5: N° facture / ticket | C5: Code client | D5: Nom du client | E5: Nature | F5: Montant HT | G5: Taux TVA | H5: TVA | I5: TTC | J5: Mode de règlement | K5: Observations
A6: =DATE(2026,10,5) | B6: FD-0001 | C6: CD001 | D6: CLIENT COMPTOIR (EXEMPLE) | E6: Marchandises | F6: 10000 | G6: =IF(F6="","",Paramètres!$B$5) | H6: =IF(F6="","",ROUND(F6*G6,2)) | I6: =IF(F6="","",F6+H6) | J6: Espèces | K6: Ligne d'exemple à remplacer
G7: =IF(F7="","",Paramètres!$B$5) | H7: =IF(F7="","",ROUND(F7*G7,2)) | I7: =IF(F7="","",F7+H7)
G8: =IF(F8="","",Paramètres!$B$5) | H8: =IF(F8="","",ROUND(F8*G8,2)) | I8: =IF(F8="","",F8+H8)
G9: =IF(F9="","",Paramètres!$B$5) | H9: =IF(F9="","",ROUND(F9*G9,2)) | I9: =IF(F9="","",F9+H9)
G10: =IF(F10="","",Paramètres!$B$5) | H10: =IF(F10="","",ROUND(F10*G10,2)) | I10: =IF(F10="","",F10+H10)
G11: =IF(F11="","",Paramètres!$B$5) | H11: =IF(F11="","",ROUND(F11*G11,2)) | I11: =IF(F11="","",F11+H11)
G12: =IF(F12="","",Paramètres!$B$5) | H12: =IF(F12="","",ROUND(F12*G12,2)) | I12: =IF(F12="","",F12+H12)
G13: =IF(F13="","",Paramètres!$B$5) | H13: =IF(F13="","",ROUND(F13*G13,2)) | I13: =IF(F13="","",F13+H13)
G14: =IF(F14="","",Paramètres!$B$5) | H14: =IF(F14="","",ROUND(F14*G14,2)) | I14: =IF(F14="","",F14+H14)
G15: =IF(F15="","",Paramètres!$B$5) | H15: =IF(F15="","",ROUND(F15*G15,2)) | I15: =IF(F15="","",F15+H15)
G16: =IF(F16="","",Paramètres!$B$5) | H16: =IF(F16="","",ROUND(F16*G16,2)) | I16: =IF(F16="","",F16+H16)
G17: =IF(F17="","",Paramètres!$B$5) | H17: =IF(F17="","",ROUND(F17*G17,2)) | I17: =IF(F17="","",F17+H17)
G18: =IF(F18="","",Paramètres!$B$5) | H18: =IF(F18="","",ROUND(F18*G18,2)) | I18: =IF(F18="","",F18+H18)
... G305: =IF(F305="","",Paramètres!$B$5) | H305: =IF(F305="","",ROUND(F305*G305,2)) | I305: =IF(F305="","",F305+H305)
E306: TOTAUX | F306: =SUM(F6:F305) | H306: =SUM(H6:H305) | I306: =SUM(I6:I305)

Sheet JOURNAL 15001
A1: FOLIO | B1: PIECE | C1: DATE | D1: REFERENCE | E1: LIBELLE | F1: CODE_JRN | G1: CODE_COM | H1: CODE_AUX | I1: CODE_BDG | J1: CODE_NAT | K1: CODE_UNT | L1: DEBIT | M1: CREDIT | N1: LETTRAGE | O1: LIBELLEA | P1: CTP_COM | Q1: CTP_AUX | R1: ECHEANCE
A2: 1 | B2: =IF('Brouillard ventes'!$F$6="","","VD"&TEXT(ROW('Brouillard ventes'!$F$6)-5,"00000")) | C2: =IF('Brouillard ventes'!$F$6="","",YEAR('Brouillard ventes'!$A$6)*10000+MONTH('Brouillard ventes'!$A$6)*100+DAY('Brouillard ventes'!$A$6)) | D2: =IF('Brouillard ventes'!$F$6="","",'Brouillard ventes'!$B$6) | E2: =IF('Brouillard ventes'!$F$6="","",LEFT('Brouillard ventes'!$D$6,30)) | F2: 15001 | G2: =IF('Brouillard ventes'!$F$6="","",Paramètres!$B$7) | H2: =IF('Brouillard ventes'!$F$6="","",IF('Brouillard ventes'!$C$6="","CD001",'Brouillard ventes'!$C$6)) | K2: =IF('Brouillard ventes'!$F$6="","",Paramètres!$B$11) | L2: =IF('Brouillard ventes'!$F$6="","",'Brouillard ventes'!$I$6) | M2: 0
A3: 1 | B3: =IF('Brouillard ventes'!$F$6="","","VD"&TEXT(ROW('Brouillard ventes'!$F$6)-5,"00000")) | C3: =IF('Brouillard ventes'!$F$6="","",YEAR('Brouillard ventes'!$A$6)*10000+MONTH('Brouillard ventes'!$A$6)*100+DAY('Brouillard ventes'!$A$6)) | D3: =IF('Brouillard ventes'!$F$6="","",'Brouillard ventes'!$B$6) | E3: =IF('Brouillard ventes'!$F$6="","",LEFT('Brouillard ventes'!$D$6,30)) | F3: 15001 | G3: =IF('Brouillard ventes'!$F$6="","",IF('Brouillard ventes'!$E$6="Réparation",Paramètres!$B$9,Paramètres!$B$8)) | K3: =IF('Brouillard ventes'!$F$6="","",Paramètres!$B$11) | L3: 0 | M3: =IF('Brouillard ventes'!$F$6="","",'Brouillard ventes'!$F$6)
A4: 1 | B4: =IF('Brouillard ventes'!$F$6="","","VD"&TEXT(ROW('Brouillard ventes'!$F$6)-5,"00000")) | C4: =IF('Brouillard ventes'!$F$6="","",YEAR('Brouillard ventes'!$A$6)*10000+MONTH('Brouillard ventes'!$A$6)*100+DAY('Brouillard ventes'!$A$6)) | D4: =IF('Brouillard ventes'!$F$6="","",'Brouillard ventes'!$B$6) | E4: =IF('Brouillard ventes'!$F$6="","",LEFT('Brouillard ventes'!$D$6,30)) | F4: 15001 | G4: =IF('Brouillard ventes'!$F$6="","",Paramètres!$B$10) | K4: =IF('Brouillard ventes'!$F$6="","",Paramètres!$B$11) | L4: 0 | M4: =IF('Brouillard ventes'!$F$6="","",'Brouillard ventes'!$H$6)
A5: 1 | B5: =IF('Brouillard ventes'!$F$7="","","VD"&TEXT(ROW('Brouillard ventes'!$F$7)-5,"00000")) | C5: =IF('Brouillard ventes'!$F$7="","",YEAR('Brouillard ventes'!$A$7)*10000+MONTH('Brouillard ventes'!$A$7)*100+DAY('Brouillard ventes'!$A$7)) | D5: =IF('Brouillard ventes'!$F$7="","",'Brouillard ventes'!$B$7) | E5: =IF('Brouillard ventes'!$F$7="","",LEFT('Brouillard ventes'!$D$7,30)) | F5: 15001 | G5: =IF('Brouillard ventes'!$F$7="","",Paramètres!$B$7) | H5: =IF('Brouillard ventes'!$F$7="","",IF('Brouillard ventes'!$C$7="","CD001",'Brouillard ventes'!$C$7)) | K5: =IF('Brouillard ventes'!$F$7="","",Paramètres!$B$11) | L5: =IF('Brouillard ventes'!$F$7="","",'Brouillard ventes'!$I$7) | M5: 0
A6: 1 | B6: =IF('Brouillard ventes'!$F$7="","","VD"&TEXT(ROW('Brouillard ventes'!$F$7)-5,"00000")) | C6: =IF('Brouillard ventes'!$F$7="","",YEAR('Brouillard ventes'!$A$7)*10000+MONTH('Brouillard ventes'!$A$7)*100+DAY('Brouillard ventes'!$A$7)) | D6: =IF('Brouillard ventes'!$F$7="","",'Brouillard ventes'!$B$7) | E6: =IF('Brouillard ventes'!$F$7="","",LEFT('Brouillard ventes'!$D$7,30)) | F6: 15001 | G6: =IF('Brouillard ventes'!$F$7="","",IF('Brouillard ventes'!$E$7="Réparation",Paramètres!$B$9,Paramètres!$B$8)) | K6: =IF('Brouillard ventes'!$F$7="","",Paramètres!$B$11) | L6: 0 | M6: =IF('Brouillard ventes'!$F$7="","",'Brouillard ventes'!$F$7)
A7: 1 | B7: =IF('Brouillard ventes'!$F$7="","","VD"&TEXT(ROW('Brouillard ventes'!$F$7)-5,"00000")) | C7: =IF('Brouillard ventes'!$F$7="","",YEAR('Brouillard ventes'!$A$7)*10000+MONTH('Brouillard ventes'!$A$7)*100+DAY('Brouillard ventes'!$A$7)) | D7: =IF('Brouillard ventes'!$F$7="","",'Brouillard ventes'!$B$7) | E7: =IF('Brouillard ventes'!$F$7="","",LEFT('Brouillard ventes'!$D$7,30)) | F7: 15001 | G7: =IF('Brouillard ventes'!$F$7="","",Paramètres!$B$10) | K7: =IF('Brouillard ventes'!$F$7="","",Paramètres!$B$11) | L7: 0 | M7: =IF('Brouillard ventes'!$F$7="","",'Brouillard ventes'!$H$7)
A8: 1 | B8: =IF('Brouillard ventes'!$F$8="","","VD"&TEXT(ROW('Brouillard ventes'!$F$8)-5,"00000")) | C8: =IF('Brouillard ventes'!$F$8="","",YEAR('Brouillard ventes'!$A$8)*10000+MONTH('Brouillard ventes'!$A$8)*100+DAY('Brouillard ventes'!$A$8)) | D8: =IF('Brouillard ventes'!$F$8="","",'Brouillard ventes'!$B$8) | E8: =IF('Brouillard ventes'!$F$8="","",LEFT('Brouillard ventes'!$D$8,30)) | F8: 15001 | G8: =IF('Brouillard ventes'!$F$8="","",Paramètres!$B$7) | H8: =IF('Brouillard ventes'!$F$8="","",IF('Brouillard ventes'!$C$8="","CD001",'Brouillard ventes'!$C$8)) | K8: =IF('Brouillard ventes'!$F$8="","",Paramètres!$B$11) | L8: =IF('Brouillard ventes'!$F$8="","",'Brouillard ventes'!$I$8) | M8: 0
A9: 1 | B9: =IF('Brouillard ventes'!$F$8="","","VD"&TEXT(ROW('Brouillard ventes'!$F$8)-5,"00000")) | C9: =IF('Brouillard ventes'!$F$8="","",YEAR('Brouillard ventes'!$A$8)*10000+MONTH('Brouillard ventes'!$A$8)*100+DAY('Brouillard ventes'!$A$8)) | D9: =IF('Brouillard ventes'!$F$8="","",'Brouillard ventes'!$B$8) | E9: =IF('Brouillard ventes'!$F$8="","",LEFT('Brouillard ventes'!$D$8,30)) | F9: 15001 | G9: =IF('Brouillard ventes'!$F$8="","",IF('Brouillard ventes'!$E$8="Réparation",Paramètres!$B$9,Paramètres!$B$8)) | K9: =IF('Brouillard ventes'!$F$8="","",Paramètres!$B$11) | L9: 0 | M9: =IF('Brouillard ventes'!$F$8="","",'Brouillard ventes'!$F$8)
A10: 1 | B10: =IF('Brouillard ventes'!$F$8="","","VD"&TEXT(ROW('Brouillard ventes'!$F$8)-5,"00000")) | C10: =IF('Brouillard ventes'!$F$8="","",YEAR('Brouillard ventes'!$A$8)*10000+MONTH('Brouillard ventes'!$A$8)*100+DAY('Brouillard ventes'!$A$8)) | D10: =IF('Brouillard ventes'!$F$8="","",'Brouillard ventes'!$B$8) | E10: =IF('Brouillard ventes'!$F$8="","",LEFT('Brouillard ventes'!$D$8,30)) | F10: 15001 | G10: =IF('Brouillard ventes'!$F$8="","",Paramètres!$B$10) | K10: =IF('Brouillard ventes'!$F$8="","",Paramètres!$B$11) | L10: 0 | M10: =IF('Brouillard ventes'!$F$8="","",'Brouillard ventes'!$H$8)
A11: 1 | B11: =IF('Brouillard ventes'!$F$9="","","VD"&TEXT(ROW('Brouillard ventes'!$F$9)-5,"00000")) | C11: =IF('Brouillard ventes'!$F$9="","",YEAR('Brouillard ventes'!$A$9)*10000+MONTH('Brouillard ventes'!$A$9)*100+DAY('Brouillard ventes'!$A$9)) | D11: =IF('Brouillard ventes'!$F$9="","",'Brouillard ventes'!$B$9) | E11: =IF('Brouillard ventes'!$F$9="","",LEFT('Brouillard ventes'!$D$9,30)) | F11: 15001 | G11: =IF('Brouillard ventes'!$F$9="","",Paramètres!$B$7) | H11: =IF('Brouillard ventes'!$F$9="","",IF('Brouillard ventes'!$C$9="","CD001",'Brouillard ventes'!$C$9)) | K11: =IF('Brouillard ventes'!$F$9="","",Paramètres!$B$11) | L11: =IF('Brouillard ventes'!$F$9="","",'Brouillard ventes'!$I$9) | M11: 0
A12: 1 | B12: =IF('Brouillard ventes'!$F$9="","","VD"&TEXT(ROW('Brouillard ventes'!$F$9)-5,"00000")) | C12: =IF('Brouillard ventes'!$F$9="","",YEAR('Brouillard ventes'!$A$9)*10000+MONTH('Brouillard ventes'!$A$9)*100+DAY('Brouillard ventes'!$A$9)) | D12: =IF('Brouillard ventes'!$F$9="","",'Brouillard ventes'!$B$9) | E12: =IF('Brouillard ventes'!$F$9="","",LEFT('Brouillard ventes'!$D$9,30)) | F12: 15001 | G12: =IF('Brouillard ventes'!$F$9="","",IF('Brouillard ventes'!$E$9="Réparation",Paramètres!$B$9,Paramètres!$B$8)) | K12: =IF('Brouillard ventes'!$F$9="","",Paramètres!$B$11) | L12: 0 | M12: =IF('Brouillard ventes'!$F$9="","",'Brouillard ventes'!$F$9)
A13: 1 | B13: =IF('Brouillard ventes'!$F$9="","","VD"&TEXT(ROW('Brouillard ventes'!$F$9)-5,"00000")) | C13: =IF('Brouillard ventes'!$F$9="","",YEAR('Brouillard ventes'!$A$9)*10000+MONTH('Brouillard ventes'!$A$9)*100+DAY('Brouillard ventes'!$A$9)) | D13: =IF('Brouillard ventes'!$F$9="","",'Brouillard ventes'!$B$9) | E13: =IF('Brouillard ventes'!$F$9="","",LEFT('Brouillard ventes'!$D$9,30)) | F13: 15001 | G13: =IF('Brouillard ventes'!$F$9="","",Paramètres!$B$10) | K13: =IF('Brouillard ventes'!$F$9="","",Paramètres!$B$11) | L13: 0 | M13: =IF('Brouillard ventes'!$F$9="","",'Brouillard ventes'!$H$9)
A14: 1 | B14: =IF('Brouillard ventes'!$F$10="","","VD"&TEXT(ROW('Brouillard ventes'!$F$10)-5,"00000")) | C14: =IF('Brouillard ventes'!$F$10="","",YEAR('Brouillard ventes'!$A$10)*10000+MONTH('Brouillard ventes'!$A$10)*100+DAY('Brouillard ventes'!$A$10)) | D14: =IF('Brouillard ventes'!$F$10="","",'Brouillard ventes'!$B$10) | E14: =IF('Brouillard ventes'!$F$10="","",LEFT('Brouillard ventes'!$D$10,30)) | F14: 15001 | G14: =IF('Brouillard ventes'!$F$10="","",Paramètres!$B$7) | H14: =IF('Brouillard ventes'!$F$10="","",IF('Brouillard ventes'!$C$10="","CD001",'Brouillard ventes'!$C$10)) | K14: =IF('Brouillard ventes'!$F$10="","",Paramètres!$B$11) | L14: =IF('Brouillard ventes'!$F$10="","",'Brouillard ventes'!$I$10) | M14: 0
A15: 1 | B15: =IF('Brouillard ventes'!$F$10="","","VD"&TEXT(ROW('Brouillard ventes'!$F$10)-5,"00000")) | C15: =IF('Brouillard ventes'!$F$10="","",YEAR('Brouillard ventes'!$A$10)*10000+MONTH('Brouillard ventes'!$A$10)*100+DAY('Brouillard ventes'!$A$10)) | D15: =IF('Brouillard ventes'!$F$10="","",'Brouillard ventes'!$B$10) | E15: =IF('Brouillard ventes'!$F$10="","",LEFT('Brouillard ventes'!$D$10,30)) | F15: 15001 | G15: =IF('Brouillard ventes'!$F$10="","",IF('Brouillard ventes'!$E$10="Réparation",Paramètres!$B$9,Paramètres!$B$8)) | K15: =IF('Brouillard ventes'!$F$10="","",Paramètres!$B$11) | L15: 0 | M15: =IF('Brouillard ventes'!$F$10="","",'Brouillard ventes'!$F$10)
A16: 1 | B16: =IF('Brouillard ventes'!$F$10="","","VD"&TEXT(ROW('Brouillard ventes'!$F$10)-5,"00000")) | C16: =IF('Brouillard ventes'!$F$10="","",YEAR('Brouillard ventes'!$A$10)*10000+MONTH('Brouillard ventes'!$A$10)*100+DAY('Brouillard ventes'!$A$10)) | D16: =IF('Brouillard ventes'!$F$10="","",'Brouillard ventes'!$B$10) | E16: =IF('Brouillard ventes'!$F$10="","",LEFT('Brouillard ventes'!$D$10,30)) | F16: 15001 | G16: =IF('Brouillard ventes'!$F$10="","",Paramètres!$B$10) | K16: =IF('Brouillard ventes'!$F$10="","",Paramètres!$B$11) | L16: 0 | M16: =IF('Brouillard ventes'!$F$10="","",'Brouillard ventes'!$H$10)
A17: 1 | B17: =IF('Brouillard ventes'!$F$11="","","VD"&TEXT(ROW('Brouillard ventes'!$F$11)-5,"00000")) | C17: =IF('Brouillard ventes'!$F$11="","",YEAR('Brouillard ventes'!$A$11)*10000+MONTH('Brouillard ventes'!$A$11)*100+DAY('Brouillard ventes'!$A$11)) | D17: =IF('Brouillard ventes'!$F$11="","",'Brouillard ventes'!$B$11) | E17: =IF('Brouillard ventes'!$F$11="","",LEFT('Brouillard ventes'!$D$11,30)) | F17: 15001 | G17: =IF('Brouillard ventes'!$F$11="","",Paramètres!$B$7) | H17: =IF('Brouillard ventes'!$F$11="","",IF('Brouillard ventes'!$C$11="","CD001",'Brouillard ventes'!$C$11)) | K17: =IF('Brouillard ventes'!$F$11="","",Paramètres!$B$11) | L17: =IF('Brouillard ventes'!$F$11="","",'Brouillard ventes'!$I$11) | M17: 0
A18: 1 | B18: =IF('Brouillard ventes'!$F$11="","","VD"&TEXT(ROW('Brouillard ventes'!$F$11)-5,"00000")) | C18: =IF('Brouillard ventes'!$F$11="","",YEAR('Brouillard ventes'!$A$11)*10000+MONTH('Brouillard ventes'!$A$11)*100+DAY('Brouillard ventes'!$A$11)) | D18: =IF('Brouillard ventes'!$F$11="","",'Brouillard ventes'!$B$11) | E18: =IF('Brouillard ventes'!$F$11="","",LEFT('Brouillard ventes'!$D$11,30)) | F18: 15001 | G18: =IF('Brouillard ventes'!$F$11="","",IF('Brouillard ventes'!$E$11="Réparation",Paramètres!$B$9,Paramètres!$B$8)) | K18: =IF('Brouillard ventes'!$F$11="","",Paramètres!$B$11) | L18: 0 | M18: =IF('Brouillard ventes'!$F$11="","",'Brouillard ventes'!$F$11)
A19: 1 | B19: =IF('Brouillard ventes'!$F$11="","","VD"&TEXT(ROW('Brouillard ventes'!$F$11)-5,"00000")) | C19: =IF('Brouillard ventes'!$F$11="","",YEAR('Brouillard ventes'!$A$11)*10000+MONTH('Brouillard ventes'!$A$11)*100+DAY('Brouillard ventes'!$A$11)) | D19: =IF('Brouillard ventes'!$F$11="","",'Brouillard ventes'!$B$11) | E19: =IF('Brouillard ventes'!$F$11="","",LEFT('Brouillard ventes'!$D$11,30)) | F19: 15001 | G19: =IF('Brouillard ventes'!$F$11="","",Paramètres!$B$10) | K19: =IF('Brouillard ventes'!$F$11="","",Paramètres!$B$11) | L19: 0 | M19: =IF('Brouillard ventes'!$F$11="","",'Brouillard ventes'!$H$11)
A20: 1 | B20: =IF('Brouillard ventes'!$F$12="","","VD"&TEXT(ROW('Brouillard ventes'!$F$12)-5,"00000")) | C20: =IF('Brouillard ventes'!$F$12="","",YEAR('Brouillard ventes'!$A$12)*10000+MONTH('Brouillard ventes'!$A$12)*100+DAY('Brouillard ventes'!$A$12)) | D20: =IF('Brouillard ventes'!$F$12="","",'Brouillard ventes'!$B$12) | E20: =IF('Brouillard ventes'!$F$12="","",LEFT('Brouillard ventes'!$D$12,30)) | F20: 15001 | G20: =IF('Brouillard ventes'!$F$12="","",Paramètres!$B$7) | H20: =IF('Brouillard ventes'!$F$12="","",IF('Brouillard ventes'!$C$12="","CD001",'Brouillard ventes'!$C$12)) | K20: =IF('Brouillard ventes'!$F$12="","",Paramètres!$B$11) | L20: =IF('Brouillard ventes'!$F$12="","",'Brouillard ventes'!$I$12) | M20: 0
A21: 1 | B21: =IF('Brouillard ventes'!$F$12="","","VD"&TEXT(ROW('Brouillard ventes'!$F$12)-5,"00000")) | C21: =IF('Brouillard ventes'!$F$12="","",YEAR('Brouillard ventes'!$A$12)*10000+MONTH('Brouillard ventes'!$A$12)*100+DAY('Brouillard ventes'!$A$12)) | D21: =IF('Brouillard ventes'!$F$12="","",'Brouillard ventes'!$B$12) | E21: =IF('Brouillard ventes'!$F$12="","",LEFT('Brouillard ventes'!$D$12,30)) | F21: 15001 | G21: =IF('Brouillard ventes'!$F$12="","",IF('Brouillard ventes'!$E$12="Réparation",Paramètres!$B$9,Paramètres!$B$8)) | K21: =IF('Brouillard ventes'!$F$12="","",Paramètres!$B$11) | L21: 0 | M21: =IF('Brouillard ventes'!$F$12="","",'Brouillard ventes'!$F$12)
A22: 1 | B22: =IF('Brouillard ventes'!$F$12="","","VD"&TEXT(ROW('Brouillard ventes'!$F$12)-5,"00000")) | C22: =IF('Brouillard ventes'!$F$12="","",YEAR('Brouillard ventes'!$A$12)*10000+MONTH('Brouillard ventes'!$A$12)*100+DAY('Brouillard ventes'!$A$12)) | D22: =IF('Brouillard ventes'!$F$12="","",'Brouillard ventes'!$B$12) | E22: =IF('Brouillard ventes'!$F$12="","",LEFT('Brouillard ventes'!$D$12,30)) | F22: 15001 | G22: =IF('Brouillard ventes'!$F$12="","",Paramètres!$B$10) | K22: =IF('Brouillard ventes'!$F$12="","",Paramètres!$B$11) | L22: 0 | M22: =IF('Brouillard ventes'!$F$12="","",'Brouillard ventes'!$H$12)
A23: 1 | B23: =IF('Brouillard ventes'!$F$13="","","VD"&TEXT(ROW('Brouillard ventes'!$F$13)-5,"00000")) | C23: =IF('Brouillard ventes'!$F$13="","",YEAR('Brouillard ventes'!$A$13)*10000+MONTH('Brouillard ventes'!$A$13)*100+DAY('Brouillard ventes'!$A$13)) | D23: =IF('Brouillard ventes'!$F$13="","",'Brouillard ventes'!$B$13) | E23: =IF('Brouillard ventes'!$F$13="","",LEFT('Brouillard ventes'!$D$13,30)) | F23: 15001 | G23: =IF('Brouillard ventes'!$F$13="","",Paramètres!$B$7) | H23: =IF('Brouillard ventes'!$F$13="","",IF('Brouillard ventes'!$C$13="","CD001",'Brouillard ventes'!$C$13)) | K23: =IF('Brouillard ventes'!$F$13="","",Paramètres!$B$11) | L23: =IF('Brouillard ventes'!$F$13="","",'Brouillard ventes'!$I$13) | M23: 0
A24: 1 | B24: =IF('Brouillard ventes'!$F$13="","","VD"&TEXT(ROW('Brouillard ventes'!$F$13)-5,"00000")) | C24: =IF('Brouillard ventes'!$F$13="","",YEAR('Brouillard ventes'!$A$13)*10000+MONTH('Brouillard ventes'!$A$13)*100+DAY('Brouillard ventes'!$A$13)) | D24: =IF('Brouillard ventes'!$F$13="","",'Brouillard ventes'!$B$13) | E24: =IF('Brouillard ventes'!$F$13="","",LEFT('Brouillard ventes'!$D$13,30)) | F24: 15001 | G24: =IF('Brouillard ventes'!$F$13="","",IF('Brouillard ventes'!$E$13="Réparation",Paramètres!$B$9,Paramètres!$B$8)) | K24: =IF('Brouillard ventes'!$F$13="","",Paramètres!$B$11) | L24: 0 | M24: =IF('Brouillard ventes'!$F$13="","",'Brouillard ventes'!$F$13)
A25: 1 | B25: =IF('Brouillard ventes'!$F$13="","","VD"&TEXT(ROW('Brouillard ventes'!$F$13)-5,"00000")) | C25: =IF('Brouillard ventes'!$F$13="","",YEAR('Brouillard ventes'!$A$13)*10000+MONTH('Brouillard ventes'!$A$13)*100+DAY('Brouillard ventes'!$A$13)) | D25: =IF('Brouillard ventes'!$F$13="","",'Brouillard ventes'!$B$13) | E25: =IF('Brouillard ventes'!$F$13="","",LEFT('Brouillard ventes'!$D$13,30)) | F25: 15001 | G25: =IF('Brouillard ventes'!$F$13="","",Paramètres!$B$10) | K25: =IF('Brouillard ventes'!$F$13="","",Paramètres!$B$11) | L25: 0 | M25: =IF('Brouillard ventes'!$F$13="","",'Brouillard ventes'!$H$13)
A26: 1 | B26: =IF('Brouillard ventes'!$F$14="","","VD"&TEXT(ROW('Brouillard ventes'!$F$14)-5,"00000")) | C26: =IF('Brouillard ventes'!$F$14="","",YEAR('Brouillard ventes'!$A$14)*10000+MONTH('Brouillard ventes'!$A$14)*100+DAY('Brouillard ventes'!$A$14)) | D26: =IF('Brouillard ventes'!$F$14="","",'Brouillard ventes'!$B$14) | E26: =IF('Brouillard ventes'!$F$14="","",LEFT('Brouillard ventes'!$D$14,30)) | F26: 15001 | G26: =IF('Brouillard ventes'!$F$14="","",Paramètres!$B$7) | H26: =IF('Brouillard ventes'!$F$14="","",IF('Brouillard ventes'!$C$14="","CD001",'Brouillard ventes'!$C$14)) | K26: =IF('Brouillard ventes'!$F$14="","",Paramètres!$B$11) | L26: =IF('Brouillard ventes'!$F$14="","",'Brouillard ventes'!$I$14) | M26: 0
A27: 1 | B27: =IF('Brouillard ventes'!$F$14="","","VD"&TEXT(ROW('Brouillard ventes'!$F$14)-5,"00000")) | C27: =IF('Brouillard ventes'!$F$14="","",YEAR('Brouillard ventes'!$A$14)*10000+MONTH('Brouillard ventes'!$A$14)*100+DAY('Brouillard ventes'!$A$14)) | D27: =IF('Brouillard ventes'!$F$14="","",'Brouillard ventes'!$B$14) | E27: =IF('Brouillard ventes'!$F$14="","",LEFT('Brouillard ventes'!$D$14,30)) | F27: 15001 | G27: =IF('Brouillard ventes'!$F$14="","",IF('Brouillard ventes'!$E$14="Réparation",Paramètres!$B$9,Paramètres!$B$8)) | K27: =IF('Brouillard ventes'!$F$14="","",Paramètres!$B$11) | L27: 0 | M27: =IF('Brouillard ventes'!$F$14="","",'Brouillard ventes'!$F$14)
A28: 1 | B28: =IF('Brouillard ventes'!$F$14="","","VD"&TEXT(ROW('Brouillard ventes'!$F$14)-5,"00000")) | C28: =IF('Brouillard ventes'!$F$14="","",YEAR('Brouillard ventes'!$A$14)*10000+MONTH('Brouillard ventes'!$A$14)*100+DAY('Brouillard ventes'!$A$14)) | D28: =IF('Brouillard ventes'!$F$14="","",'Brouillard ventes'!$B$14) | E28: =IF('Brouillard ventes'!$F$14="","",LEFT('Brouillard ventes'!$D$14,30)) | F28: 15001 | G28: =IF('Brouillard ventes'!$F$14="","",Paramètres!$B$10) | K28: =IF('Brouillard ventes'!$F$14="","",Paramètres!$B$11) | L28: 0 | M28: =IF('Brouillard ventes'!$F$14="","",'Brouillard ventes'!$H$14)
A29: 1 | B29: =IF('Brouillard ventes'!$F$15="","","VD"&TEXT(ROW('Brouillard ventes'!$F$15)-5,"00000")) | C29: =IF('Brouillard ventes'!$F$15="","",YEAR('Brouillard ventes'!$A$15)*10000+MONTH('Brouillard ventes'!$A$15)*100+DAY('Brouillard ventes'!$A$15)) | D29: =IF('Brouillard ventes'!$F$15="","",'Brouillard ventes'!$B$15) | E29: =IF('Brouillard ventes'!$F$15="","",LEFT('Brouillard ventes'!$D$15,30)) | F29: 15001 | G29: =IF('Brouillard ventes'!$F$15="","",Paramètres!$B$7) | H29: =IF('Brouillard ventes'!$F$15="","",IF('Brouillard ventes'!$C$15="","CD001",'Brouillard ventes'!$C$15)) | K29: =IF('Brouillard ventes'!$F$15="","",Paramètres!$B$11) | L29: =IF('Brouillard ventes'!$F$15="","",'Brouillard ventes'!$I$15) | M29: 0
A30: 1 | B30: =IF('Brouillard ventes'!$F$15="","","VD"&TEXT(ROW('Brouillard ventes'!$F$15)-5,"00000")) | C30: =IF('Brouillard ventes'!$F$15="","",YEAR('Brouillard ventes'!$A$15)*10000+MONTH('Brouillard ventes'!$A$15)*100+DAY('Brouillard ventes'!$A$15)) | D30: =IF('Brouillard ventes'!$F$15="","",'Brouillard ventes'!$B$15) | E30: =IF('Brouillard ventes'!$F$15="","",LEFT('Brouillard ventes'!$D$15,30)) | F30: 15001 | G30: =IF('Brouillard ventes'!$F$15="","",IF('Brouillard ventes'!$E$15="Réparation",Paramètres!$B$9,Paramètres!$B$8)) | K30: =IF('Brouillard ventes'!$F$15="","",Paramètres!$B$11) | L30: 0 | M30: =IF('Brouillard ventes'!$F$15="","",'Brouillard ventes'!$F$15)
A31: 1 | B31: =IF('Brouillard ventes'!$F$15="","","VD"&TEXT(ROW('Brouillard ventes'!$F$15)-5,"00000")) | C31: =IF('Brouillard ventes'!$F$15="","",YEAR('Brouillard ventes'!$A$15)*10000+MONTH('Brouillard ventes'!$A$15)*100+DAY('Brouillard ventes'!$A$15)) | D31: =IF('Brouillard ventes'!$F$15="","",'Brouillard ventes'!$B$15) | E31: =IF('Brouillard ventes'!$F$15="","",LEFT('Brouillard ventes'!$D$15,30)) | F31: 15001 | G31: =IF('Brouillard ventes'!$F$15="","",Paramètres!$B$10) | K31: =IF('Brouillard ventes'!$F$15="","",Paramètres!$B$11) | L31: 0 | M31: =IF('Brouillard ventes'!$F$15="","",'Brouillard ventes'!$H$15)
A32: 1 | B32: =IF('Brouillard ventes'!$F$16="","","VD"&TEXT(ROW('Brouillard ventes'!$F$16)-5,"00000")) | C32: =IF('Brouillard ventes'!$F$16="","",YEAR('Brouillard ventes'!$A$16)*10000+MONTH('Brouillard ventes'!$A$16)*100+DAY('Brouillard ventes'!$A$16)) | D32: =IF('Brouillard ventes'!$F$16="","",'Brouillard ventes'!$B$16) | E32: =IF('Brouillard ventes'!$F$16="","",LEFT('Brouillard ventes'!$D$16,30)) | F32: 15001 | G32: =IF('Brouillard ventes'!$F$16="","",Paramètres!$B$7) | H32: =IF('Brouillard ventes'!$F$16="","",IF('Brouillard ventes'!$C$16="","CD001",'Brouillard ventes'!$C$16)) | K32: =IF('Brouillard ventes'!$F$16="","",Paramètres!$B$11) | L32: =IF('Brouillard ventes'!$F$16="","",'Brouillard ventes'!$I$16) | M32: 0
A33: 1 | B33: =IF('Brouillard ventes'!$F$16="","","VD"&TEXT(ROW('Brouillard ventes'!$F$16)-5,"00000")) | C33: =IF('Brouillard ventes'!$F$16="","",YEAR('Brouillard ventes'!$A$16)*10000+MONTH('Brouillard ventes'!$A$16)*100+DAY('Brouillard ventes'!$A$16)) | D33: =IF('Brouillard ventes'!$F$16="","",'Brouillard ventes'!$B$16) | E33: =IF('Brouillard ventes'!$F$16="","",LEFT('Brouillard ventes'!$D$16,30)) | F33: 15001 | G33: =IF('Brouillard ventes'!$F$16="","",IF('Brouillard ventes'!$E$16="Réparation",Paramètres!$B$9,Paramètres!$B$8)) | K33: =IF('Brouillard ventes'!$F$16="","",Paramètres!$B$11) | L33: 0 | M33: =IF('Brouillard ventes'!$F$16="","",'Brouillard ventes'!$F$16)
A34: 1 | B34: =IF('Brouillard ventes'!$F$16="","","VD"&TEXT(ROW('Brouillard ventes'!$F$16)-5,"00000")) | C34: =IF('Brouillard ventes'!$F$16="","",YEAR('Brouillard ventes'!$A$16)*10000+MONTH('Brouillard ventes'!$A$16)*100+DAY('Brouillard ventes'!$A$16)) | D34: =IF('Brouillard ventes'!$F$16="","",'Brouillard ventes'!$B$16) | E34: =IF('Brouillard ventes'!$F$16="","",LEFT('Brouillard ventes'!$D$16,30)) | F34: 15001 | G34: =IF('Brouillard ventes'!$F$16="","",Paramètres!$B$10) | K34: =IF('Brouillard ventes'!$F$16="","",Paramètres!$B$11) | L34: 0 | M34: =IF('Brouillard ventes'!$F$16="","",'Brouillard ventes'!$H$16)
A35: 1 | B35: =IF('Brouillard ventes'!$F$17="","","VD"&TEXT(ROW('Brouillard ventes'!$F$17)-5,"00000")) | C35: =IF('Brouillard ventes'!$F$17="","",YEAR('Brouillard ventes'!$A$17)*10000+MONTH('Brouillard ventes'!$A$17)*100+DAY('Brouillard ventes'!$A$17)) | D35: =IF('Brouillard ventes'!$F$17="","",'Brouillard ventes'!$B$17) | E35: =IF('Brouillard ventes'!$F$17="","",LEFT('Brouillard ventes'!$D$17,30)) | F35: 15001 | G35: =IF('Brouillard ventes'!$F$17="","",Paramètres!$B$7) | H35: =IF('Brouillard ventes'!$F$17="","",IF('Brouillard ventes'!$C$17="","CD001",'Brouillard ventes'!$C$17)) | K35: =IF('Brouillard ventes'!$F$17="","",Paramètres!$B$11) | L35: =IF('Brouillard ventes'!$F$17="","",'Brouillard ventes'!$I$17) | M35: 0
A36: 1 | B36: =IF('Brouillard ventes'!$F$17="","","VD"&TEXT(ROW('Brouillard ventes'!$F$17)-5,"00000")) | C36: =IF('Brouillard ventes'!$F$17="","",YEAR('Brouillard ventes'!$A$17)*10000+MONTH('Brouillard ventes'!$A$17)*100+DAY('Brouillard ventes'!$A$17)) | D36: =IF('Brouillard ventes'!$F$17="","",'Brouillard ventes'!$B$17) | E36: =IF('Brouillard ventes'!$F$17="","",LEFT('Brouillard ventes'!$D$17,30)) | F36: 15001 | G36: =IF('Brouillard ventes'!$F$17="","",IF('Brouillard ventes'!$E$17="Réparation",Paramètres!$B$9,Paramètres!$B$8)) | K36: =IF('Brouillard ventes'!$F$17="","",Paramètres!$B$11) | L36: 0 | M36: =IF('Brouillard ventes'!$F$17="","",'Brouillard ventes'!$F$17)
A37: 1 | B37: =IF('Brouillard ventes'!$F$17="","","VD"&TEXT(ROW('Brouillard ventes'!$F$17)-5,"00000")) | C37: =IF('Brouillard ventes'!$F$17="","",YEAR('Brouillard ventes'!$A$17)*10000+MONTH('Brouillard ventes'!$A$17)*100+DAY('Brouillard ventes'!$A$17)) | D37: =IF('Brouillard ventes'!$F$17="","",'Brouillard ventes'!$B$17) | E37: =IF('Brouillard ventes'!$F$17="","",LEFT('Brouillard ventes'!$D$17,30)) | F37: 15001 | G37: =IF('Brouillard ventes'!$F$17="","",Paramètres!$B$10) | K37: =IF('Brouillard ventes'!$F$17="","",Paramètres!$B$11) | L37: 0 | M37: =IF('Brouillard ventes'!$F$17="","",'Brouillard ventes'!$H$17)
A38: 1 | B38: =IF('Brouillard ventes'!$F$18="","","VD"&TEXT(ROW('Brouillard ventes'!$F$18)-5,"00000")) | C38: =IF('Brouillard ventes'!$F$18="","",YEAR('Brouillard ventes'!$A$18)*10000+MONTH('Brouillard ventes'!$A$18)*100+DAY('Brouillard ventes'!$A$18)) | D38: =IF('Brouillard ventes'!$F$18="","",'Brouillard ventes'!$B$18) | E38: =IF('Brouillard ventes'!$F$18="","",LEFT('Brouillard ventes'!$D$18,30)) | F38: 15001 | G38: =IF('Brouillard ventes'!$F$18="","",Paramètres!$B$7) | H38: =IF('Brouillard ventes'!$F$18="","",IF('Brouillard ventes'!$C$18="","CD001",'Brouillard ventes'!$C$18)) | K38: =IF('Brouillard ventes'!$F$18="","",Paramètres!$B$11) | L38: =IF('Brouillard ventes'!$F$18="","",'Brouillard ventes'!$I$18) | M38: 0
A39: 1 | B39: =IF('Brouillard ventes'!$F$18="","","VD"&TEXT(ROW('Brouillard ventes'!$F$18)-5,"00000")) | C39: =IF('Brouillard ventes'!$F$18="","",YEAR('Brouillard ventes'!$A$18)*10000+MONTH('Brouillard ventes'!$A$18)*100+DAY('Brouillard ventes'!$A$18)) | D39: =IF('Brouillard ventes'!$F$18="","",'Brouillard ventes'!$B$18) | E39: =IF('Brouillard ventes'!$F$18="","",LEFT('Brouillard ventes'!$D$18,30)) | F39: 15001 | G39: =IF('Brouillard ventes'!$F$18="","",IF('Brouillard ventes'!$E$18="Réparation",Paramètres!$B$9,Paramètres!$B$8)) | K39: =IF('Brouillard ventes'!$F$18="","",Paramètres!$B$11) | L39: 0 | M39: =IF('Brouillard ventes'!$F$18="","",'Brouillard ventes'!$F$18)
A40: 1 | B40: =IF('Brouillard ventes'!$F$18="","","VD"&TEXT(ROW('Brouillard ventes'!$F$18)-5,"00000")) | C40: =IF('Brouillard ventes'!$F$18="","",YEAR('Brouillard ventes'!$A$18)*10000+MONTH('Brouillard ventes'!$A$18)*100+DAY('Brouillard ventes'!$A$18)) | D40: =IF('Brouillard ventes'!$F$18="","",'Brouillard ventes'!$B$18) | E40: =IF('Brouillard ventes'!$F$18="","",LEFT('Brouillard ventes'!$D$18,30)) | F40: 15001 | G40: =IF('Brouillard ventes'!$F$18="","",Paramètres!$B$10) | K40: =IF('Brouillard ventes'!$F$18="","",Paramètres!$B$11) | L40: 0 | M40: =IF('Brouillard ventes'!$F$18="","",'Brouillard ventes'!$H$18)
...

Sheet Encaissements comptant
A1: FOLIO | B1: PIECE | C1: DATE | D1: REFERENCE | E1: LIBELLE | F1: CODE_JRN | G1: CODE_COM | H1: CODE_AUX | I1: CODE_BDG | J1: CODE_NAT | K1: CODE_UNT | L1: DEBIT | M1: CREDIT | N1: LETTRAGE | O1: LIBELLEA | P1: CTP_COM | Q1: CTP_AUX | R1: ECHEANCE
A2: 1 | B2: =IF(OR('Brouillard ventes'!$F$6="",'Brouillard ventes'!$J$6="À crédit",'Brouillard ventes'!$J$6=""),"","EC"&TEXT(ROW('Brouillard ventes'!$F$6)-5,"00000")) | C2: =IF(OR('Brouillard ventes'!$F$6="",'Brouillard ventes'!$J$6="À crédit",'Brouillard ventes'!$J$6=""),"",YEAR('Brouillard ventes'!$A$6)*10000+MONTH('Brouillard ventes'!$A$6)*100+DAY('Brouillard ventes'!$A$6)) | D2: =IF(OR('Brouillard ventes'!$F$6="",'Brouillard ventes'!$J$6="À crédit",'Brouillard ventes'!$J$6=""),"",'Brouillard ventes'!$B$6) | E2: =IF(OR('Brouillard ventes'!$F$6="",'Brouillard ventes'!$J$6="À crédit",'Brouillard ventes'!$J$6=""),"","REGL "&LEFT('Brouillard ventes'!$D$6,25)) | F2: =IF(OR('Brouillard ventes'!$F$6="",'Brouillard ventes'!$J$6="À crédit",'Brouillard ventes'!$J$6=""),"",IF('Brouillard ventes'!$J$6="Espèces","04001","02001")) | G2: =IF(OR('Brouillard ventes'!$F$6="",'Brouillard ventes'!$J$6="À crédit",'Brouillard ventes'!$J$6=""),"",IF('Brouillard ventes'!$J$6="Espèces","53000","51220")) | K2: =IF(OR('Brouillard ventes'!$F$6="",'Brouillard ventes'!$J$6="À crédit",'Brouillard ventes'!$J$6=""),"",Paramètres!$B$11) | L2: =IF(OR('Brouillard ventes'!$F$6="",'Brouillard ventes'!$J$6="À crédit",'Brouillard ventes'!$J$6=""),0,'Brouillard ventes'!$I$6) | M2: 0
A3: 1 | B3: =IF(OR('Brouillard ventes'!$F$6="",'Brouillard ventes'!$J$6="À crédit",'Brouillard ventes'!$J$6=""),"","EC"&TEXT(ROW('Brouillard ventes'!$F$6)-5,"00000")) | C3: =IF(OR('Brouillard ventes'!$F$6="",'Brouillard ventes'!$J$6="À crédit",'Brouillard ventes'!$J$6=""),"",YEAR('Brouillard ventes'!$A$6)*10000+MONTH('Brouillard ventes'!$A$6)*100+DAY('Brouillard ventes'!$A$6)) | D3: =IF(OR('Brouillard ventes'!$F$6="",'Brouillard ventes'!$J$6="À crédit",'Brouillard ventes'!$J$6=""),"",'Brouillard ventes'!$B$6) | E3: =IF(OR('Brouillard ventes'!$F$6="",'Brouillard ventes'!$J$6="À crédit",'Brouillard ventes'!$J$6=""),"","REGL "&LEFT('Brouillard ventes'!$D$6,25)) | F3: =IF(OR('Brouillard ventes'!$F$6="",'Brouillard ventes'!$J$6="À crédit",'Brouillard ventes'!$J$6=""),"",IF('Brouillard ventes'!$J$6="Espèces","04001","02001")) | G3: =IF(OR('Brouillard ventes'!$F$6="",'Brouillard ventes'!$J$6="À crédit",'Brouillard ventes'!$J$6=""),"",Paramètres!$B$7) | H3: =IF(OR('Brouillard ventes'!$F$6="",'Brouillard ventes'!$J$6="À crédit",'Brouillard ventes'!$J$6=""),"",IF('Brouillard ventes'!$C$6="","CD001",'Brouillard ventes'!$C$6)) | K3: =IF(OR('Brouillard ventes'!$F$6="",'Brouillard ventes'!$J$6="À crédit",'Brouillard ventes'!$J$6=""),"",Paramètres!$B$11) | L3: 0 | M3: =IF(OR('Brouillard ventes'!$F$6="",'Brouillard ventes'!$J$6="À crédit",'Brouillard ventes'!$J$6=""),0,'Brouillard ventes'!$I$6)
A4: 1 | B4: =IF(OR('Brouillard ventes'!$F$7="",'Brouillard ventes'!$J$7="À crédit",'Brouillard ventes'!$J$7=""),"","EC"&TEXT(ROW('Brouillard ventes'!$F$7)-5,"00000")) | C4: =IF(OR('Brouillard ventes'!$F$7="",'Brouillard ventes'!$J$7="À crédit",'Brouillard ventes'!$J$7=""),"",YEAR('Brouillard ventes'!$A$7)*10000+MONTH('Brouillard ventes'!$A$7)*100+DAY('Brouillard ventes'!$A$7)) | D4: =IF(OR('Brouillard ventes'!$F$7="",'Brouillard ventes'!$J$7="À crédit",'Brouillard ventes'!$J$7=""),"",'Brouillard ventes'!$B$7) | E4: =IF(OR('Brouillard ventes'!$F$7="",'Brouillard ventes'!$J$7="À crédit",'Brouillard ventes'!$J$7=""),"","REGL "&LEFT('Brouillard ventes'!$D$7,25)) | F4: =IF(OR('Brouillard ventes'!$F$7="",'Brouillard ventes'!$J$7="À crédit",'Brouillard ventes'!$J$7=""),"",IF('Brouillard ventes'!$J$7="Espèces","04001","02001")) | G4: =IF(OR('Brouillard ventes'!$F$7="",'Brouillard ventes'!$J$7="À crédit",'Brouillard ventes'!$J$7=""),"",IF('Brouillard ventes'!$J$7="Espèces","53000","51220")) | K4: =IF(OR('Brouillard ventes'!$F$7="",'Brouillard ventes'!$J$7="À crédit",'Brouillard ventes'!$J$7=""),"",Paramètres!$B$11) | L4: =IF(OR('Brouillard ventes'!$F$7="",'Brouillard ventes'!$J$7="À crédit",'Brouillard ventes'!$J$7=""),0,'Brouillard ventes'!$I$7) | M4: 0
A5: 1 | B5: =IF(OR('Brouillard ventes'!$F$7="",'Brouillard ventes'!$J$7="À crédit",'Brouillard ventes'!$J$7=""),"","EC"&TEXT(ROW('Brouillard ventes'!$F$7)-5,"00000")) | C5: =IF(OR('Brouillard ventes'!$F$7="",'Brouillard ventes'!$J$7="À crédit",'Brouillard ventes'!$J$7=""),"",YEAR('Brouillard ventes'!$A$7)*10000+MONTH('Brouillard ventes'!$A$7)*100+DAY('Brouillard ventes'!$A$7)) | D5: =IF(OR('Brouillard ventes'!$F$7="",'Brouillard ventes'!$J$7="À crédit",'Brouillard ventes'!$J$7=""),"",'Brouillard ventes'!$B$7) | E5: =IF(OR('Brouillard ventes'!$F$7="",'Brouillard ventes'!$J$7="À crédit",'Brouillard ventes'!$J$7=""),"","REGL "&LEFT('Brouillard ventes'!$D$7,25)) | F5: =IF(OR('Brouillard ventes'!$F$7="",'Brouillard ventes'!$J$7="À crédit",'Brouillard ventes'!$J$7=""),"",IF('Brouillard ventes'!$J$7="Espèces","04001","02001")) | G5: =IF(OR('Brouillard ventes'!$F$7="",'Brouillard ventes'!$J$7="À crédit",'Brouillard ventes'!$J$7=""),"",Paramètres!$B$7) | H5: =IF(OR('Brouillard ventes'!$F$7="",'Brouillard ventes'!$J$7="À crédit",'Brouillard ventes'!$J$7=""),"",IF('Brouillard ventes'!$C$7="","CD001",'Brouillard ventes'!$C$7)) | K5: =IF(OR('Brouillard ventes'!$F$7="",'Brouillard ventes'!$J$7="À crédit",'Brouillard ventes'!$J$7=""),"",Paramètres!$B$11) | L5: 0 | M5: =IF(OR('Brouillard ventes'!$F$7="",'Brouillard ventes'!$J$7="À crédit",'Brouillard ventes'!$J$7=""),0,'Brouillard ventes'!$I$7)
A6: 1 | B6: =IF(OR('Brouillard ventes'!$F$8="",'Brouillard ventes'!$J$8="À crédit",'Brouillard ventes'!$J$8=""),"","EC"&TEXT(ROW('Brouillard ventes'!$F$8)-5,"00000")) | C6: =IF(OR('Brouillard ventes'!$F$8="",'Brouillard ventes'!$J$8="À crédit",'Brouillard ventes'!$J$8=""),"",YEAR('Brouillard ventes'!$A$8)*10000+MONTH('Brouillard ventes'!$A$8)*100+DAY('Brouillard ventes'!$A$8)) | D6: =IF(OR('Brouillard ventes'!$F$8="",'Brouillard ventes'!$J$8="À crédit",'Brouillard ventes'!$J$8=""),"",'Brouillard ventes'!$B$8) | E6: =IF(OR('Brouillard ventes'!$F$8="",'Brouillard ventes'!$J$8="À crédit",'Brouillard ventes'!$J$8=""),"","REGL "&LEFT('Brouillard ventes'!$D$8,25)) | F6: =IF(OR('Brouillard ventes'!$F$8="",'Brouillard ventes'!$J$8="À crédit",'Brouillard ventes'!$J$8=""),"",IF('Brouillard ventes'!$J$8="Espèces","04001","02001")) | G6: =IF(OR('Brouillard ventes'!$F$8="",'Brouillard ventes'!$J$8="À crédit",'Brouillard ventes'!$J$8=""),"",IF('Brouillard ventes'!$J$8="Espèces","53000","51220")) | K6: =IF(OR('Brouillard ventes'!$F$8="",'Brouillard ventes'!$J$8="À crédit",'Brouillard ventes'!$J$8=""),"",Paramètres!$B$11) | L6: =IF(OR('Brouillard ventes'!$F$8="",'Brouillard ventes'!$J$8="À crédit",'Brouillard ventes'!$J$8=""),0,'Brouillard ventes'!$I$8) | M6: 0
A7: 1 | B7: =IF(OR('Brouillard ventes'!$F$8="",'Brouillard ventes'!$J$8="À crédit",'Brouillard ventes'!$J$8=""),"","EC"&TEXT(ROW('Brouillard ventes'!$F$8)-5,"00000")) | C7: =IF(OR('Brouillard ventes'!$F$8="",'Brouillard ventes'!$J$8="À crédit",'Brouillard ventes'!$J$8=""),"",YEAR('Brouillard ventes'!$A$8)*10000+MONTH('Brouillard ventes'!$A$8)*100+DAY('Brouillard ventes'!$A$8)) | D7: =IF(OR('Brouillard ventes'!$F$8="",'Brouillard ventes'!$J$8="À crédit",'Brouillard ventes'!$J$8=""),"",'Brouillard ventes'!$B$8) | E7: =IF(OR('Brouillard ventes'!$F$8="",'Brouillard ventes'!$J$8="À crédit",'Brouillard ventes'!$J$8=""),"","REGL "&LEFT('Brouillard ventes'!$D$8,25)) | F7: =IF(OR('Brouillard ventes'!$F$8="",'Brouillard ventes'!$J$8="À crédit",'Brouillard ventes'!$J$8=""),"",IF('Brouillard ventes'!$J$8="Espèces","04001","02001")) | G7: =IF(OR('Brouillard ventes'!$F$8="",'Brouillard ventes'!$J$8="À crédit",'Brouillard ventes'!$J$8=""),"",Paramètres!$B$7) | H7: =IF(OR('Brouillard ventes'!$F$8="",'Brouillard ventes'!$J$8="À crédit",'Brouillard ventes'!$J$8=""),"",IF('Brouillard ventes'!$C$8="","CD001",'Brouillard ventes'!$C$8)) | K7: =IF(OR('Brouillard ventes'!$F$8="",'Brouillard ventes'!$J$8="À crédit",'Brouillard ventes'!$J$8=""),"",Paramètres!$B$11) | L7: 0 | M7: =IF(OR('Brouillard ventes'!$F$8="",'Brouillard ventes'!$J$8="À crédit",'Brouillard ventes'!$J$8=""),0,'Brouillard ventes'!$I$8)
A8: 1 | B8: =IF(OR('Brouillard ventes'!$F$9="",'Brouillard ventes'!$J$9="À crédit",'Brouillard ventes'!$J$9=""),"","EC"&TEXT(ROW('Brouillard ventes'!$F$9)-5,"00000")) | C8: =IF(OR('Brouillard ventes'!$F$9="",'Brouillard ventes'!$J$9="À crédit",'Brouillard ventes'!$J$9=""),"",YEAR('Brouillard ventes'!$A$9)*10000+MONTH('Brouillard ventes'!$A$9)*100+DAY('Brouillard ventes'!$A$9)) | D8: =IF(OR('Brouillard ventes'!$F$9="",'Brouillard ventes'!$J$9="À crédit",'Brouillard ventes'!$J$9=""),"",'Brouillard ventes'!$B$9) | E8: =IF(OR('Brouillard ventes'!$F$9="",'Brouillard ventes'!$J$9="À crédit",'Brouillard ventes'!$J$9=""),"","REGL "&LEFT('Brouillard ventes'!$D$9,25)) | F8: =IF(OR('Brouillard ventes'!$F$9="",'Brouillard ventes'!$J$9="À crédit",'Brouillard ventes'!$J$9=""),"",IF('Brouillard ventes'!$J$9="Espèces","04001","02001")) | G8: =IF(OR('Brouillard ventes'!$F$9="",'Brouillard ventes'!$J$9="À crédit",'Brouillard ventes'!$J$9=""),"",IF('Brouillard ventes'!$J$9="Espèces","53000","51220")) | K8: =IF(OR('Brouillard ventes'!$F$9="",'Brouillard ventes'!$J$9="À crédit",'Brouillard ventes'!$J$9=""),"",Paramètres!$B$11) | L8: =IF(OR('Brouillard ventes'!$F$9="",'Brouillard ventes'!$J$9="À crédit",'Brouillard ventes'!$J$9=""),0,'Brouillard ventes'!$I$9) | M8: 0
A9: 1 | B9: =IF(OR('Brouillard ventes'!$F$9="",'Brouillard ventes'!$J$9="À crédit",'Brouillard ventes'!$J$9=""),"","EC"&TEXT(ROW('Brouillard ventes'!$F$9)-5,"00000")) | C9: =IF(OR('Brouillard ventes'!$F$9="",'Brouillard ventes'!$J$9="À crédit",'Brouillard ventes'!$J$9=""),"",YEAR('Brouillard ventes'!$A$9)*10000+MONTH('Brouillard ventes'!$A$9)*100+DAY('Brouillard ventes'!$A$9)) | D9: =IF(OR('Brouillard ventes'!$F$9="",'Brouillard ventes'!$J$9="À crédit",'Brouillard ventes'!$J$9=""),"",'Brouillard ventes'!$B$9) | E9: =IF(OR('Brouillard ventes'!$F$9="",'Brouillard ventes'!$J$9="À crédit",'Brouillard ventes'!$J$9=""),"","REGL "&LEFT('Brouillard ventes'!$D$9,25)) | F9: =IF(OR('Brouillard ventes'!$F$9="",'Brouillard ventes'!$J$9="À crédit",'Brouillard ventes'!$J$9=""),"",IF('Brouillard ventes'!$J$9="Espèces","04001","02001")) | G9: =IF(OR('Brouillard ventes'!$F$9="",'Brouillard ventes'!$J$9="À crédit",'Brouillard ventes'!$J$9=""),"",Paramètres!$B$7) | H9: =IF(OR('Brouillard ventes'!$F$9="",'Brouillard ventes'!$J$9="À crédit",'Brouillard ventes'!$J$9=""),"",IF('Brouillard ventes'!$C$9="","CD001",'Brouillard ventes'!$C$9)) | K9: =IF(OR('Brouillard ventes'!$F$9="",'Brouillard ventes'!$J$9="À crédit",'Brouillard ventes'!$J$9=""),"",Paramètres!$B$11) | L9: 0 | M9: =IF(OR('Brouillard ventes'!$F$9="",'Brouillard ventes'!$J$9="À crédit",'Brouillard ventes'!$J$9=""),0,'Brouillard ventes'!$I$9)
A10: 1 | B10: =IF(OR('Brouillard ventes'!$F$10="",'Brouillard ventes'!$J$10="À crédit",'Brouillard ventes'!$J$10=""),"","EC"&TEXT(ROW('Brouillard ventes'!$F$10)-5,"00000")) | C10: =IF(OR('Brouillard ventes'!$F$10="",'Brouillard ventes'!$J$10="À crédit",'Brouillard ventes'!$J$10=""),"",YEAR('Brouillard ventes'!$A$10)*10000+MONTH('Brouillard ventes'!$A$10)*100+DAY('Brouillard ventes'!$A$10)) | D10: =IF(OR('Brouillard ventes'!$F$10="",'Brouillard ventes'!$J$10="À crédit",'Brouillard ventes'!$J$10=""),"",'Brouillard ventes'!$B$10) | E10: =IF(OR('Brouillard ventes'!$F$10="",'Brouillard ventes'!$J$10="À crédit",'Brouillard ventes'!$J$10=""),"","REGL "&LEFT('Brouillard ventes'!$D$10,25)) | F10: =IF(OR('Brouillard ventes'!$F$10="",'Brouillard ventes'!$J$10="À crédit",'Brouillard ventes'!$J$10=""),"",IF('Brouillard ventes'!$J$10="Espèces","04001","02001")) | G10: =IF(OR('Brouillard ventes'!$F$10="",'Brouillard ventes'!$J$10="À crédit",'Brouillard ventes'!$J$10=""),"",IF('Brouillard ventes'!$J$10="Espèces","53000","51220")) | K10: =IF(OR('Brouillard ventes'!$F$10="",'Brouillard ventes'!$J$10="À crédit",'Brouillard ventes'!$J$10=""),"",Paramètres!$B$11) | L10: =IF(OR('Brouillard ventes'!$F$10="",'Brouillard ventes'!$J$10="À crédit",'Brouillard ventes'!$J$10=""),0,'Brouillard ventes'!$I$10) | M10: 0
A11: 1 | B11: =IF(OR('Brouillard ventes'!$F$10="",'Brouillard ventes'!$J$10="À crédit",'Brouillard ventes'!$J$10=""),"","EC"&TEXT(ROW('Brouillard ventes'!$F$10)-5,"00000")) | C11: =IF(OR('Brouillard ventes'!$F$10="",'Brouillard ventes'!$J$10="À crédit",'Brouillard ventes'!$J$10=""),"",YEAR('Brouillard ventes'!$A$10)*10000+MONTH('Brouillard ventes'!$A$10)*100+DAY('Brouillard ventes'!$A$10)) | D11: =IF(OR('Brouillard ventes'!$F$10="",'Brouillard ventes'!$J$10="À crédit",'Brouillard ventes'!$J$10=""),"",'Brouillard ventes'!$B$10) | E11: =IF(OR('Brouillard ventes'!$F$10="",'Brouillard ventes'!$J$10="À crédit",'Brouillard ventes'!$J$10=""),"","REGL "&LEFT('Brouillard ventes'!$D$10,25)) | F11: =IF(OR('Brouillard ventes'!$F$10="",'Brouillard ventes'!$J$10="À crédit",'Brouillard ventes'!$J$10=""),"",IF('Brouillard ventes'!$J$10="Espèces","04001","02001")) | G11: =IF(OR('Brouillard ventes'!$F$10="",'Brouillard ventes'!$J$10="À crédit",'Brouillard ventes'!$J$10=""),"",Paramètres!$B$7) | H11: =IF(OR('Brouillard ventes'!$F$10="",'Brouillard ventes'!$J$10="À crédit",'Brouillard ventes'!$J$10=""),"",IF('Brouillard ventes'!$C$10="","CD001",'Brouillard ventes'!$C$10)) | K11: =IF(OR('Brouillard ventes'!$F$10="",'Brouillard ventes'!$J$10="À crédit",'Brouillard ventes'!$J$10=""),"",Paramètres!$B$11) | L11: 0 | M11: =IF(OR('Brouillard ventes'!$F$10="",'Brouillard ventes'!$J$10="À crédit",'Brouillard ventes'!$J$10=""),0,'Brouillard ventes'!$I$10)
A12: 1 | B12: =IF(OR('Brouillard ventes'!$F$11="",'Brouillard ventes'!$J$11="À crédit",'Brouillard ventes'!$J$11=""),"","EC"&TEXT(ROW('Brouillard ventes'!$F$11)-5,"00000")) | C12: =IF(OR('Brouillard ventes'!$F$11="",'Brouillard ventes'!$J$11="À crédit",'Brouillard ventes'!$J$11=""),"",YEAR('Brouillard ventes'!$A$11)*10000+MONTH('Brouillard ventes'!$A$11)*100+DAY('Brouillard ventes'!$A$11)) | D12: =IF(OR('Brouillard ventes'!$F$11="",'Brouillard ventes'!$J$11="À crédit",'Brouillard ventes'!$J$11=""),"",'Brouillard ventes'!$B$11) | E12: =IF(OR('Brouillard ventes'!$F$11="",'Brouillard ventes'!$J$11="À crédit",'Brouillard ventes'!$J$11=""),"","REGL "&LEFT('Brouillard ventes'!$D$11,25)) | F12: =IF(OR('Brouillard ventes'!$F$11="",'Brouillard ventes'!$J$11="À crédit",'Brouillard ventes'!$J$11=""),"",IF('Brouillard ventes'!$J$11="Espèces","04001","02001")) | G12: =IF(OR('Brouillard ventes'!$F$11="",'Brouillard ventes'!$J$11="À crédit",'Brouillard ventes'!$J$11=""),"",IF('Brouillard ventes'!$J$11="Espèces","53000","51220")) | K12: =IF(OR('Brouillard ventes'!$F$11="",'Brouillard ventes'!$J$11="À crédit",'Brouillard ventes'!$J$11=""),"",Paramètres!$B$11) | L12: =IF(OR('Brouillard ventes'!$F$11="",'Brouillard ventes'!$J$11="À crédit",'Brouillard ventes'!$J$11=""),0,'Brouillard ventes'!$I$11) | M12: 0
A13: 1 | B13: =IF(OR('Brouillard ventes'!$F$11="",'Brouillard ventes'!$J$11="À crédit",'Brouillard ventes'!$J$11=""),"","EC"&TEXT(ROW('Brouillard ventes'!$F$11)-5,"00000")) | C13: =IF(OR('Brouillard ventes'!$F$11="",'Brouillard ventes'!$J$11="À crédit",'Brouillard ventes'!$J$11=""),"",YEAR('Brouillard ventes'!$A$11)*10000+MONTH('Brouillard ventes'!$A$11)*100+DAY('Brouillard ventes'!$A$11)) | D13: =IF(OR('Brouillard ventes'!$F$11="",'Brouillard ventes'!$J$11="À crédit",'Brouillard ventes'!$J$11=""),"",'Brouillard ventes'!$B$11) | E13: =IF(OR('Brouillard ventes'!$F$11="",'Brouillard ventes'!$J$11="À crédit",'Brouillard ventes'!$J$11=""),"","REGL "&LEFT('Brouillard ventes'!$D$11,25)) | F13: =IF(OR('Brouillard ventes'!$F$11="",'Brouillard ventes'!$J$11="À crédit",'Brouillard ventes'!$J$11=""),"",IF('Brouillard ventes'!$J$11="Espèces","04001","02001")) | G13: =IF(OR('Brouillard ventes'!$F$11="",'Brouillard ventes'!$J$11="À crédit",'Brouillard ventes'!$J$11=""),"",Paramètres!$B$7) | H13: =IF(OR('Brouillard ventes'!$F$11="",'Brouillard ventes'!$J$11="À crédit",'Brouillard ventes'!$J$11=""),"",IF('Brouillard ventes'!$C$11="","CD001",'Brouillard ventes'!$C$11)) | K13: =IF(OR('Brouillard ventes'!$F$11="",'Brouillard ventes'!$J$11="À crédit",'Brouillard ventes'!$J$11=""),"",Paramètres!$B$11) | L13: 0 | M13: =IF(OR('Brouillard ventes'!$F$11="",'Brouillard ventes'!$J$11="À crédit",'Brouillard ventes'!$J$11=""),0,'Brouillard ventes'!$I$11)
A14: 1 | B14: =IF(OR('Brouillard ventes'!$F$12="",'Brouillard ventes'!$J$12="À crédit",'Brouillard ventes'!$J$12=""),"","EC"&TEXT(ROW('Brouillard ventes'!$F$12)-5,"00000")) | C14: =IF(OR('Brouillard ventes'!$F$12="",'Brouillard ventes'!$J$12="À crédit",'Brouillard ventes'!$J$12=""),"",YEAR('Brouillard ventes'!$A$12)*10000+MONTH('Brouillard ventes'!$A$12)*100+DAY('Brouillard ventes'!$A$12)) | D14: =IF(OR('Brouillard ventes'!$F$12="",'Brouillard ventes'!$J$12="À crédit",'Brouillard ventes'!$J$12=""),"",'Brouillard ventes'!$B$12) | E14: =IF(OR('Brouillard ventes'!$F$12="",'Brouillard ventes'!$J$12="À crédit",'Brouillard ventes'!$J$12=""),"","REGL "&LEFT('Brouillard ventes'!$D$12,25)) | F14: =IF(OR('Brouillard ventes'!$F$12="",'Brouillard ventes'!$J$12="À crédit",'Brouillard ventes'!$J$12=""),"",IF('Brouillard ventes'!$J$12="Espèces","04001","02001")) | G14: =IF(OR('Brouillard ventes'!$F$12="",'Brouillard ventes'!$J$12="À crédit",'Brouillard ventes'!$J$12=""),"",IF('Brouillard ventes'!$J$12="Espèces","53000","51220")) | K14: =IF(OR('Brouillard ventes'!$F$12="",'Brouillard ventes'!$J$12="À crédit",'Brouillard ventes'!$J$12=""),"",Paramètres!$B$11) | L14: =IF(OR('Brouillard ventes'!$F$12="",'Brouillard ventes'!$J$12="À crédit",'Brouillard ventes'!$J$12=""),0,'Brouillard ventes'!$I$12) | M14: 0
A15: 1 | B15: =IF(OR('Brouillard ventes'!$F$12="",'Brouillard ventes'!$J$12="À crédit",'Brouillard ventes'!$J$12=""),"","EC"&TEXT(ROW('Brouillard ventes'!$F$12)-5,"00000")) | C15: =IF(OR('Brouillard ventes'!$F$12="",'Brouillard ventes'!$J$12="À crédit",'Brouillard ventes'!$J$12=""),"",YEAR('Brouillard ventes'!$A$12)*10000+MONTH('Brouillard ventes'!$A$12)*100+DAY('Brouillard ventes'!$A$12)) | D15: =IF(OR('Brouillard ventes'!$F$12="",'Brouillard ventes'!$J$12="À crédit",'Brouillard ventes'!$J$12=""),"",'Brouillard ventes'!$B$12) | E15: =IF(OR('Brouillard ventes'!$F$12="",'Brouillard ventes'!$J$12="À crédit",'Brouillard ventes'!$J$12=""),"","REGL "&LEFT('Brouillard ventes'!$D$12,25)) | F15: =IF(OR('Brouillard ventes'!$F$12="",'Brouillard ventes'!$J$12="À crédit",'Brouillard ventes'!$J$12=""),"",IF('Brouillard ventes'!$J$12="Espèces","04001","02001")) | G15: =IF(OR('Brouillard ventes'!$F$12="",'Brouillard ventes'!$J$12="À crédit",'Brouillard ventes'!$J$12=""),"",Paramètres!$B$7) | H15: =IF(OR('Brouillard ventes'!$F$12="",'Brouillard ventes'!$J$12="À crédit",'Brouillard ventes'!$J$12=""),"",IF('Brouillard ventes'!$C$12="","CD001",'Brouillard ventes'!$C$12)) | K15: =IF(OR('Brouillard ventes'!$F$12="",'Brouillard ventes'!$J$12="À crédit",'Brouillard ventes'!$J$12=""),"",Paramètres!$B$11) | L15: 0 | M15: =IF(OR('Brouillard ventes'!$F$12="",'Brouillard ventes'!$J$12="À crédit",'Brouillard ventes'!$J$12=""),0,'Brouillard ventes'!$I$12)
A16: 1 | B16: =IF(OR('Brouillard ventes'!$F$13="",'Brouillard ventes'!$J$13="À crédit",'Brouillard ventes'!$J$13=""),"","EC"&TEXT(ROW('Brouillard ventes'!$F$13)-5,"00000")) | C16: =IF(OR('Brouillard ventes'!$F$13="",'Brouillard ventes'!$J$13="À crédit",'Brouillard ventes'!$J$13=""),"",YEAR('Brouillard ventes'!$A$13)*10000+MONTH('Brouillard ventes'!$A$13)*100+DAY('Brouillard ventes'!$A$13)) | D16: =IF(OR('Brouillard ventes'!$F$13="",'Brouillard ventes'!$J$13="À crédit",'Brouillard ventes'!$J$13=""),"",'Brouillard ventes'!$B$13) | E16: =IF(OR('Brouillard ventes'!$F$13="",'Brouillard ventes'!$J$13="À crédit",'Brouillard ventes'!$J$13=""),"","REGL "&LEFT('Brouillard ventes'!$D$13,25)) | F16: =IF(OR('Brouillard ventes'!$F$13="",'Brouillard ventes'!$J$13="À crédit",'Brouillard ventes'!$J$13=""),"",IF('Brouillard ventes'!$J$13="Espèces","04001","02001")) | G16: =IF(OR('Brouillard ventes'!$F$13="",'Brouillard ventes'!$J$13="À crédit",'Brouillard ventes'!$J$13=""),"",IF('Brouillard ventes'!$J$13="Espèces","53000","51220")) | K16: =IF(OR('Brouillard ventes'!$F$13="",'Brouillard ventes'!$J$13="À crédit",'Brouillard ventes'!$J$13=""),"",Paramètres!$B$11) | L16: =IF(OR('Brouillard ventes'!$F$13="",'Brouillard ventes'!$J$13="À crédit",'Brouillard ventes'!$J$13=""),0,'Brouillard ventes'!$I$13) | M16: 0
A17: 1 | B17: =IF(OR('Brouillard ventes'!$F$13="",'Brouillard ventes'!$J$13="À crédit",'Brouillard ventes'!$J$13=""),"","EC"&TEXT(ROW('Brouillard ventes'!$F$13)-5,"00000")) | C17: =IF(OR('Brouillard ventes'!$F$13="",'Brouillard ventes'!$J$13="À crédit",'Brouillard ventes'!$J$13=""),"",YEAR('Brouillard ventes'!$A$13)*10000+MONTH('Brouillard ventes'!$A$13)*100+DAY('Brouillard ventes'!$A$13)) | D17: =IF(OR('Brouillard ventes'!$F$13="",'Brouillard ventes'!$J$13="À crédit",'Brouillard ventes'!$J$13=""),"",'Brouillard ventes'!$B$13) | E17: =IF(OR('Brouillard ventes'!$F$13="",'Brouillard ventes'!$J$13="À crédit",'Brouillard ventes'!$J$13=""),"","REGL "&LEFT('Brouillard ventes'!$D$13,25)) | F17: =IF(OR('Brouillard ventes'!$F$13="",'Brouillard ventes'!$J$13="À crédit",'Brouillard ventes'!$J$13=""),"",IF('Brouillard ventes'!$J$13="Espèces","04001","02001")) | G17: =IF(OR('Brouillard ventes'!$F$13="",'Brouillard ventes'!$J$13="À crédit",'Brouillard ventes'!$J$13=""),"",Paramètres!$B$7) | H17: =IF(OR('Brouillard ventes'!$F$13="",'Brouillard ventes'!$J$13="À crédit",'Brouillard ventes'!$J$13=""),"",IF('Brouillard ventes'!$C$13="","CD001",'Brouillard ventes'!$C$13)) | K17: =IF(OR('Brouillard ventes'!$F$13="",'Brouillard ventes'!$J$13="À crédit",'Brouillard ventes'!$J$13=""),"",Paramètres!$B$11) | L17: 0 | M17: =IF(OR('Brouillard ventes'!$F$13="",'Brouillard ventes'!$J$13="À crédit",'Brouillard ventes'!$J$13=""),0,'Brouillard ventes'!$I$13)
A18: 1 | B18: =IF(OR('Brouillard ventes'!$F$14="",'Brouillard ventes'!$J$14="À crédit",'Brouillard ventes'!$J$14=""),"","EC"&TEXT(ROW('Brouillard ventes'!$F$14)-5,"00000")) | C18: =IF(OR('Brouillard ventes'!$F$14="",'Brouillard ventes'!$J$14="À crédit",'Brouillard ventes'!$J$14=""),"",YEAR('Brouillard ventes'!$A$14)*10000+MONTH('Brouillard ventes'!$A$14)*100+DAY('Brouillard ventes'!$A$14)) | D18: =IF(OR('Brouillard ventes'!$F$14="",'Brouillard ventes'!$J$14="À crédit",'Brouillard ventes'!$J$14=""),"",'Brouillard ventes'!$B$14) | E18: =IF(OR('Brouillard ventes'!$F$14="",'Brouillard ventes'!$J$14="À crédit",'Brouillard ventes'!$J$14=""),"","REGL "&LEFT('Brouillard ventes'!$D$14,25)) | F18: =IF(OR('Brouillard ventes'!$F$14="",'Brouillard ventes'!$J$14="À crédit",'Brouillard ventes'!$J$14=""),"",IF('Brouillard ventes'!$J$14="Espèces","04001","02001")) | G18: =IF(OR('Brouillard ventes'!$F$14="",'Brouillard ventes'!$J$14="À crédit",'Brouillard ventes'!$J$14=""),"",IF('Brouillard ventes'!$J$14="Espèces","53000","51220")) | K18: =IF(OR('Brouillard ventes'!$F$14="",'Brouillard ventes'!$J$14="À crédit",'Brouillard ventes'!$J$14=""),"",Paramètres!$B$11) | L18: =IF(OR('Brouillard ventes'!$F$14="",'Brouillard ventes'!$J$14="À crédit",'Brouillard ventes'!$J$14=""),0,'Brouillard ventes'!$I$14) | M18: 0
A19: 1 | B19: =IF(OR('Brouillard ventes'!$F$14="",'Brouillard ventes'!$J$14="À crédit",'Brouillard ventes'!$J$14=""),"","EC"&TEXT(ROW('Brouillard ventes'!$F$14)-5,"00000")) | C19: =IF(OR('Brouillard ventes'!$F$14="",'Brouillard ventes'!$J$14="À crédit",'Brouillard ventes'!$J$14=""),"",YEAR('Brouillard ventes'!$A$14)*10000+MONTH('Brouillard ventes'!$A$14)*100+DAY('Brouillard ventes'!$A$14)) | D19: =IF(OR('Brouillard ventes'!$F$14="",'Brouillard ventes'!$J$14="À crédit",'Brouillard ventes'!$J$14=""),"",'Brouillard ventes'!$B$14) | E19: =IF(OR('Brouillard ventes'!$F$14="",'Brouillard ventes'!$J$14="À crédit",'Brouillard ventes'!$J$14=""),"","REGL "&LEFT('Brouillard ventes'!$D$14,25)) | F19: =IF(OR('Brouillard ventes'!$F$14="",'Brouillard ventes'!$J$14="À crédit",'Brouillard ventes'!$J$14=""),"",IF('Brouillard ventes'!$J$14="Espèces","04001","02001")) | G19: =IF(OR('Brouillard ventes'!$F$14="",'Brouillard ventes'!$J$14="À crédit",'Brouillard ventes'!$J$14=""),"",Paramètres!$B$7) | H19: =IF(OR('Brouillard ventes'!$F$14="",'Brouillard ventes'!$J$14="À crédit",'Brouillard ventes'!$J$14=""),"",IF('Brouillard ventes'!$C$14="","CD001",'Brouillard ventes'!$C$14)) | K19: =IF(OR('Brouillard ventes'!$F$14="",'Brouillard ventes'!$J$14="À crédit",'Brouillard ventes'!$J$14=""),"",Paramètres!$B$11) | L19: 0 | M19: =IF(OR('Brouillard ventes'!$F$14="",'Brouillard ventes'!$J$14="À crédit",'Brouillard ventes'!$J$14=""),0,'Brouillard ventes'!$I$14)
A20: 1 | B20: =IF(OR('Brouillard ventes'!$F$15="",'Brouillard ventes'!$J$15="À crédit",'Brouillard ventes'!$J$15=""),"","EC"&TEXT(ROW('Brouillard ventes'!$F$15)-5,"00000")) | C20: =IF(OR('Brouillard ventes'!$F$15="",'Brouillard ventes'!$J$15="À crédit",'Brouillard ventes'!$J$15=""),"",YEAR('Brouillard ventes'!$A$15)*10000+MONTH('Brouillard ventes'!$A$15)*100+DAY('Brouillard ventes'!$A$15)) | D20: =IF(OR('Brouillard ventes'!$F$15="",'Brouillard ventes'!$J$15="À crédit",'Brouillard ventes'!$J$15=""),"",'Brouillard ventes'!$B$15) | E20: =IF(OR('Brouillard ventes'!$F$15="",'Brouillard ventes'!$J$15="À crédit",'Brouillard ventes'!$J$15=""),"","REGL "&LEFT('Brouillard ventes'!$D$15,25)) | F20: =IF(OR('Brouillard ventes'!$F$15="",'Brouillard ventes'!$J$15="À crédit",'Brouillard ventes'!$J$15=""),"",IF('Brouillard ventes'!$J$15="Espèces","04001","02001")) | G20: =IF(OR('Brouillard ventes'!$F$15="",'Brouillard ventes'!$J$15="À crédit",'Brouillard ventes'!$J$15=""),"",IF('Brouillard ventes'!$J$15="Espèces","53000","51220")) | K20: =IF(OR('Brouillard ventes'!$F$15="",'Brouillard ventes'!$J$15="À crédit",'Brouillard ventes'!$J$15=""),"",Paramètres!$B$11) | L20: =IF(OR('Brouillard ventes'!$F$15="",'Brouillard ventes'!$J$15="À crédit",'Brouillard ventes'!$J$15=""),0,'Brouillard ventes'!$I$15) | M20: 0
