Workbook

Sheet Synthèse
A1: SARL DPR AXXAM — Synthèse de la prime du mois
A2: Tableau de bord — tout est calculé.
A3: Mois : | B3: =Paramètres!B4 -> 46296
A5: Équipe | B5: Postes travaillés | C5: Postes primés | D5: Wagons dépilés | E5: Moyenne wagons / poste | F5: Prime totale
A6: =IF(Paramètres!A11="","",Paramètres!A11) -> Équipe A | B6: =IF(A6="","",COUNTIFS(Postes!$B$5:$B$124,A6,Postes!$A$5:$A$124,">="&Paramètres!$B$4,Postes!$A$5:$A$124,"<"&Paramètres!$B$17)) -> 1 | C6: =IF(A6="","",COUNTIFS(Postes!$B$5:$B$124,A6,Postes!$A$5:$A$124,">="&Paramètres!$B$4,Postes!$A$5:$A$124,"<"&Paramètres!$B$17,Postes!$N$5:$N$124,">0")) -> 1 | D6: =IF(A6="","",SUMIFS(Postes!$F$5:$F$124,Postes!$B$5:$B$124,A6,Postes!$A$5:$A$124,">="&Paramètres!$B$4,Postes!$A$5:$A$124,"<"&Paramètres!$B$17)) -> 13 | E6: =IF(A6="","",IF(B6=0,0,D6/B6)) -> 13 | F6: =IF(A6="","",SUMIFS(Postes!$N$5:$N$124,Postes!$B$5:$B$124,A6,Postes!$A$5:$A$124,">="&Paramètres!$B$4,Postes!$A$5:$A$124,"<"&Paramètres!$B$17)) -> 4500
A7: =IF(Paramètres!A12="","",Paramètres!A12) -> Équipe B | B7: =IF(A7="","",COUNTIFS(Postes!$B$5:$B$124,A7,Postes!$A$5:$A$124,">="&Paramètres!$B$4,Postes!$A$5:$A$124,"<"&Paramètres!$B$17)) -> 1 | C7: =IF(A7="","",COUNTIFS(Postes!$B$5:$B$124,A7,Postes!$A$5:$A$124,">="&Paramètres!$B$4,Postes!$A$5:$A$124,"<"&Paramètres!$B$17,Postes!$N$5:$N$124,">0")) -> 0 | D7: =IF(A7="","",SUMIFS(Postes!$F$5:$F$124,Postes!$B$5:$B$124,A7,Postes!$A$5:$A$124,">="&Paramètres!$B$4,Postes!$A$5:$A$124,"<"&Paramètres!$B$17)) -> 12 | E7: =IF(A7="","",IF(B7=0,0,D7/B7)) -> 12 | F7: =IF(A7="","",SUMIFS(Postes!$N$5:$N$124,Postes!$B$5:$B$124,A7,Postes!$A$5:$A$124,">="&Paramètres!$B$4,Postes!$A$5:$A$124,"<"&Paramètres!$B$17)) -> 0
A8: =IF(Paramètres!A13="","",Paramètres!A13) -> Équipe C | B8: =IF(A8="","",COUNTIFS(Postes!$B$5:$B$124,A8,Postes!$A$5:$A$124,">="&Paramètres!$B$4,Postes!$A$5:$A$124,"<"&Paramètres!$B$17)) -> 0 | C8: =IF(A8="","",COUNTIFS(Postes!$B$5:$B$124,A8,Postes!$A$5:$A$124,">="&Paramètres!$B$4,Postes!$A$5:$A$124,"<"&Paramètres!$B$17,Postes!$N$5:$N$124,">0")) -> 0 | D8: =IF(A8="","",SUMIFS(Postes!$F$5:$F$124,Postes!$B$5:$B$124,A8,Postes!$A$5:$A$124,">="&Paramètres!$B$4,Postes!$A$5:$A$124,"<"&Paramètres!$B$17)) -> 0 | E8: =IF(A8="","",IF(B8=0,0,D8/B8)) -> 0 | F8: =IF(A8="","",SUMIFS(Postes!$N$5:$N$124,Postes!$B$5:$B$124,A8,Postes!$A$5:$A$124,">="&Paramètres!$B$4,Postes!$A$5:$A$124,"<"&Paramètres!$B$17)) -> 0
A9: =IF(Paramètres!A14="","",Paramètres!A14) | B9: =IF(A9="","",COUNTIFS(Postes!$B$5:$B$124,A9,Postes!$A$5:$A$124,">="&Paramètres!$B$4,Postes!$A$5:$A$124,"<"&Paramètres!$B$17)) | C9: =IF(A9="","",COUNTIFS(Postes!$B$5:$B$124,A9,Postes!$A$5:$A$124,">="&Paramètres!$B$4,Postes!$A$5:$A$124,"<"&Paramètres!$B$17,Postes!$N$5:$N$124,">0")) | D9: =IF(A9="","",SUMIFS(Postes!$F$5:$F$124,Postes!$B$5:$B$124,A9,Postes!$A$5:$A$124,">="&Paramètres!$B$4,Postes!$A$5:$A$124,"<"&Paramètres!$B$17)) | E9: =IF(A9="","",IF(B9=0,0,D9/B9)) | F9: =IF(A9="","",SUMIFS(Postes!$N$5:$N$124,Postes!$B$5:$B$124,A9,Postes!$A$5:$A$124,">="&Paramètres!$B$4,Postes!$A$5:$A$124,"<"&Paramètres!$B$17))
A10: =IF(Paramètres!A15="","",Paramètres!A15) | B10: =IF(A10="","",COUNTIFS(Postes!$B$5:$B$124,A10,Postes!$A$5:$A$124,">="&Paramètres!$B$4,Postes!$A$5:$A$124,"<"&Paramètres!$B$17)) | C10: =IF(A10="","",COUNTIFS(Postes!$B$5:$B$124,A10,Postes!$A$5:$A$124,">="&Paramètres!$B$4,Postes!$A$5:$A$124,"<"&Paramètres!$B$17,Postes!$N$5:$N$124,">0")) | D10: =IF(A10="","",SUMIFS(Postes!$F$5:$F$124,Postes!$B$5:$B$124,A10,Postes!$A$5:$A$124,">="&Paramètres!$B$4,Postes!$A$5:$A$124,"<"&Paramètres!$B$17)) | E10: =IF(A10="","",IF(B10=0,0,D10/B10)) | F10: =IF(A10="","",SUMIFS(Postes!$N$5:$N$124,Postes!$B$5:$B$124,A10,Postes!$A$5:$A$124,">="&Paramètres!$B$4,Postes!$A$5:$A$124,"<"&Paramètres!$B$17))
A11: Total | B11: =SUM(B6:B10) -> 2 | C11: =SUM(C6:C10) -> 1 | D11: =SUM(D6:D10) -> 25 | E11: =IF(B11=0,0,D11/B11) -> 12.5 | F11: =SUM(F6:F10) -> 4500
A13: Objectif | B13: =Paramètres!B5 -> 10
A14: Prime par wagon au-delà | B14: =Paramètres!B6 -> 1500
A15: Seuil de casse | B15: =Paramètres!B7 -> 0.05

Sheet Paramètres
A1: SARL DPR AXXAM — Prime de rendement
A2: Cellules jaunes = à remplir. Cellules grises = calculées, ne pas toucher.
A4: Mois de la prime (1er jour du mois) | B4: 46296 | C4: Un classeur par mois : changer cette date pour un nouveau mois.
A5: Objectif (wagons dépilés par équipe et par poste) | B5: 10 | C5: Document « Prime de rendement », décision de la direction.
A6: Prime par wagon au-delà de l'objectif | B6: 1500 | C6: Document « Prime de rendement », décision de la direction.
A7: Seuil de casse et déclassés | B7: 0.05 | C7: À FIXER PAR LA DIRECTION (laissé en blanc dans le document) : 5 % est une valeur provisoire.
A8: Paie du mois de | C8: Texte libre, ex. « novembre 2026 ».
A10: Équipes
A11: Équipe A | C11: Nommer les équipes comme à l'usine (A, B, C, matin, soir…).
A12: Équipe B
A13: Équipe C
A17: Fin du mois (calculé) | B17: =EDATE(B4,1) -> 46327
A20: Comment remplir :
A21: 1. Feuille « Employés » : la liste du personnel de production (une seule fois).
A22: 2. Feuille « Postes » : une ligne par équipe et par jour, recopiée de la fiche journalière (wagons dépilés, casse, contrôles O/N).
A23: 3. Feuille « Présences » : une ligne par personne présente ce jour-là dans cette équipe. Mettre O dans « Absence/retard injustifié » pour priver la personne de sa part.
A24: 4. Les feuilles « Récap équipe », « État employés » et « Synthèse » se remplissent toutes seules.
A25: 5. « État employés » donne le total à verser avec la paie, avec la colonne d'émargement.
A26: Règle : prime de l'équipe = (wagons dépilés − objectif) × prime par wagon, seulement si TOUS les contrôles sont à O et la casse sous le seuil.
A27: Part par personne = prime de l'équipe ÷ nombre de présents ayant droit, arrondie au dinar.

Sheet Employés
A1: SARL DPR AXXAM — Personnel de production
A2: Saisir une fois. Les noms servent de liste déroulante dans « Présences ».
A4: N° | B4: Nom et prénom | C4: Poste occupé | D4: Équipe habituelle
A5: 1 | B5: BENALI Karim | C5: Dépileur | D5: Équipe A | F5: Lignes 1 à 3 = exemples (noms fictifs) : les remplacer par le vrai personnel.
A6: 2 | B6: HADDAD Samir | C6: Dépileur | D6: Équipe A
A7: 3 | B7: MEZIANE Yacine | C7: Cariste | D7: Équipe A
A8: 4
A9: 5
A10: 6
A11: 7
A12: 8
A13: 9
A14: 10
A15: 11
A16: 12
A17: 13
A18: 14
A19: 15
... A64: 60

Sheet Postes
A1: SARL DPR AXXAM — Fiches journalières — une ligne par équipe et par poste
A2: Recopier la fiche du poste. Contrôles : O = oui, N = non. Une case vide = prime refusée.
A4: Date | B4: Équipe | C4: Chef de poste | D4: Brique | E4: Poste (horaire) | F4: Wagons dépilés (1) | G4: Casse et déclassés (%) | H4: Paquets bien présentés et cerclés | I4: Sécurité respectée | J4: Poste propre | K4: Fiche visée chef de poste et production | L4: Conditions remplies | M4: Wagons au-delà (2) | N4: Prime de l'équipe (3) | O4: Présents ayant droit (4) | P4: Part par personne | Q4: Motif si refus
A5: 46296 | B5: Équipe A | C5: Chef A | D5: B8 | E5: 6h-14h | F5: 13 | G5: 0.03 | H5: O | I5: O | J5: O | K5: O | L5: =IF(OR(A5="",B5=""),"",IF(AND(F5<>"",G5<>"",G5<=Paramètres!$B$7,H5="O",I5="O",J5="O",K5="O"),"O","N")) -> O | M5: =IF(L5="","",MAX(0,F5-Paramètres!$B$5)) -> 3 | N5: =IF(L5="","",IF(L5="O",M5*Paramètres!$B$6,0)) -> 4500 | O5: =IF(L5="","",COUNTIFS(Présences!$A$5:$A$1204,A5,Présences!$B$5:$B$1204,B5,Présences!$D$5:$D$1204,"<>O")) -> 2 | P5: =IF(L5="","",IF(O5>0,ROUND(N5/O5,0),0)) -> 2250
A6: 46296 | B6: Équipe B | C6: Chef B | D6: B8 | E6: 14h-22h | F6: 12 | G6: 0.07 | H6: O | I6: O | J6: O | K6: O | L6: =IF(OR(A6="",B6=""),"",IF(AND(F6<>"",G6<>"",G6<=Paramètres!$B$7,H6="O",I6="O",J6="O",K6="O"),"O","N")) -> N | M6: =IF(L6="","",MAX(0,F6-Paramètres!$B$5)) -> 2 | N6: =IF(L6="","",IF(L6="O",M6*Paramètres!$B$6,0)) -> 0 | O6: =IF(L6="","",COUNTIFS(Présences!$A$5:$A$1204,A6,Présences!$B$5:$B$1204,B6,Présences!$D$5:$D$1204,"<>O")) -> 0 | P6: =IF(L6="","",IF(O6>0,ROUND(N6/O6,0),0)) -> 0
L7: =IF(OR(A7="",B7=""),"",IF(AND(F7<>"",G7<>"",G7<=Paramètres!$B$7,H7="O",I7="O",J7="O",K7="O"),"O","N")) | M7: =IF(L7="","",MAX(0,F7-Paramètres!$B$5)) | N7: =IF(L7="","",IF(L7="O",M7*Paramètres!$B$6,0)) | O7: =IF(L7="","",COUNTIFS(Présences!$A$5:$A$1204,A7,Présences!$B$5:$B$1204,B7,Présences!$D$5:$D$1204,"<>O")) | P7: =IF(L7="","",IF(O7>0,ROUND(N7/O7,0),0))
L8: =IF(OR(A8="",B8=""),"",IF(AND(F8<>"",G8<>"",G8<=Paramètres!$B$7,H8="O",I8="O",J8="O",K8="O"),"O","N")) | M8: =IF(L8="","",MAX(0,F8-Paramètres!$B$5)) | N8: =IF(L8="","",IF(L8="O",M8*Paramètres!$B$6,0)) | O8: =IF(L8="","",COUNTIFS(Présences!$A$5:$A$1204,A8,Présences!$B$5:$B$1204,B8,Présences!$D$5:$D$1204,"<>O")) | P8: =IF(L8="","",IF(O8>0,ROUND(N8/O8,0),0))
L9: =IF(OR(A9="",B9=""),"",IF(AND(F9<>"",G9<>"",G9<=Paramètres!$B$7,H9="O",I9="O",J9="O",K9="O"),"O","N")) | M9: =IF(L9="","",MAX(0,F9-Paramètres!$B$5)) | N9: =IF(L9="","",IF(L9="O",M9*Paramètres!$B$6,0)) | O9: =IF(L9="","",COUNTIFS(Présences!$A$5:$A$1204,A9,Présences!$B$5:$B$1204,B9,Présences!$D$5:$D$1204,"<>O")) | P9: =IF(L9="","",IF(O9>0,ROUND(N9/O9,0),0))
L10: =IF(OR(A10="",B10=""),"",IF(AND(F10<>"",G10<>"",G10<=Paramètres!$B$7,H10="O",I10="O",J10="O",K10="O"),"O","N")) | M10: =IF(L10="","",MAX(0,F10-Paramètres!$B$5)) | N10: =IF(L10="","",IF(L10="O",M10*Paramètres!$B$6,0)) | O10: =IF(L10="","",COUNTIFS(Présences!$A$5:$A$1204,A10,Présences!$B$5:$B$1204,B10,Présences!$D$5:$D$1204,"<>O")) | P10: =IF(L10="","",IF(O10>0,ROUND(N10/O10,0),0))
L11: =IF(OR(A11="",B11=""),"",IF(AND(F11<>"",G11<>"",G11<=Paramètres!$B$7,H11="O",I11="O",J11="O",K11="O"),"O","N")) | M11: =IF(L11="","",MAX(0,F11-Paramètres!$B$5)) | N11: =IF(L11="","",IF(L11="O",M11*Paramètres!$B$6,0)) | O11: =IF(L11="","",COUNTIFS(Présences!$A$5:$A$1204,A11,Présences!$B$5:$B$1204,B11,Présences!$D$5:$D$1204,"<>O")) | P11: =IF(L11="","",IF(O11>0,ROUND(N11/O11,0),0))
L12: =IF(OR(A12="",B12=""),"",IF(AND(F12<>"",G12<>"",G12<=Paramètres!$B$7,H12="O",I12="O",J12="O",K12="O"),"O","N")) | M12: =IF(L12="","",MAX(0,F12-Paramètres!$B$5)) | N12: =IF(L12="","",IF(L12="O",M12*Paramètres!$B$6,0)) | O12: =IF(L12="","",COUNTIFS(Présences!$A$5:$A$1204,A12,Présences!$B$5:$B$1204,B12,Présences!$D$5:$D$1204,"<>O")) | P12: =IF(L12="","",IF(O12>0,ROUND(N12/O12,0),0))
L13: =IF(OR(A13="",B13=""),"",IF(AND(F13<>"",G13<>"",G13<=Paramètres!$B$7,H13="O",I13="O",J13="O",K13="O"),"O","N")) | M13: =IF(L13="","",MAX(0,F13-Paramètres!$B$5)) | N13: =IF(L13="","",IF(L13="O",M13*Paramètres!$B$6,0)) | O13: =IF(L13="","",COUNTIFS(Présences!$A$5:$A$1204,A13,Présences!$B$5:$B$1204,B13,Présences!$D$5:$D$1204,"<>O")) | P13: =IF(L13="","",IF(O13>0,ROUND(N13/O13,0),0))
L14: =IF(OR(A14="",B14=""),"",IF(AND(F14<>"",G14<>"",G14<=Paramètres!$B$7,H14="O",I14="O",J14="O",K14="O"),"O","N")) | M14: =IF(L14="","",MAX(0,F14-Paramètres!$B$5)) | N14: =IF(L14="","",IF(L14="O",M14*Paramètres!$B$6,0)) | O14: =IF(L14="","",COUNTIFS(Présences!$A$5:$A$1204,A14,Présences!$B$5:$B$1204,B14,Présences!$D$5:$D$1204,"<>O")) | P14: =IF(L14="","",IF(O14>0,ROUND(N14/O14,0),0))
L15: =IF(OR(A15="",B15=""),"",IF(AND(F15<>"",G15<>"",G15<=Paramètres!$B$7,H15="O",I15="O",J15="O",K15="O"),"O","N")) | M15: =IF(L15="","",MAX(0,F15-Paramètres!$B$5)) | N15: =IF(L15="","",IF(L15="O",M15*Paramètres!$B$6,0)) | O15: =IF(L15="","",COUNTIFS(Présences!$A$5:$A$1204,A15,Présences!$B$5:$B$1204,B15,Présences!$D$5:$D$1204,"<>O")) | P15: =IF(L15="","",IF(O15>0,ROUND(N15/O15,0),0))
L16: =IF(OR(A16="",B16=""),"",IF(AND(F16<>"",G16<>"",G16<=Paramètres!$B$7,H16="O",I16="O",J16="O",K16="O"),"O","N")) | M16: =IF(L16="","",MAX(0,F16-Paramètres!$B$5)) | N16: =IF(L16="","",IF(L16="O",M16*Paramètres!$B$6,0)) | O16: =IF(L16="","",COUNTIFS(Présences!$A$5:$A$1204,A16,Présences!$B$5:$B$1204,B16,Présences!$D$5:$D$1204,"<>O")) | P16: =IF(L16="","",IF(O16>0,ROUND(N16/O16,0),0))
L17: =IF(OR(A17="",B17=""),"",IF(AND(F17<>"",G17<>"",G17<=Paramètres!$B$7,H17="O",I17="O",J17="O",K17="O"),"O","N")) | M17: =IF(L17="","",MAX(0,F17-Paramètres!$B$5)) | N17: =IF(L17="","",IF(L17="O",M17*Paramètres!$B$6,0)) | O17: =IF(L17="","",COUNTIFS(Présences!$A$5:$A$1204,A17,Présences!$B$5:$B$1204,B17,Présences!$D$5:$D$1204,"<>O")) | P17: =IF(L17="","",IF(O17>0,ROUND(N17/O17,0),0))
L18: =IF(OR(A18="",B18=""),"",IF(AND(F18<>"",G18<>"",G18<=Paramètres!$B$7,H18="O",I18="O",J18="O",K18="O"),"O","N")) | M18: =IF(L18="","",MAX(0,F18-Paramètres!$B$5)) | N18: =IF(L18="","",IF(L18="O",M18*Paramètres!$B$6,0)) | O18: =IF(L18="","",COUNTIFS(Présences!$A$5:$A$1204,A18,Présences!$B$5:$B$1204,B18,Présences!$D$5:$D$1204,"<>O")) | P18: =IF(L18="","",IF(O18>0,ROUND(N18/O18,0),0))
... L124: =IF(OR(A124="",B124=""),"",IF(AND(F124<>"",G124<>"",G124<=Paramètres!$B$7,H124="O",I124="O",J124="O",K124="O"),"O","N")) | M124: =IF(L124="","",MAX(0,F124-Paramètres!$B$5)) | N124: =IF(L124="","",IF(L124="O",M124*Paramètres!$B$6,0)) | O124: =IF(L124="","",COUNTIFS(Présences!$A$5:$A$1204,A124,Présences!$B$5:$B$1204,B124,Présences!$D$5:$D$1204,"<>O")) | P124: =IF(L124="","",IF(O124>0,ROUND(N124/O124,0),0))

Sheet Présences
A1: SARL DPR AXXAM — Présences par poste
A2: Une ligne par personne présente. La part se calcule toute seule.
A4: Date | B4: Équipe | C4: Nom et prénom | D4: Absence/retard injustifié (O = pas de prime) | E4: Part (DA)
A5: 46296 | B5: Équipe A | C5: BENALI Karim | E5: =IF(OR(A5="",B5="",C5=""),"",IF(D5="O",0,SUMIFS(Postes!$P$5:$P$124,Postes!$A$5:$A$124,A5,Postes!$B$5:$B$124,B5))) -> 2250
A6: 46296 | B6: Équipe A | C6: HADDAD Samir | E6: =IF(OR(A6="",B6="",C6=""),"",IF(D6="O",0,SUMIFS(Postes!$P$5:$P$124,Postes!$A$5:$A$124,A6,Postes!$B$5:$B$124,B6))) -> 2250
A7: 46296 | B7: Équipe A | C7: MEZIANE Yacine | D7: O | E7: =IF(OR(A7="",B7="",C7=""),"",IF(D7="O",0,SUMIFS(Postes!$P$5:$P$124,Postes!$A$5:$A$124,A7,Postes!$B$5:$B$124,B7))) -> 0
E8: =IF(OR(A8="",B8="",C8=""),"",IF(D8="O",0,SUMIFS(Postes!$P$5:$P$124,Postes!$A$5:$A$124,A8,Postes!$B$5:$B$124,B8)))
E9: =IF(OR(A9="",B9="",C9=""),"",IF(D9="O",0,SUMIFS(Postes!$P$5:$P$124,Postes!$A$5:$A$124,A9,Postes!$B$5:$B$124,B9)))
E10: =IF(OR(A10="",B10="",C10=""),"",IF(D10="O",0,SUMIFS(Postes!$P$5:$P$124,Postes!$A$5:$A$124,A10,Postes!$B$5:$B$124,B10)))
E11: =IF(OR(A11="",B11="",C11=""),"",IF(D11="O",0,SUMIFS(Postes!$P$5:$P$124,Postes!$A$5:$A$124,A11,Postes!$B$5:$B$124,B11)))
E12: =IF(OR(A12="",B12="",C12=""),"",IF(D12="O",0,SUMIFS(Postes!$P$5:$P$124,Postes!$A$5:$A$124,A12,Postes!$B$5:$B$124,B12)))
E13: =IF(OR(A13="",B13="",C13=""),"",IF(D13="O",0,SUMIFS(Postes!$P$5:$P$124,Postes!$A$5:$A$124,A13,Postes!$B$5:$B$124,B13)))
E14: =IF(OR(A14="",B14="",C14=""),"",IF(D14="O",0,SUMIFS(Postes!$P$5:$P$124,Postes!$A$5:$A$124,A14,Postes!$B$5:$B$124,B14)))
E15: =IF(OR(A15="",B15="",C15=""),"",IF(D15="O",0,SUMIFS(Postes!$P$5:$P$124,Postes!$A$5:$A$124,A15,Postes!$B$5:$B$124,B15)))
E16: =IF(OR(A16="",B16="",C16=""),"",IF(D16="O",0,SUMIFS(Postes!$P$5:$P$124,Postes!$A$5:$A$124,A16,Postes!$B$5:$B$124,B16)))
E17: =IF(OR(A17="",B17="",C17=""),"",IF(D17="O",0,SUMIFS(Postes!$P$5:$P$124,Postes!$A$5:$A$124,A17,Postes!$B$5:$B$124,B17)))
E18: =IF(OR(A18="",B18="",C18=""),"",IF(D18="O",0,SUMIFS(Postes!$P$5:$P$124,Postes!$A$5:$A$124,A18,Postes!$B$5:$B$124,B18)))
E19: =IF(OR(A19="",B19="",C19=""),"",IF(D19="O",0,SUMIFS(Postes!$P$5:$P$124,Postes!$A$5:$A$124,A19,Postes!$B$5:$B$124,B19)))
... E1204: =IF(OR(A1204="",B1204="",C1204=""),"",IF(D1204="O",0,SUMIFS(Postes!$P$5:$P$124,Postes!$A$5:$A$124,A1204,Postes!$B$5:$B$124,B1204)))

Sheet Récap équipe
A1: SARL DPR AXXAM — Récapitulatif mensuel de la prime — par équipe
A2: Choisir l'équipe en B3 (liste déroulante).
A3: Équipe : | B3: Équipe A | D3: Mois : | E3: =Paramètres!B4 -> 46296
A5: Jour | B5: Date | C5: Wagons dépilés | D5: Au-delà de l'objectif | E5: Casse (%) | F5: Qualité (O/N) | G5: Prime équipe | H5: Présents | I5: Part / pers. | J5: Visa
A6: 1 | B6: =IF(MONTH(Paramètres!$B$4+0)=MONTH(Paramètres!$B$4),Paramètres!$B$4+0,"") -> 46296 | C6: =IF(OR(B6="",COUNTIFS(Postes!$A$5:$A$124,B6,Postes!$B$5:$B$124,$B$3)=0),"",SUMIFS(Postes!$F$5:$F$124,Postes!$A$5:$A$124,B6,Postes!$B$5:$B$124,$B$3)) -> 13 | D6: =IF(OR(B6="",COUNTIFS(Postes!$A$5:$A$124,B6,Postes!$B$5:$B$124,$B$3)=0),"",SUMIFS(Postes!$M$5:$M$124,Postes!$A$5:$A$124,B6,Postes!$B$5:$B$124,$B$3)) -> 3 | E6: =IF(OR(B6="",COUNTIFS(Postes!$A$5:$A$124,B6,Postes!$B$5:$B$124,$B$3)=0),"",AVERAGEIFS(Postes!$G$5:$G$124,Postes!$A$5:$A$124,B6,Postes!$B$5:$B$124,$B$3)) -> 0.03 | F6: =IF(OR(B6="",COUNTIFS(Postes!$A$5:$A$124,B6,Postes!$B$5:$B$124,$B$3)=0),"",IF(COUNTIFS(Postes!$A$5:$A$124,B6,Postes!$B$5:$B$124,$B$3,Postes!$L$5:$L$124,"O")>0,"O","N")) -> O | G6: =IF(OR(B6="",COUNTIFS(Postes!$A$5:$A$124,B6,Postes!$B$5:$B$124,$B$3)=0),"",SUMIFS(Postes!$N$5:$N$124,Postes!$A$5:$A$124,B6,Postes!$B$5:$B$124,$B$3)) -> 4500 | H6: =IF(OR(B6="",COUNTIFS(Postes!$A$5:$A$124,B6,Postes!$B$5:$B$124,$B$3)=0),"",SUMIFS(Postes!$O$5:$O$124,Postes!$A$5:$A$124,B6,Postes!$B$5:$B$124,$B$3)) -> 2 | I6: =IF(OR(B6="",COUNTIFS(Postes!$A$5:$A$124,B6,Postes!$B$5:$B$124,$B$3)=0),"",SUMIFS(Postes!$P$5:$P$124,Postes!$A$5:$A$124,B6,Postes!$B$5:$B$124,$B$3)) -> 2250
A7: 2 | B7: =IF(MONTH(Paramètres!$B$4+1)=MONTH(Paramètres!$B$4),Paramètres!$B$4+1,"") -> 46297 | C7: =IF(OR(B7="",COUNTIFS(Postes!$A$5:$A$124,B7,Postes!$B$5:$B$124,$B$3)=0),"",SUMIFS(Postes!$F$5:$F$124,Postes!$A$5:$A$124,B7,Postes!$B$5:$B$124,$B$3)) | D7: =IF(OR(B7="",COUNTIFS(Postes!$A$5:$A$124,B7,Postes!$B$5:$B$124,$B$3)=0),"",SUMIFS(Postes!$M$5:$M$124,Postes!$A$5:$A$124,B7,Postes!$B$5:$B$124,$B$3)) | E7: =IF(OR(B7="",COUNTIFS(Postes!$A$5:$A$124,B7,Postes!$B$5:$B$124,$B$3)=0),"",AVERAGEIFS(Postes!$G$5:$G$124,Postes!$A$5:$A$124,B7,Postes!$B$5:$B$124,$B$3)) | F7: =IF(OR(B7="",COUNTIFS(Postes!$A$5:$A$124,B7,Postes!$B$5:$B$124,$B$3)=0),"",IF(COUNTIFS(Postes!$A$5:$A$124,B7,Postes!$B$5:$B$124,$B$3,Postes!$L$5:$L$124,"O")>0,"O","N")) | G7: =IF(OR(B7="",COUNTIFS(Postes!$A$5:$A$124,B7,Postes!$B$5:$B$124,$B$3)=0),"",SUMIFS(Postes!$N$5:$N$124,Postes!$A$5:$A$124,B7,Postes!$B$5:$B$124,$B$3)) | H7: =IF(OR(B7="",COUNTIFS(Postes!$A$5:$A$124,B7,Postes!$B$5:$B$124,$B$3)=0),"",SUMIFS(Postes!$O$5:$O$124,Postes!$A$5:$A$124,B7,Postes!$B$5:$B$124,$B$3)) | I7: =IF(OR(B7="",COUNTIFS(Postes!$A$5:$A$124,B7,Postes!$B$5:$B$124,$B$3)=0),"",SUMIFS(Postes!$P$5:$P$124,Postes!$A$5:$A$124,B7,Postes!$B$5:$B$124,$B$3))
A8: 3 | B8: =IF(MONTH(Paramètres!$B$4+2)=MONTH(Paramètres!$B$4),Paramètres!$B$4+2,"") -> 46298 | C8: =IF(OR(B8="",COUNTIFS(Postes!$A$5:$A$124,B8,Postes!$B$5:$B$124,$B$3)=0),"",SUMIFS(Postes!$F$5:$F$124,Postes!$A$5:$A$124,B8,Postes!$B$5:$B$124,$B$3)) | D8: =IF(OR(B8="",COUNTIFS(Postes!$A$5:$A$124,B8,Postes!$B$5:$B$124,$B$3)=0),"",SUMIFS(Postes!$M$5:$M$124,Postes!$A$5:$A$124,B8,Postes!$B$5:$B$124,$B$3)) | E8: =IF(OR(B8="",COUNTIFS(Postes!$A$5:$A$124,B8,Postes!$B$5:$B$124,$B$3)=0),"",AVERAGEIFS(Postes!$G$5:$G$124,Postes!$A$5:$A$124,B8,Postes!$B$5:$B$124,$B$3)) | F8: =IF(OR(B8="",COUNTIFS(Postes!$A$5:$A$124,B8,Postes!$B$5:$B$124,$B$3)=0),"",IF(COUNTIFS(Postes!$A$5:$A$124,B8,Postes!$B$5:$B$124,$B$3,Postes!$L$5:$L$124,"O")>0,"O","N")) | G8: =IF(OR(B8="",COUNTIFS(Postes!$A$5:$A$124,B8,Postes!$B$5:$B$124,$B$3)=0),"",SUMIFS(Postes!$N$5:$N$124,Postes!$A$5:$A$124,B8,Postes!$B$5:$B$124,$B$3)) | H8: =IF(OR(B8="",COUNTIFS(Postes!$A$5:$A$124,B8,Postes!$B$5:$B$124,$B$3)=0),"",SUMIFS(Postes!$O$5:$O$124,Postes!$A$5:$A$124,B8,Postes!$B$5:$B$124,$B$3)) | I8: =IF(OR(B8="",COUNTIFS(Postes!$A$5:$A$124,B8,Postes!$B$5:$B$124,$B$3)=0),"",SUMIFS(Postes!$P$5:$P$124,Postes!$A$5:$A$124,B8,Postes!$B$5:$B$124,$B$3))
A9: 4 | B9: =IF(MONTH(Paramètres!$B$4+3)=MONTH(Paramètres!$B$4),Paramètres!$B$4+3,"") -> 46299 | C9: =IF(OR(B9="",COUNTIFS(Postes!$A$5:$A$124,B9,Postes!$B$5:$B$124,$B$3)=0),"",SUMIFS(Postes!$F$5:$F$124,Postes!$A$5:$A$124,B9,Postes!$B$5:$B$124,$B$3)) | D9: =IF(OR(B9="",COUNTIFS(Postes!$A$5:$A$124,B9,Postes!$B$5:$B$124,$B$3)=0),"",SUMIFS(Postes!$M$5:$M$124,Postes!$A$5:$A$124,B9,Postes!$B$5:$B$124,$B$3)) | E9: =IF(OR(B9="",COUNTIFS(Postes!$A$5:$A$124,B9,Postes!$B$5:$B$124,$B$3)=0),"",AVERAGEIFS(Postes!$G$5:$G$124,Postes!$A$5:$A$124,B9,Postes!$B$5:$B$124,$B$3)) | F9: =IF(OR(B9="",COUNTIFS(Postes!$A$5:$A$124,B9,Postes!$B$5:$B$124,$B$3)=0),"",IF(COUNTIFS(Postes!$A$5:$A$124,B9,Postes!$B$5:$B$124,$B$3,Postes!$L$5:$L$124,"O")>0,"O","N")) | G9: =IF(OR(B9="",COUNTIFS(Postes!$A$5:$A$124,B9,Postes!$B$5:$B$124,$B$3)=0),"",SUMIFS(Postes!$N$5:$N$124,Postes!$A$5:$A$124,B9,Postes!$B$5:$B$124,$B$3)) | H9: =IF(OR(B9="",COUNTIFS(Postes!$A$5:$A$124,B9,Postes!$B$5:$B$124,$B$3)=0),"",SUMIFS(Postes!$O$5:$O$124,Postes!$A$5:$A$124,B9,Postes!$B$5:$B$124,$B$3)) | I9: =IF(OR(B9="",COUNTIFS(Postes!$A$5:$A$124,B9,Postes!$B$5:$B$124,$B$3)=0),"",SUMIFS(Postes!$P$5:$P$124,Postes!$A$5:$A$124,B9,Postes!$B$5:$B$124,$B$3))
A10: 5 | B10: =IF(MONTH(Paramètres!$B$4+4)=MONTH(Paramètres!$B$4),Paramètres!$B$4+4,"") -> 46300 | C10: =IF(OR(B10="",COUNTIFS(Postes!$A$5:$A$124,B10,Postes!$B$5:$B$124,$B$3)=0),"",SUMIFS(Postes!$F$5:$F$124,Postes!$A$5:$A$124,B10,Postes!$B$5:$B$124,$B$3)) | D10: =IF(OR(B10="",COUNTIFS(Postes!$A$5:$A$124,B10,Postes!$B$5:$B$124,$B$3)=0),"",SUMIFS(Postes!$M$5:$M$124,Postes!$A$5:$A$124,B10,Postes!$B$5:$B$124,$B$3)) | E10: =IF(OR(B10="",COUNTIFS(Postes!$A$5:$A$124,B10,Postes!$B$5:$B$124,$B$3)=0),"",AVERAGEIFS(Postes!$G$5:$G$124,Postes!$A$5:$A$124,B10,Postes!$B$5:$B$124,$B$3)) | F10: =IF(OR(B10="",COUNTIFS(Postes!$A$5:$A$124,B10,Postes!$B$5:$B$124,$B$3)=0),"",IF(COUNTIFS(Postes!$A$5:$A$124,B10,Postes!$B$5:$B$124,$B$3,Postes!$L$5:$L$124,"O")>0,"O","N")) | G10: =IF(OR(B10="",COUNTIFS(Postes!$A$5:$A$124,B10,Postes!$B$5:$B$124,$B$3)=0),"",SUMIFS(Postes!$N$5:$N$124,Postes!$A$5:$A$124,B10,Postes!$B$5:$B$124,$B$3)) | H10: =IF(OR(B10="",COUNTIFS(Postes!$A$5:$A$124,B10,Postes!$B$5:$B$124,$B$3)=0),"",SUMIFS(Postes!$O$5:$O$124,Postes!$A$5:$A$124,B10,Postes!$B$5:$B$124,$B$3)) | I10: =IF(OR(B10="",COUNTIFS(Postes!$A$5:$A$124,B10,Postes!$B$5:$B$124,$B$3)=0),"",SUMIFS(Postes!$P$5:$P$124,Postes!$A$5:$A$124,B10,Postes!$B$5:$B$124,$B$3))
A11: 6 | B11: =IF(MONTH(Paramètres!$B$4+5)=MONTH(Paramètres!$B$4),Paramètres!$B$4+5,"") -> 46301 | C11: =IF(OR(B11="",COUNTIFS(Postes!$A$5:$A$124,B11,Postes!$B$5:$B$124,$B$3)=0),"",SUMIFS(Postes!$F$5:$F$124,Postes!$A$5:$A$124,B11,Postes!$B$5:$B$124,$B$3)) | D11: =IF(OR(B11="",COUNTIFS(Postes!$A$5:$A$124,B11,Postes!$B$5:$B$124,$B$3)=0),"",SUMIFS(Postes!$M$5:$M$124,Postes!$A$5:$A$124,B11,Postes!$B$5:$B$124,$B$3)) | E11: =IF(OR(B11="",COUNTIFS(Postes!$A$5:$A$124,B11,Postes!$B$5:$B$124,$B$3)=0),"",AVERAGEIFS(Postes!$G$5:$G$124,Postes!$A$5:$A$124,B11,Postes!$B$5:$B$124,$B$3)) | F11: =IF(OR(B11="",COUNTIFS(Postes!$A$5:$A$124,B11,Postes!$B$5:$B$124,$B$3)=0),"",IF(COUNTIFS(Postes!$A$5:$A$124,B11,Postes!$B$5:$B$124,$B$3,Postes!$L$5:$L$124,"O")>0,"O","N")) | G11: =IF(OR(B11="",COUNTIFS(Postes!$A$5:$A$124,B11,Postes!$B$5:$B$124,$B$3)=0),"",SUMIFS(Postes!$N$5:$N$124,Postes!$A$5:$A$124,B11,Postes!$B$5:$B$124,$B$3)) | H11: =IF(OR(B11="",COUNTIFS(Postes!$A$5:$A$124,B11,Postes!$B$5:$B$124,$B$3)=0),"",SUMIFS(Postes!$O$5:$O$124,Postes!$A$5:$A$124,B11,Postes!$B$5:$B$124,$B$3)) | I11: =IF(OR(B11="",COUNTIFS(Postes!$A$5:$A$124,B11,Postes!$B$5:$B$124,$B$3)=0),"",SUMIFS(Postes!$P$5:$P$124,Postes!$A$5:$A$124,B11,Postes!$B$5:$B$124,$B$3))
A12: 7 | B12: =IF(MONTH(Paramètres!$B$4+6)=MONTH(Paramètres!$B$4),Paramètres!$B$4+6,"") -> 46302 | C12: =IF(OR(B12="",COUNTIFS(Postes!$A$5:$A$124,B12,Postes!$B$5:$B$124,$B$3)=0),"",SUMIFS(Postes!$F$5:$F$124,Postes!$A$5:$A$124,B12,Postes!$B$5:$B$124,$B$3)) | D12: =IF(OR(B12="",COUNTIFS(Postes!$A$5:$A$124,B12,Postes!$B$5:$B$124,$B$3)=0),"",SUMIFS(Postes!$M$5:$M$124,Postes!$A$5:$A$124,B12,Postes!$B$5:$B$124,$B$3)) | E12: =IF(OR(B12="",COUNTIFS(Postes!$A$5:$A$124,B12,Postes!$B$5:$B$124,$B$3)=0),"",AVERAGEIFS(Postes!$G$5:$G$124,Postes!$A$5:$A$124,B12,Postes!$B$5:$B$124,$B$3)) | F12: =IF(OR(B12="",COUNTIFS(Postes!$A$5:$A$124,B12,Postes!$B$5:$B$124,$B$3)=0),"",IF(COUNTIFS(Postes!$A$5:$A$124,B12,Postes!$B$5:$B$124,$B$3,Postes!$L$5:$L$124,"O")>0,"O","N")) | G12: =IF(OR(B12="",COUNTIFS(Postes!$A$5:$A$124,B12,Postes!$B$5:$B$124,$B$3)=0),"",SUMIFS(Postes!$N$5:$N$124,Postes!$A$5:$A$124,B12,Postes!$B$5:$B$124,$B$3)) | H12: =IF(OR(B12="",COUNTIFS(Postes!$A$5:$A$124,B12,Postes!$B$5:$B$124,$B$3)=0),"",SUMIFS(Postes!$O$5:$O$124,Postes!$A$5:$A$124,B12,Postes!$B$5:$B$124,$B$3)) | I12: =IF(OR(B12="",COUNTIFS(Postes!$A$5:$A$124,B12,Postes!$B$5:$B$124,$B$3)=0),"",SUMIFS(Postes!$P$5:$P$124,Postes!$A$5:$A$124,B12,Postes!$B$5:$B$124,$B$3))
A13: 8 | B13: =IF(MONTH(Paramètres!$B$4+7)=MONTH(Paramètres!$B$4),Paramètres!$B$4+7,"") -> 46303 | C13: =IF(OR(B13="",COUNTIFS(Postes!$A$5:$A$124,B13,Postes!$B$5:$B$124,$B$3)=0),"",SUMIFS(Postes!$F$5:$F$124,Postes!$A$5:$A$124,B13,Postes!$B$5:$B$124,$B$3)) | D13: =IF(OR(B13="",COUNTIFS(Postes!$A$5:$A$124,B13,Postes!$B$5:$B$124,$B$3)=0),"",SUMIFS(Postes!$M$5:$M$124,Postes!$A$5:$A$124,B13,Postes!$B$5:$B$124,$B$3)) | E13: =IF(OR(B13="",COUNTIFS(Postes!$A$5:$A$124,B13,Postes!$B$5:$B$124,$B$3)=0),"",AVERAGEIFS(Postes!$G$5:$G$124,Postes!$A$5:$A$124,B13,Postes!$B$5:$B$124,$B$3)) | F13: =IF(OR(B13="",COUNTIFS(Postes!$A$5:$A$124,B13,Postes!$B$5:$B$124,$B$3)=0),"",IF(COUNTIFS(Postes!$A$5:$A$124,B13,Postes!$B$5:$B$124,$B$3,Postes!$L$5:$L$124,"O")>0,"O","N")) | G13: =IF(OR(B13="",COUNTIFS(Postes!$A$5:$A$124,B13,Postes!$B$5:$B$124,$B$3)=0),"",SUMIFS(Postes!$N$5:$N$124,Postes!$A$5:$A$124,B13,Postes!$B$5:$B$124,$B$3)) | H13: =IF(OR(B13="",COUNTIFS(Postes!$A$5:$A$124,B13,Postes!$B$5:$B$124,$B$3)=0),"",SUMIFS(Postes!$O$5:$O$124,Postes!$A$5:$A$124,B13,Postes!$B$5:$B$124,$B$3)) | I13: =IF(OR(B13="",COUNTIFS(Postes!$A$5:$A$124,B13,Postes!$B$5:$B$124,$B$3)=0),"",SUMIFS(Postes!$P$5:$P$124,Postes!$A$5:$A$124,B13,Postes!$B$5:$B$124,$B$3))
A14: 9 | B14: =IF(MONTH(Paramètres!$B$4+8)=MONTH(Paramètres!$B$4),Paramètres!$B$4+8,"") -> 46304 | C14: =IF(OR(B14="",COUNTIFS(Postes!$A$5:$A$124,B14,Postes!$B$5:$B$124,$B$3)=0),"",SUMIFS(Postes!$F$5:$F$124,Postes!$A$5:$A$124,B14,Postes!$B$5:$B$124,$B$3)) | D14: =IF(OR(B14="",COUNTIFS(Postes!$A$5:$A$124,B14,Postes!$B$5:$B$124,$B$3)=0),"",SUMIFS(Postes!$M$5:$M$124,Postes!$A$5:$A$124,B14,Postes!$B$5:$B$124,$B$3)) | E14: =IF(OR(B14="",COUNTIFS(Postes!$A$5:$A$124,B14,Postes!$B$5:$B$124,$B$3)=0),"",AVERAGEIFS(Postes!$G$5:$G$124,Postes!$A$5:$A$124,B14,Postes!$B$5:$B$124,$B$3)) | F14: =IF(OR(B14="",COUNTIFS(Postes!$A$5:$A$124,B14,Postes!$B$5:$B$124,$B$3)=0),"",IF(COUNTIFS(Postes!$A$5:$A$124,B14,Postes!$B$5:$B$124,$B$3,Postes!$L$5:$L$124,"O")>0,"O","N")) | G14: =IF(OR(B14="",COUNTIFS(Postes!$A$5:$A$124,B14,Postes!$B$5:$B$124,$B$3)=0),"",SUMIFS(Postes!$N$5:$N$124,Postes!$A$5:$A$124,B14,Postes!$B$5:$B$124,$B$3)) | H14: =IF(OR(B14="",COUNTIFS(Postes!$A$5:$A$124,B14,Postes!$B$5:$B$124,$B$3)=0),"",SUMIFS(Postes!$O$5:$O$124,Postes!$A$5:$A$124,B14,Postes!$B$5:$B$124,$B$3)) | I14: =IF(OR(B14="",COUNTIFS(Postes!$A$5:$A$124,B14,Postes!$B$5:$B$124,$B$3)=0),"",SUMIFS(Postes!$P$5:$P$124,Postes!$A$5:$A$124,B14,Postes!$B$5:$B$124,$B$3))
A15: 10 | B15: =IF(MONTH(Paramètres!$B$4+9)=MONTH(Paramètres!$B$4),Paramètres!$B$4+9,"") -> 46305 | C15: =IF(OR(B15="",COUNTIFS(Postes!$A$5:$A$124,B15,Postes!$B$5:$B$124,$B$3)=0),"",SUMIFS(Postes!$F$5:$F$124,Postes!$A$5:$A$124,B15,Postes!$B$5:$B$124,$B$3)) | D15: =IF(OR(B15="",COUNTIFS(Postes!$A$5:$A$124,B15,Postes!$B$5:$B$124,$B$3)=0),"",SUMIFS(Postes!$M$5:$M$124,Postes!$A$5:$A$124,B15,Postes!$B$5:$B$124,$B$3)) | E15: =IF(OR(B15="",COUNTIFS(Postes!$A$5:$A$124,B15,Postes!$B$5:$B$124,$B$3)=0),"",AVERAGEIFS(Postes!$G$5:$G$124,Postes!$A$5:$A$124,B15,Postes!$B$5:$B$124,$B$3)) | F15: =IF(OR(B15="",COUNTIFS(Postes!$A$5:$A$124,B15,Postes!$B$5:$B$124,$B$3)=0),"",IF(COUNTIFS(Postes!$A$5:$A$124,B15,Postes!$B$5:$B$124,$B$3,Postes!$L$5:$L$124,"O")>0,"O","N")) | G15: =IF(OR(B15="",COUNTIFS(Postes!$A$5:$A$124,B15,Postes!$B$5:$B$124,$B$3)=0),"",SUMIFS(Postes!$N$5:$N$124,Postes!$A$5:$A$124,B15,Postes!$B$5:$B$124,$B$3)) | H15: =IF(OR(B15="",COUNTIFS(Postes!$A$5:$A$124,B15,Postes!$B$5:$B$124,$B$3)=0),"",SUMIFS(Postes!$O$5:$O$124,Postes!$A$5:$A$124,B15,Postes!$B$5:$B$124,$B$3)) | I15: =IF(OR(B15="",COUNTIFS(Postes!$A$5:$A$124,B15,Postes!$B$5:$B$124,$B$3)=0),"",SUMIFS(Postes!$P$5:$P$124,Postes!$A$5:$A$124,B15,Postes!$B$5:$B$124,$B$3))
A16: 11 | B16: =IF(MONTH(Paramètres!$B$4+10)=MONTH(Paramètres!$B$4),Paramètres!$B$4+10,"") -> 46306 | C16: =IF(OR(B16="",COUNTIFS(Postes!$A$5:$A$124,B16,Postes!$B$5:$B$124,$B$3)=0),"",SUMIFS(Postes!$F$5:$F$124,Postes!$A$5:$A$124,B16,Postes!$B$5:$B$124,$B$3)) | D16: =IF(OR(B16="",COUNTIFS(Postes!$A$5:$A$124,B16,Postes!$B$5:$B$124,$B$3)=0),"",SUMIFS(Postes!$M$5:$M$124,Postes!$A$5:$A$124,B16,Postes!$B$5:$B$124,$B$3)) | E16: =IF(OR(B16="",COUNTIFS(Postes!$A$5:$A$124,B16,Postes!$B$5:$B$124,$B$3)=0),"",AVERAGEIFS(Postes!$G$5:$G$124,Postes!$A$5:$A$124,B16,Postes!$B$5:$B$124,$B$3)) | F16: =IF(OR(B16="",COUNTIFS(Postes!$A$5:$A$124,B16,Postes!$B$5:$B$124,$B$3)=0),"",IF(COUNTIFS(Postes!$A$5:$A$124,B16,Postes!$B$5:$B$124,$B$3,Postes!$L$5:$L$124,"O")>0,"O","N")) | G16: =IF(OR(B16="",COUNTIFS(Postes!$A$5:$A$124,B16,Postes!$B$5:$B$124,$B$3)=0),"",SUMIFS(Postes!$N$5:$N$124,Postes!$A$5:$A$124,B16,Postes!$B$5:$B$124,$B$3)) | H16: =IF(OR(B16="",COUNTIFS(Postes!$A$5:$A$124,B16,Postes!$B$5:$B$124,$B$3)=0),"",SUMIFS(Postes!$O$5:$O$124,Postes!$A$5:$A$124,B16,Postes!$B$5:$B$124,$B$3)) | I16: =IF(OR(B16="",COUNTIFS(Postes!$A$5:$A$124,B16,Postes!$B$5:$B$124,$B$3)=0),"",SUMIFS(Postes!$P$5:$P$124,Postes!$A$5:$A$124,B16,Postes!$B$5:$B$124,$B$3))
A17: 12 | B17: =IF(MONTH(Paramètres!$B$4+11)=MONTH(Paramètres!$B$4),Paramètres!$B$4+11,"") -> 46307 | C17: =IF(OR(B17="",COUNTIFS(Postes!$A$5:$A$124,B17,Postes!$B$5:$B$124,$B$3)=0),"",SUMIFS(Postes!$F$5:$F$124,Postes!$A$5:$A$124,B17,Postes!$B$5:$B$124,$B$3)) | D17: =IF(OR(B17="",COUNTIFS(Postes!$A$5:$A$124,B17,Postes!$B$5:$B$124,$B$3)=0),"",SUMIFS(Postes!$M$5:$M$124,Postes!$A$5:$A$124,B17,Postes!$B$5:$B$124,$B$3)) | E17: =IF(OR(B17="",COUNTIFS(Postes!$A$5:$A$124,B17,Postes!$B$5:$B$124,$B$3)=0),"",AVERAGEIFS(Postes!$G$5:$G$124,Postes!$A$5:$A$124,B17,Postes!$B$5:$B$124,$B$3)) | F17: =IF(OR(B17="",COUNTIFS(Postes!$A$5:$A$124,B17,Postes!$B$5:$B$124,$B$3)=0),"",IF(COUNTIFS(Postes!$A$5:$A$124,B17,Postes!$B$5:$B$124,$B$3,Postes!$L$5:$L$124,"O")>0,"O","N")) | G17: =IF(OR(B17="",COUNTIFS(Postes!$A$5:$A$124,B17,Postes!$B$5:$B$124,$B$3)=0),"",SUMIFS(Postes!$N$5:$N$124,Postes!$A$5:$A$124,B17,Postes!$B$5:$B$124,$B$3)) | H17: =IF(OR(B17="",COUNTIFS(Postes!$A$5:$A$124,B17,Postes!$B$5:$B$124,$B$3)=0),"",SUMIFS(Postes!$O$5:$O$124,Postes!$A$5:$A$124,B17,Postes!$B$5:$B$124,$B$3)) | I17: =IF(OR(B17="",COUNTIFS(Postes!$A$5:$A$124,B17,Postes!$B$5:$B$124,$B$3)=0),"",SUMIFS(Postes!$P$5:$P$124,Postes!$A$5:$A$124,B17,Postes!$B$5:$B$124,$B$3))
A18: 13 | B18: =IF(MONTH(Paramètres!$B$4+12)=MONTH(Paramètres!$B$4),Paramètres!$B$4+12,"") -> 46308 | C18: =IF(OR(B18="",COUNTIFS(Postes!$A$5:$A$124,B18,Postes!$B$5:$B$124,$B$3)=0),"",SUMIFS(Postes!$F$5:$F$124,Postes!$A$5:$A$124,B18,Postes!$B$5:$B$124,$B$3)) | D18: =IF(OR(B18="",COUNTIFS(Postes!$A$5:$A$124,B18,Postes!$B$5:$B$124,$B$3)=0),"",SUMIFS(Postes!$M$5:$M$124,Postes!$A$5:$A$124,B18,Postes!$B$5:$B$124,$B$3)) | E18: =IF(OR(B18="",COUNTIFS(Postes!$A$5:$A$124,B18,Postes!$B$5:$B$124,$B$3)=0),"",AVERAGEIFS(Postes!$G$5:$G$124,Postes!$A$5:$A$124,B18,Postes!$B$5:$B$124,$B$3)) | F18: =IF(OR(B18="",COUNTIFS(Postes!$A$5:$A$124,B18,Postes!$B$5:$B$124,$B$3)=0),"",IF(COUNTIFS(Postes!$A$5:$A$124,B18,Postes!$B$5:$B$124,$B$3,Postes!$L$5:$L$124,"O")>0,"O","N")) | G18: =IF(OR(B18="",COUNTIFS(Postes!$A$5:$A$124,B18,Postes!$B$5:$B$124,$B$3)=0),"",SUMIFS(Postes!$N$5:$N$124,Postes!$A$5:$A$124,B18,Postes!$B$5:$B$124,$B$3)) | H18: =IF(OR(B18="",COUNTIFS(Postes!$A$5:$A$124,B18,Postes!$B$5:$B$124,$B$3)=0),"",SUMIFS(Postes!$O$5:$O$124,Postes!$A$5:$A$124,B18,Postes!$B$5:$B$124,$B$3)) | I18: =IF(OR(B18="",COUNTIFS(Postes!$A$5:$A$124,B18,Postes!$B$5:$B$124,$B$3)=0),"",SUMIFS(Postes!$P$5:$P$124,Postes!$A$5:$A$124,B18,Postes!$B$5:$B$124,$B$3))
A19: 14 | B19: =IF(MONTH(Paramètres!$B$4+13)=MONTH(Paramètres!$B$4),Paramètres!$B$4+13,"") -> 46309 | C19: =IF(OR(B19="",COUNTIFS(Postes!$A$5:$A$124,B19,Postes!$B$5:$B$124,$B$3)=0),"",SUMIFS(Postes!$F$5:$F$124,Postes!$A$5:$A$124,B19,Postes!$B$5:$B$124,$B$3)) | D19: =IF(OR(B19="",COUNTIFS(Postes!$A$5:$A$124,B19,Postes!$B$5:$B$124,$B$3)=0),"",SUMIFS(Postes!$M$5:$M$124,Postes!$A$5:$A$124,B19,Postes!$B$5:$B$124,$B$3)) | E19: =IF(OR(B19="",COUNTIFS(Postes!$A$5:$A$124,B19,Postes!$B$5:$B$124,$B$3)=0),"",AVERAGEIFS(Postes!$G$5:$G$124,Postes!$A$5:$A$124,B19,Postes!$B$5:$B$124,$B$3)) | F19: =IF(OR(B19="",COUNTIFS(Postes!$A$5:$A$124,B19,Postes!$B$5:$B$124,$B$3)=0),"",IF(COUNTIFS(Postes!$A$5:$A$124,B19,Postes!$B$5:$B$124,$B$3,Postes!$L$5:$L$124,"O")>0,"O","N")) | G19: =IF(OR(B19="",COUNTIFS(Postes!$A$5:$A$124,B19,Postes!$B$5:$B$124,$B$3)=0),"",SUMIFS(Postes!$N$5:$N$124,Postes!$A$5:$A$124,B19,Postes!$B$5:$B$124,$B$3)) | H19: =IF(OR(B19="",COUNTIFS(Postes!$A$5:$A$124,B19,Postes!$B$5:$B$124,$B$3)=0),"",SUMIFS(Postes!$O$5:$O$124,Postes!$A$5:$A$124,B19,Postes!$B$5:$B$124,$B$3)) | I19: =IF(OR(B19="",COUNTIFS(Postes!$A$5:$A$124,B19,Postes!$B$5:$B$124,$B$3)=0),"",SUMIFS(Postes!$P$5:$P$124,Postes!$A$5:$A$124,B19,Postes!$B$5:$B$124,$B$3))
A20: 15 | B20: =IF(MONTH(Paramètres!$B$4+14)=MONTH(Paramètres!$B$4),Paramètres!$B$4+14,"") -> 46310 | C20: =IF(OR(B20="",COUNTIFS(Postes!$A$5:$A$124,B20,Postes!$B$5:$B$124,$B$3)=0),"",SUMIFS(Postes!$F$5:$F$124,Postes!$A$5:$A$124,B20,Postes!$B$5:$B$124,$B$3)) | D20: =IF(OR(B20="",COUNTIFS(Postes!$A$5:$A$124,B20,Postes!$B$5:$B$124,$B$3)=0),"",SUMIFS(Postes!$M$5:$M$124,Postes!$A$5:$A$124,B20,Postes!$B$5:$B$124,$B$3)) | E20: =IF(OR(B20="",COUNTIFS(Postes!$A$5:$A$124,B20,Postes!$B$5:$B$124,$B$3)=0),"",AVERAGEIFS(Postes!$G$5:$G$124,Postes!$A$5:$A$124,B20,Postes!$B$5:$B$124,$B$3)) | F20: =IF(OR(B20="",COUNTIFS(Postes!$A$5:$A$124,B20,Postes!$B$5:$B$124,$B$3)=0),"",IF(COUNTIFS(Postes!$A$5:$A$124,B20,Postes!$B$5:$B$124,$B$3,Postes!$L$5:$L$124,"O")>0,"O","N")) | G20: =IF(OR(B20="",COUNTIFS(Postes!$A$5:$A$124,B20,Postes!$B$5:$B$124,$B$3)=0),"",SUMIFS(Postes!$N$5:$N$124,Postes!$A$5:$A$124,B20,Postes!$B$5:$B$124,$B$3)) | H20: =IF(OR(B20="",COUNTIFS(Postes!$A$5:$A$124,B20,Postes!$B$5:$B$124,$B$3)=0),"",SUMIFS(Postes!$O$5:$O$124,Postes!$A$5:$A$124,B20,Postes!$B$5:$B$124,$B$3)) | I20: =IF(OR(B20="",COUNTIFS(Postes!$A$5:$A$124,B20,Postes!$B$5:$B$124,$B$3)=0),"",SUMIFS(Postes!$P$5:$P$124,Postes!$A$5:$A$124,B20,Postes!$B$5:$B$124,$B$3))
A21: 16 | B21: =IF(MONTH(Paramètres!$B$4+15)=MONTH(Paramètres!$B$4),Paramètres!$B$4+15,"") -> 46311 | C21: =IF(OR(B21="",COUNTIFS(Postes!$A$5:$A$124,B21,Postes!$B$5:$B$124,$B$3)=0),"",SUMIFS(Postes!$F$5:$F$124,Postes!$A$5:$A$124,B21,Postes!$B$5:$B$124,$B$3)) | D21: =IF(OR(B21="",COUNTIFS(Postes!$A$5:$A$124,B21,Postes!$B$5:$B$124,$B$3)=0),"",SUMIFS(Postes!$M$5:$M$124,Postes!$A$5:$A$124,B21,Postes!$B$5:$B$124,$B$3)) | E21: =IF(OR(B21="",COUNTIFS(Postes!$A$5:$A$124,B21,Postes!$B$5:$B$124,$B$3)=0),"",AVERAGEIFS(Postes!$G$5:$G$124,Postes!$A$5:$A$124,B21,Postes!$B$5:$B$124,$B$3)) | F21: =IF(OR(B21="",COUNTIFS(Postes!$A$5:$A$124,B21,Postes!$B$5:$B$124,$B$3)=0),"",IF(COUNTIFS(Postes!$A$5:$A$124,B21,Postes!$B$5:$B$124,$B$3,Postes!$L$5:$L$124,"O")>0,"O","N")) | G21: =IF(OR(B21="",COUNTIFS(Postes!$A$5:$A$124,B21,Postes!$B$5:$B$124,$B$3)=0),"",SUMIFS(Postes!$N$5:$N$124,Postes!$A$5:$A$124,B21,Postes!$B$5:$B$124,$B$3)) | H21: =IF(OR(B21="",COUNTIFS(Postes!$A$5:$A$124,B21,Postes!$B$5:$B$124,$B$3)=0),"",SUMIFS(Postes!$O$5:$O$124,Postes!$A$5:$A$124,B21,Postes!$B$5:$B$124,$B$3)) | I21: =IF(OR(B21="",COUNTIFS(Postes!$A$5:$A$124,B21,Postes!$B$5:$B$124,$B$3)=0),"",SUMIFS(Postes!$P$5:$P$124,Postes!$A$5:$A$124,B21,Postes!$B$5:$B$124,$B$3))
A22: 17 | B22: =IF(MONTH(Paramètres!$B$4+16)=MONTH(Paramètres!$B$4),Paramètres!$B$4+16,"") -> 46312 | C22: =IF(OR(B22="",COUNTIFS(Postes!$A$5:$A$124,B22,Postes!$B$5:$B$124,$B$3)=0),"",SUMIFS(Postes!$F$5:$F$124,Postes!$A$5:$A$124,B22,Postes!$B$5:$B$124,$B$3)) | D22: =IF(OR(B22="",COUNTIFS(Postes!$A$5:$A$124,B22,Postes!$B$5:$B$124,$B$3)=0),"",SUMIFS(Postes!$M$5:$M$124,Postes!$A$5:$A$124,B22,Postes!$B$5:$B$124,$B$3)) | E22: =IF(OR(B22="",COUNTIFS(Postes!$A$5:$A$124,B22,Postes!$B$5:$B$124,$B$3)=0),"",AVERAGEIFS(Postes!$G$5:$G$124,Postes!$A$5:$A$124,B22,Postes!$B$5:$B$124,$B$3)) | F22: =IF(OR(B22="",COUNTIFS(Postes!$A$5:$A$124,B22,Postes!$B$5:$B$124,$B$3)=0),"",IF(COUNTIFS(Postes!$A$5:$A$124,B22,Postes!$B$5:$B$124,$B$3,Postes!$L$5:$L$124,"O")>0,"O","N")) | G22: =IF(OR(B22="",COUNTIFS(Postes!$A$5:$A$124,B22,Postes!$B$5:$B$124,$B$3)=0),"",SUMIFS(Postes!$N$5:$N$124,Postes!$A$5:$A$124,B22,Postes!$B$5:$B$124,$B$3)) | H22: =IF(OR(B22="",COUNTIFS(Postes!$A$5:$A$124,B22,Postes!$B$5:$B$124,$B$3)=0),"",SUMIFS(Postes!$O$5:$O$124,Postes!$A$5:$A$124,B22,Postes!$B$5:$B$124,$B$3)) | I22: =IF(OR(B22="",COUNTIFS(Postes!$A$5:$A$124,B22,Postes!$B$5:$B$124,$B$3)=0),"",SUMIFS(Postes!$P$5:$P$124,Postes!$A$5:$A$124,B22,Postes!$B$5:$B$124,$B$3))
A23: 18 | B23: =IF(MONTH(Paramètres!$B$4+17)=MONTH(Paramètres!$B$4),Paramètres!$B$4+17,"") -> 46313 | C23: =IF(OR(B23="",COUNTIFS(Postes!$A$5:$A$124,B23,Postes!$B$5:$B$124,$B$3)=0),"",SUMIFS(Postes!$F$5:$F$124,Postes!$A$5:$A$124,B23,Postes!$B$5:$B$124,$B$3)) | D23: =IF(OR(B23="",COUNTIFS(Postes!$A$5:$A$124,B23,Postes!$B$5:$B$124,$B$3)=0),"",SUMIFS(Postes!$M$5:$M$124,Postes!$A$5:$A$124,B23,Postes!$B$5:$B$124,$B$3)) | E23: =IF(OR(B23="",COUNTIFS(Postes!$A$5:$A$124,B23,Postes!$B$5:$B$124,$B$3)=0),"",AVERAGEIFS(Postes!$G$5:$G$124,Postes!$A$5:$A$124,B23,Postes!$B$5:$B$124,$B$3)) | F23: =IF(OR(B23="",COUNTIFS(Postes!$A$5:$A$124,B23,Postes!$B$5:$B$124,$B$3)=0),"",IF(COUNTIFS(Postes!$A$5:$A$124,B23,Postes!$B$5:$B$124,$B$3,Postes!$L$5:$L$124,"O")>0,"O","N")) | G23: =IF(OR(B23="",COUNTIFS(Postes!$A$5:$A$124,B23,Postes!$B$5:$B$124,$B$3)=0),"",SUMIFS(Postes!$N$5:$N$124,Postes!$A$5:$A$124,B23,Postes!$B$5:$B$124,$B$3)) | H23: =IF(OR(B23="",COUNTIFS(Postes!$A$5:$A$124,B23,Postes!$B$5:$B$124,$B$3)=0),"",SUMIFS(Postes!$O$5:$O$124,Postes!$A$5:$A$124,B23,Postes!$B$5:$B$124,$B$3)) | I23: =IF(OR(B23="",COUNTIFS(Postes!$A$5:$A$124,B23,Postes!$B$5:$B$124,$B$3)=0),"",SUMIFS(Postes!$P$5:$P$124,Postes!$A$5:$A$124,B23,Postes!$B$5:$B$124,$B$3))
A24: 19 | B24: =IF(MONTH(Paramètres!$B$4+18)=MONTH(Paramètres!$B$4),Paramètres!$B$4+18,"") -> 46314 | C24: =IF(OR(B24="",COUNTIFS(Postes!$A$5:$A$124,B24,Postes!$B$5:$B$124,$B$3)=0),"",SUMIFS(Postes!$F$5:$F$124,Postes!$A$5:$A$124,B24,Postes!$B$5:$B$124,$B$3)) | D24: =IF(OR(B24="",COUNTIFS(Postes!$A$5:$A$124,B24,Postes!$B$5:$B$124,$B$3)=0),"",SUMIFS(Postes!$M$5:$M$124,Postes!$A$5:$A$124,B24,Postes!$B$5:$B$124,$B$3)) | E24: =IF(OR(B24="",COUNTIFS(Postes!$A$5:$A$124,B24,Postes!$B$5:$B$124,$B$3)=0),"",AVERAGEIFS(Postes!$G$5:$G$124,Postes!$A$5:$A$124,B24,Postes!$B$5:$B$124,$B$3)) | F24: =IF(OR(B24="",COUNTIFS(Postes!$A$5:$A$124,B24,Postes!$B$5:$B$124,$B$3)=0),"",IF(COUNTIFS(Postes!$A$5:$A$124,B24,Postes!$B$5:$B$124,$B$3,Postes!$L$5:$L$124,"O")>0,"O","N")) | G24: =IF(OR(B24="",COUNTIFS(Postes!$A$5:$A$124,B24,Postes!$B$5:$B$124,$B$3)=0),"",SUMIFS(Postes!$N$5:$N$124,Postes!$A$5:$A$124,B24,Postes!$B$5:$B$124,$B$3)) | H24: =IF(OR(B24="",COUNTIFS(Postes!$A$5:$A$124,B24,Postes!$B$5:$B$124,$B$3)=0),"",SUMIFS(Postes!$O$5:$O$124,Postes!$A$5:$A$124,B24,Postes!$B$5:$B$124,$B$3)) | I24: =IF(OR(B24="",COUNTIFS(Postes!$A$5:$A$124,B24,Postes!$B$5:$B$124,$B$3)=0),"",SUMIFS(Postes!$P$5:$P$124,Postes!$A$5:$A$124,B24,Postes!$B$5:$B$124,$B$3))
A25: 20 | B25: =IF(MONTH(Paramètres!$B$4+19)=MONTH(Paramètres!$B$4),Paramètres!$B$4+19,"") -> 46315 | C25: =IF(OR(B25="",COUNTIFS(Postes!$A$5:$A$124,B25,Postes!$B$5:$B$124,$B$3)=0),"",SUMIFS(Postes!$F$5:$F$124,Postes!$A$5:$A$124,B25,Postes!$B$5:$B$124,$B$3)) | D25: =IF(OR(B25="",COUNTIFS(Postes!$A$5:$A$124,B25,Postes!$B$5:$B$124,$B$3)=0),"",SUMIFS(Postes!$M$5:$M$124,Postes!$A$5:$A$124,B25,Postes!$B$5:$B$124,$B$3)) | E25: =IF(OR(B25="",COUNTIFS(Postes!$A$5:$A$124,B25,Postes!$B$5:$B$124,$B$3)=0),"",AVERAGEIFS(Postes!$G$5:$G$124,Postes!$A$5:$A$124,B25,Postes!$B$5:$B$124,$B$3)) | F25: =IF(OR(B25="",COUNTIFS(Postes!$A$5:$A$124,B25,Postes!$B$5:$B$124,$B$3)=0),"",IF(COUNTIFS(Postes!$A$5:$A$124,B25,Postes!$B$5:$B$124,$B$3,Postes!$L$5:$L$124,"O")>0,"O","N")) | G25: =IF(OR(B25="",COUNTIFS(Postes!$A$5:$A$124,B25,Postes!$B$5:$B$124,$B$3)=0),"",SUMIFS(Postes!$N$5:$N$124,Postes!$A$5:$A$124,B25,Postes!$B$5:$B$124,$B$3)) | H25: =IF(OR(B25="",COUNTIFS(Postes!$A$5:$A$124,B25,Postes!$B$5:$B$124,$B$3)=0),"",SUMIFS(Postes!$O$5:$O$124,Postes!$A$5:$A$124,B25,Postes!$B$5:$B$124,$B$3)) | I25: =IF(OR(B25="",COUNTIFS(Postes!$A$5:$A$124,B25,Postes!$B$5:$B$124,$B$3)=0),"",SUMIFS(Postes!$P$5:$P$124,Postes!$A$5:$A$124,B25,Postes!$B$5:$B$124,$B$3))
A26: 21 | B26: =IF(MONTH(Paramètres!$B$4+20)=MONTH(Paramètres!$B$4),Paramètres!$B$4+20,"") -> 46316 | C26: =IF(OR(B26="",COUNTIFS(Postes!$A$5:$A$124,B26,Postes!$B$5:$B$124,$B$3)=0),"",SUMIFS(Postes!$F$5:$F$124,Postes!$A$5:$A$124,B26,Postes!$B$5:$B$124,$B$3)) | D26: =IF(OR(B26="",COUNTIFS(Postes!$A$5:$A$124,B26,Postes!$B$5:$B$124,$B$3)=0),"",SUMIFS(Postes!$M$5:$M$124,Postes!$A$5:$A$124,B26,Postes!$B$5:$B$124,$B$3)) | E26: =IF(OR(B26="",COUNTIFS(Postes!$A$5:$A$124,B26,Postes!$B$5:$B$124,$B$3)=0),"",AVERAGEIFS(Postes!$G$5:$G$124,Postes!$A$5:$A$124,B26,Postes!$B$5:$B$124,$B$3)) | F26: =IF(OR(B26="",COUNTIFS(Postes!$A$5:$A$124,B26,Postes!$B$5:$B$124,$B$3)=0),"",IF(COUNTIFS(Postes!$A$5:$A$124,B26,Postes!$B$5:$B$124,$B$3,Postes!$L$5:$L$124,"O")>0,"O","N")) | G26: =IF(OR(B26="",COUNTIFS(Postes!$A$5:$A$124,B26,Postes!$B$5:$B$124,$B$3)=0),"",SUMIFS(Postes!$N$5:$N$124,Postes!$A$5:$A$124,B26,Postes!$B$5:$B$124,$B$3)) | H26: =IF(OR(B26="",COUNTIFS(Postes!$A$5:$A$124,B26,Postes!$B$5:$B$124,$B$3)=0),"",SUMIFS(Postes!$O$5:$O$124,Postes!$A$5:$A$124,B26,Postes!$B$5:$B$124,$B$3)) | I26: =IF(OR(B26="",COUNTIFS(Postes!$A$5:$A$124,B26,Postes!$B$5:$B$124,$B$3)=0),"",SUMIFS(Postes!$P$5:$P$124,Postes!$A$5:$A$124,B26,Postes!$B$5:$B$124,$B$3))
A27: 22 | B27: =IF(MONTH(Paramètres!$B$4+21)=MONTH(Paramètres!$B$4),Paramètres!$B$4+21,"") -> 46317 | C27: =IF(OR(B27="",COUNTIFS(Postes!$A$5:$A$124,B27,Postes!$B$5:$B$124,$B$3)=0),"",SUMIFS(Postes!$F$5:$F$124,Postes!$A$5:$A$124,B27,Postes!$B$5:$B$124,$B$3)) | D27: =IF(OR(B27="",COUNTIFS(Postes!$A$5:$A$124,B27,Postes!$B$5:$B$124,$B$3)=0),"",SUMIFS(Postes!$M$5:$M$124,Postes!$A$5:$A$124,B27,Postes!$B$5:$B$124,$B$3)) | E27: =IF(OR(B27="",COUNTIFS(Postes!$A$5:$A$124,B27,Postes!$B$5:$B$124,$B$3)=0),"",AVERAGEIFS(Postes!$G$5:$G$124,Postes!$A$5:$A$124,B27,Postes!$B$5:$B$124,$B$3)) | F27: =IF(OR(B27="",COUNTIFS(Postes!$A$5:$A$124,B27,Postes!$B$5:$B$124,$B$3)=0),"",IF(COUNTIFS(Postes!$A$5:$A$124,B27,Postes!$B$5:$B$124,$B$3,Postes!$L$5:$L$124,"O")>0,"O","N")) | G27: =IF(OR(B27="",COUNTIFS(Postes!$A$5:$A$124,B27,Postes!$B$5:$B$124,$B$3)=0),"",SUMIFS(Postes!$N$5:$N$124,Postes!$A$5:$A$124,B27,Postes!$B$5:$B$124,$B$3)) | H27: =IF(OR(B27="",COUNTIFS(Postes!$A$5:$A$124,B27,Postes!$B$5:$B$124,$B$3)=0),"",SUMIFS(Postes!$O$5:$O$124,Postes!$A$5:$A$124,B27,Postes!$B$5:$B$124,$B$3)) | I27: =IF(OR(B27="",COUNTIFS(Postes!$A$5:$A$124,B27,Postes!$B$5:$B$124,$B$3)=0),"",SUMIFS(Postes!$P$5:$P$124,Postes!$A$5:$A$124,B27,Postes!$B$5:$B$124,$B$3))
A28: 23 | B28: =IF(MONTH(Paramètres!$B$4+22)=MONTH(Paramètres!$B$4),Paramètres!$B$4+22,"") -> 46318 | C28: =IF(OR(B28="",COUNTIFS(Postes!$A$5:$A$124,B28,Postes!$B$5:$B$124,$B$3)=0),"",SUMIFS(Postes!$F$5:$F$124,Postes!$A$5:$A$124,B28,Postes!$B$5:$B$124,$B$3)) | D28: =IF(OR(B28="",COUNTIFS(Postes!$A$5:$A$124,B28,Postes!$B$5:$B$124,$B$3)=0),"",SUMIFS(Postes!$M$5:$M$124,Postes!$A$5:$A$124,B28,Postes!$B$5:$B$124,$B$3)) | E28: =IF(OR(B28="",COUNTIFS(Postes!$A$5:$A$124,B28,Postes!$B$5:$B$124,$B$3)=0),"",AVERAGEIFS(Postes!$G$5:$G$124,Postes!$A$5:$A$124,B28,Postes!$B$5:$B$124,$B$3)) | F28: =IF(OR(B28="",COUNTIFS(Postes!$A$5:$A$124,B28,Postes!$B$5:$B$124,$B$3)=0),"",IF(COUNTIFS(Postes!$A$5:$A$124,B28,Postes!$B$5:$B$124,$B$3,Postes!$L$5:$L$124,"O")>0,"O","N")) | G28: =IF(OR(B28="",COUNTIFS(Postes!$A$5:$A$124,B28,Postes!$B$5:$B$124,$B$3)=0),"",SUMIFS(Postes!$N$5:$N$124,Postes!$A$5:$A$124,B28,Postes!$B$5:$B$124,$B$3)) | H28: =IF(OR(B28="",COUNTIFS(Postes!$A$5:$A$124,B28,Postes!$B$5:$B$124,$B$3)=0),"",SUMIFS(Postes!$O$5:$O$124,Postes!$A$5:$A$124,B28,Postes!$B$5:$B$124,$B$3)) | I28: =IF(OR(B28="",COUNTIFS(Postes!$A$5:$A$124,B28,Postes!$B$5:$B$124,$B$3)=0),"",SUMIFS(Postes!$P$5:$P$124,Postes!$A$5:$A$124,B28,Postes!$B$5:$B$124,$B$3))
A29: 24 | B29: =IF(MONTH(Paramètres!$B$4+23)=MONTH(Paramètres!$B$4),Paramètres!$B$4+23,"") -> 46319 | C29: =IF(OR(B29="",COUNTIFS(Postes!$A$5:$A$124,B29,Postes!$B$5:$B$124,$B$3)=0),"",SUMIFS(Postes!$F$5:$F$124,Postes!$A$5:$A$124,B29,Postes!$B$5:$B$124,$B$3)) | D29: =IF(OR(B29="",COUNTIFS(Postes!$A$5:$A$124,B29,Postes!$B$5:$B$124,$B$3)=0),"",SUMIFS(Postes!$M$5:$M$124,Postes!$A$5:$A$124,B29,Postes!$B$5:$B$124,$B$3)) | E29: =IF(OR(B29="",COUNTIFS(Postes!$A$5:$A$124,B29,Postes!$B$5:$B$124,$B$3)=0),"",AVERAGEIFS(Postes!$G$5:$G$124,Postes!$A$5:$A$124,B29,Postes!$B$5:$B$124,$B$3)) | F29: =IF(OR(B29="",COUNTIFS(Postes!$A$5:$A$124,B29,Postes!$B$5:$B$124,$B$3)=0),"",IF(COUNTIFS(Postes!$A$5:$A$124,B29,Postes!$B$5:$B$124,$B$3,Postes!$L$5:$L$124,"O")>0,"O","N")) | G29: =IF(OR(B29="",COUNTIFS(Postes!$A$5:$A$124,B29,Postes!$B$5:$B$124,$B$3)=0),"",SUMIFS(Postes!$N$5:$N$124,Postes!$A$5:$A$124,B29,Postes!$B$5:$B$124,$B$3)) | H29: =IF(OR(B29="",COUNTIFS(Postes!$A$5:$A$124,B29,Postes!$B$5:$B$124,$B$3)=0),"",SUMIFS(Postes!$O$5:$O$124,Postes!$A$5:$A$124,B29,Postes!$B$5:$B$124,$B$3)) | I29: =IF(OR(B29="",COUNTIFS(Postes!$A$5:$A$124,B29,Postes!$B$5:$B$124,$B$3)=0),"",SUMIFS(Postes!$P$5:$P$124,Postes!$A$5:$A$124,B29,Postes!$B$5:$B$124,$B$3))
A30: 25 | B30: =IF(MONTH(Paramètres!$B$4+24)=MONTH(Paramètres!$B$4),Paramètres!$B$4+24,"") -> 46320 | C30: =IF(OR(B30="",COUNTIFS(Postes!$A$5:$A$124,B30,Postes!$B$5:$B$124,$B$3)=0),"",SUMIFS(Postes!$F$5:$F$124,Postes!$A$5:$A$124,B30,Postes!$B$5:$B$124,$B$3)) | D30: =IF(OR(B30="",COUNTIFS(Postes!$A$5:$A$124,B30,Postes!$B$5:$B$124,$B$3)=0),"",SUMIFS(Postes!$M$5:$M$124,Postes!$A$5:$A$124,B30,Postes!$B$5:$B$124,$B$3)) | E30: =IF(OR(B30="",COUNTIFS(Postes!$A$5:$A$124,B30,Postes!$B$5:$B$124,$B$3)=0),"",AVERAGEIFS(Postes!$G$5:$G$124,Postes!$A$5:$A$124,B30,Postes!$B$5:$B$124,$B$3)) | F30: =IF(OR(B30="",COUNTIFS(Postes!$A$5:$A$124,B30,Postes!$B$5:$B$124,$B$3)=0),"",IF(COUNTIFS(Postes!$A$5:$A$124,B30,Postes!$B$5:$B$124,$B$3,Postes!$L$5:$L$124,"O")>0,"O","N")) | G30: =IF(OR(B30="",COUNTIFS(Postes!$A$5:$A$124,B30,Postes!$B$5:$B$124,$B$3)=0),"",SUMIFS(Postes!$N$5:$N$124,Postes!$A$5:$A$124,B30,Postes!$B$5:$B$124,$B$3)) | H30: =IF(OR(B30="",COUNTIFS(Postes!$A$5:$A$124,B30,Postes!$B$5:$B$124,$B$3)=0),"",SUMIFS(Postes!$O$5:$O$124,Postes!$A$5:$A$124,B30,Postes!$B$5:$B$124,$B$3)) | I30: =IF(OR(B30="",COUNTIFS(Postes!$A$5:$A$124,B30,Postes!$B$5:$B$124,$B$3)=0),"",SUMIFS(Postes!$P$5:$P$124,Postes!$A$5:$A$124,B30,Postes!$B$5:$B$124,$B$3))
A31: 26 | B31: =IF(MONTH(Paramètres!$B$4+25)=MONTH(Paramètres!$B$4),Paramètres!$B$4+25,"") -> 46321 | C31: =IF(OR(B31="",COUNTIFS(Postes!$A$5:$A$124,B31,Postes!$B$5:$B$124,$B$3)=0),"",SUMIFS(Postes!$F$5:$F$124,Postes!$A$5:$A$124,B31,Postes!$B$5:$B$124,$B$3)) | D31: =IF(OR(B31="",COUNTIFS(Postes!$A$5:$A$124,B31,Postes!$B$5:$B$124,$B$3)=0),"",SUMIFS(Postes!$M$5:$M$124,Postes!$A$5:$A$124,B31,Postes!$B$5:$B$124,$B$3)) | E31: =IF(OR(B31="",COUNTIFS(Postes!$A$5:$A$124,B31,Postes!$B$5:$B$124,$B$3)=0),"",AVERAGEIFS(Postes!$G$5:$G$124,Postes!$A$5:$A$124,B31,Postes!$B$5:$B$124,$B$3)) | F31: =IF(OR(B31="",COUNTIFS(Postes!$A$5:$A$124,B31,Postes!$B$5:$B$124,$B$3)=0),"",IF(COUNTIFS(Postes!$A$5:$A$124,B31,Postes!$B$5:$B$124,$B$3,Postes!$L$5:$L$124,"O")>0,"O","N")) | G31: =IF(OR(B31="",COUNTIFS(Postes!$A$5:$A$124,B31,Postes!$B$5:$B$124,$B$3)=0),"",SUMIFS(Postes!$N$5:$N$124,Postes!$A$5:$A$124,B31,Postes!$B$5:$B$124,$B$3)) | H31: =IF(OR(B31="",COUNTIFS(Postes!$A$5:$A$124,B31,Postes!$B$5:$B$124,$B$3)=0),"",SUMIFS(Postes!$O$5:$O$124,Postes!$A$5:$A$124,B31,Postes!$B$5:$B$124,$B$3)) | I31: =IF(OR(B31="",COUNTIFS(Postes!$A$5:$A$124,B31,Postes!$B$5:$B$124,$B$3)=0),"",SUMIFS(Postes!$P$5:$P$124,Postes!$A$5:$A$124,B31,Postes!$B$5:$B$124,$B$3))
A32: 27 | B32: =IF(MONTH(Paramètres!$B$4+26)=MONTH(Paramètres!$B$4),Paramètres!$B$4+26,"") -> 46322 | C32: =IF(OR(B32="",COUNTIFS(Postes!$A$5:$A$124,B32,Postes!$B$5:$B$124,$B$3)=0),"",SUMIFS(Postes!$F$5:$F$124,Postes!$A$5:$A$124,B32,Postes!$B$5:$B$124,$B$3)) | D32: =IF(OR(B32="",COUNTIFS(Postes!$A$5:$A$124,B32,Postes!$B$5:$B$124,$B$3)=0),"",SUMIFS(Postes!$M$5:$M$124,Postes!$A$5:$A$124,B32,Postes!$B$5:$B$124,$B$3)) | E32: =IF(OR(B32="",COUNTIFS(Postes!$A$5:$A$124,B32,Postes!$B$5:$B$124,$B$3)=0),"",AVERAGEIFS(Postes!$G$5:$G$124,Postes!$A$5:$A$124,B32,Postes!$B$5:$B$124,$B$3)) | F32: =IF(OR(B32="",COUNTIFS(Postes!$A$5:$A$124,B32,Postes!$B$5:$B$124,$B$3)=0),"",IF(COUNTIFS(Postes!$A$5:$A$124,B32,Postes!$B$5:$B$124,$B$3,Postes!$L$5:$L$124,"O")>0,"O","N")) | G32: =IF(OR(B32="",COUNTIFS(Postes!$A$5:$A$124,B32,Postes!$B$5:$B$124,$B$3)=0),"",SUMIFS(Postes!$N$5:$N$124,Postes!$A$5:$A$124,B32,Postes!$B$5:$B$124,$B$3)) | H32: =IF(OR(B32="",COUNTIFS(Postes!$A$5:$A$124,B32,Postes!$B$5:$B$124,$B$3)=0),"",SUMIFS(Postes!$O$5:$O$124,Postes!$A$5:$A$124,B32,Postes!$B$5:$B$124,$B$3)) | I32: =IF(OR(B32="",COUNTIFS(Postes!$A$5:$A$124,B32,Postes!$B$5:$B$124,$B$3)=0),"",SUMIFS(Postes!$P$5:$P$124,Postes!$A$5:$A$124,B32,Postes!$B$5:$B$124,$B$3))
A33: 28 | B33: =IF(MONTH(Paramètres!$B$4+27)=MONTH(Paramètres!$B$4),Paramètres!$B$4+27,"") -> 46323 | C33: =IF(OR(B33="",COUNTIFS(Postes!$A$5:$A$124,B33,Postes!$B$5:$B$124,$B$3)=0),"",SUMIFS(Postes!$F$5:$F$124,Postes!$A$5:$A$124,B33,Postes!$B$5:$B$124,$B$3)) | D33: =IF(OR(B33="",COUNTIFS(Postes!$A$5:$A$124,B33,Postes!$B$5:$B$124,$B$3)=0),"",SUMIFS(Postes!$M$5:$M$124,Postes!$A$5:$A$124,B33,Postes!$B$5:$B$124,$B$3)) | E33: =IF(OR(B33="",COUNTIFS(Postes!$A$5:$A$124,B33,Postes!$B$5:$B$124,$B$3)=0),"",AVERAGEIFS(Postes!$G$5:$G$124,Postes!$A$5:$A$124,B33,Postes!$B$5:$B$124,$B$3)) | F33: =IF(OR(B33="",COUNTIFS(Postes!$A$5:$A$124,B33,Postes!$B$5:$B$124,$B$3)=0),"",IF(COUNTIFS(Postes!$A$5:$A$124,B33,Postes!$B$5:$B$124,$B$3,Postes!$L$5:$L$124,"O")>0,"O","N")) | G33: =IF(OR(B33="",COUNTIFS(Postes!$A$5:$A$124,B33,Postes!$B$5:$B$124,$B$3)=0),"",SUMIFS(Postes!$N$5:$N$124,Postes!$A$5:$A$124,B33,Postes!$B$5:$B$124,$B$3)) | H33: =IF(OR(B33="",COUNTIFS(Postes!$A$5:$A$124,B33,Postes!$B$5:$B$124,$B$3)=0),"",SUMIFS(Postes!$O$5:$O$124,Postes!$A$5:$A$124,B33,Postes!$B$5:$B$124,$B$3)) | I33: =IF(OR(B33="",COUNTIFS(Postes!$A$5:$A$124,B33,Postes!$B$5:$B$124,$B$3)=0),"",SUMIFS(Postes!$P$5:$P$124,Postes!$A$5:$A$124,B33,Postes!$B$5:$B$124,$B$3))
A34: 29 | B34: =IF(MONTH(Paramètres!$B$4+28)=MONTH(Paramètres!$B$4),Paramètres!$B$4+28,"") -> 46324 | C34: =IF(OR(B34="",COUNTIFS(Postes!$A$5:$A$124,B34,Postes!$B$5:$B$124,$B$3)=0),"",SUMIFS(Postes!$F$5:$F$124,Postes!$A$5:$A$124,B34,Postes!$B$5:$B$124,$B$3)) | D34: =IF(OR(B34="",COUNTIFS(Postes!$A$5:$A$124,B34,Postes!$B$5:$B$124,$B$3)=0),"",SUMIFS(Postes!$M$5:$M$124,Postes!$A$5:$A$124,B34,Postes!$B$5:$B$124,$B$3)) | E34: =IF(OR(B34="",COUNTIFS(Postes!$A$5:$A$124,B34,Postes!$B$5:$B$124,$B$3)=0),"",AVERAGEIFS(Postes!$G$5:$G$124,Postes!$A$5:$A$124,B34,Postes!$B$5:$B$124,$B$3)) | F34: =IF(OR(B34="",COUNTIFS(Postes!$A$5:$A$124,B34,Postes!$B$5:$B$124,$B$3)=0),"",IF(COUNTIFS(Postes!$A$5:$A$124,B34,Postes!$B$5:$B$124,$B$3,Postes!$L$5:$L$124,"O")>0,"O","N")) | G34: =IF(OR(B34="",COUNTIFS(Postes!$A$5:$A$124,B34,Postes!$B$5:$B$124,$B$3)=0),"",SUMIFS(Postes!$N$5:$N$124,Postes!$A$5:$A$124,B34,Postes!$B$5:$B$124,$B$3)) | H34: =IF(OR(B34="",COUNTIFS(Postes!$A$5:$A$124,B34,Postes!$B$5:$B$124,$B$3)=0),"",SUMIFS(Postes!$O$5:$O$124,Postes!$A$5:$A$124,B34,Postes!$B$5:$B$124,$B$3)) | I34: =IF(OR(B34="",COUNTIFS(Postes!$A$5:$A$124,B34,Postes!$B$5:$B$124,$B$3)=0),"",SUMIFS(Postes!$P$5:$P$124,Postes!$A$5:$A$124,B34,Postes!$B$5:$B$124,$B$3))
A35: 30 | B35: =IF(MONTH(Paramètres!$B$4+29)=MONTH(Paramètres!$B$4),Paramètres!$B$4+29,"") -> 46325 | C35: =IF(OR(B35="",COUNTIFS(Postes!$A$5:$A$124,B35,Postes!$B$5:$B$124,$B$3)=0),"",SUMIFS(Postes!$F$5:$F$124,Postes!$A$5:$A$124,B35,Postes!$B$5:$B$124,$B$3)) | D35: =IF(OR(B35="",COUNTIFS(Postes!$A$5:$A$124,B35,Postes!$B$5:$B$124,$B$3)=0),"",SUMIFS(Postes!$M$5:$M$124,Postes!$A$5:$A$124,B35,Postes!$B$5:$B$124,$B$3)) | E35: =IF(OR(B35="",COUNTIFS(Postes!$A$5:$A$124,B35,Postes!$B$5:$B$124,$B$3)=0),"",AVERAGEIFS(Postes!$G$5:$G$124,Postes!$A$5:$A$124,B35,Postes!$B$5:$B$124,$B$3)) | F35: =IF(OR(B35="",COUNTIFS(Postes!$A$5:$A$124,B35,Postes!$B$5:$B$124,$B$3)=0),"",IF(COUNTIFS(Postes!$A$5:$A$124,B35,Postes!$B$5:$B$124,$B$3,Postes!$L$5:$L$124,"O")>0,"O","N")) | G35: =IF(OR(B35="",COUNTIFS(Postes!$A$5:$A$124,B35,Postes!$B$5:$B$124,$B$3)=0),"",SUMIFS(Postes!$N$5:$N$124,Postes!$A$5:$A$124,B35,Postes!$B$5:$B$124,$B$3)) | H35: =IF(OR(B35="",COUNTIFS(Postes!$A$5:$A$124,B35,Postes!$B$5:$B$124,$B$3)=0),"",SUMIFS(Postes!$O$5:$O$124,Postes!$A$5:$A$124,B35,Postes!$B$5:$B$124,$B$3)) | I35: =IF(OR(B35="",COUNTIFS(Postes!$A$5:$A$124,B35,Postes!$B$5:$B$124,$B$3)=0),"",SUMIFS(Postes!$P$5:$P$124,Postes!$A$5:$A$124,B35,Postes!$B$5:$B$124,$B$3))
A36: 31 | B36: =IF(MONTH(Paramètres!$B$4+30)=MONTH(Paramètres!$B$4),Paramètres!$B$4+30,"") -> 46326 | C36: =IF(OR(B36="",COUNTIFS(Postes!$A$5:$A$124,B36,Postes!$B$5:$B$124,$B$3)=0),"",SUMIFS(Postes!$F$5:$F$124,Postes!$A$5:$A$124,B36,Postes!$B$5:$B$124,$B$3)) | D36: =IF(OR(B36="",COUNTIFS(Postes!$A$5:$A$124,B36,Postes!$B$5:$B$124,$B$3)=0),"",SUMIFS(Postes!$M$5:$M$124,Postes!$A$5:$A$124,B36,Postes!$B$5:$B$124,$B$3)) | E36: =IF(OR(B36="",COUNTIFS(Postes!$A$5:$A$124,B36,Postes!$B$5:$B$124,$B$3)=0),"",AVERAGEIFS(Postes!$G$5:$G$124,Postes!$A$5:$A$124,B36,Postes!$B$5:$B$124,$B$3)) | F36: =IF(OR(B36="",COUNTIFS(Postes!$A$5:$A$124,B36,Postes!$B$5:$B$124,$B$3)=0),"",IF(COUNTIFS(Postes!$A$5:$A$124,B36,Postes!$B$5:$B$124,$B$3,Postes!$L$5:$L$124,"O")>0,"O","N")) | G36: =IF(OR(B36="",COUNTIFS(Postes!$A$5:$A$124,B36,Postes!$B$5:$B$124,$B$3)=0),"",SUMIFS(Postes!$N$5:$N$124,Postes!$A$5:$A$124,B36,Postes!$B$5:$B$124,$B$3)) | H36: =IF(OR(B36="",COUNTIFS(Postes!$A$5:$A$124,B36,Postes!$B$5:$B$124,$B$3)=0),"",SUMIFS(Postes!$O$5:$O$124,Postes!$A$5:$A$124,B36,Postes!$B$5:$B$124,$B$3)) | I36: =IF(OR(B36="",COUNTIFS(Postes!$A$5:$A$124,B36,Postes!$B$5:$B$124,$B$3)=0),"",SUMIFS(Postes!$P$5:$P$124,Postes!$A$5:$A$124,B36,Postes!$B$5:$B$124,$B$3))
A37: Total | C37: =SUM(C6:C36) -> 13 | D37: =SUM(D6:D36) -> 3 | G37: =SUM(G6:G36) -> 4500
A39: Jours travaillés : | C39: =COUNT(C6:C36) -> 1 | D39: Jours primés : | E39: =COUNTIF(G6:G36,">0") -> 1 | F39: Prime totale : | G39: =G37 -> 4500
A42: Chef de production — nom et signature : | F42: Direction — nom et signature :

Sheet État employés
A1: SARL DPR AXXAM — État mensuel des primes — par employé
A2: À remettre à la paie. Se remplit depuis « Employés » et « Présences ».
A3: Mois : | B3: =Paramètres!B4 -> 46296 | D3: À verser avec la paie du mois de : | F3: =IF(Paramètres!B8="","",Paramètres!B8)
A5: N° | B5: Nom et prénom | C5: Poste | D5: Équipe | E5: Jours de présence | F5: Jours primés | G5: Total prime | H5: Émargement
A6: 1 | B6: =IF(Employés!B5="","",Employés!B5) -> BENALI Karim | C6: =IF(Employés!B5="","",IF(Employés!C5="","",Employés!C5)) -> Dépileur | D6: =IF(Employés!B5="","",IF(Employés!D5="","",Employés!D5)) -> Équipe A | E6: =IF(B6="","",COUNTIFS(Présences!$C$5:$C$1204,B6,Présences!$A$5:$A$1204,">="&Paramètres!$B$4,Présences!$A$5:$A$1204,"<"&Paramètres!$B$17)) -> 1 | F6: =IF(B6="","",COUNTIFS(Présences!$C$5:$C$1204,B6,Présences!$A$5:$A$1204,">="&Paramètres!$B$4,Présences!$A$5:$A$1204,"<"&Paramètres!$B$17,Présences!$E$5:$E$1204,">0")) -> 1 | G6: =IF(B6="","",SUMIFS(Présences!$E$5:$E$1204,Présences!$C$5:$C$1204,B6,Présences!$A$5:$A$1204,">="&Paramètres!$B$4,Présences!$A$5:$A$1204,"<"&Paramètres!$B$17)) -> 2250
A7: 2 | B7: =IF(Employés!B6="","",Employés!B6) -> HADDAD Samir | C7: =IF(Employés!B6="","",IF(Employés!C6="","",Employés!C6)) -> Dépileur | D7: =IF(Employés!B6="","",IF(Employés!D6="","",Employés!D6)) -> Équipe A | E7: =IF(B7="","",COUNTIFS(Présences!$C$5:$C$1204,B7,Présences!$A$5:$A$1204,">="&Paramètres!$B$4,Présences!$A$5:$A$1204,"<"&Paramètres!$B$17)) -> 1 | F7: =IF(B7="","",COUNTIFS(Présences!$C$5:$C$1204,B7,Présences!$A$5:$A$1204,">="&Paramètres!$B$4,Présences!$A$5:$A$1204,"<"&Paramètres!$B$17,Présences!$E$5:$E$1204,">0")) -> 1 | G7: =IF(B7="","",SUMIFS(Présences!$E$5:$E$1204,Présences!$C$5:$C$1204,B7,Présences!$A$5:$A$1204,">="&Paramètres!$B$4,Présences!$A$5:$A$1204,"<"&Paramètres!$B$17)) -> 2250
A8: 3 | B8: =IF(Employés!B7="","",Employés!B7) -> MEZIANE Yacine | C8: =IF(Employés!B7="","",IF(Employés!C7="","",Employés!C7)) -> Cariste | D8: =IF(Employés!B7="","",IF(Employés!D7="","",Employés!D7)) -> Équipe A | E8: =IF(B8="","",COUNTIFS(Présences!$C$5:$C$1204,B8,Présences!$A$5:$A$1204,">="&Paramètres!$B$4,Présences!$A$5:$A$1204,"<"&Paramètres!$B$17)) -> 1 | F8: =IF(B8="","",COUNTIFS(Présences!$C$5:$C$1204,B8,Présences!$A$5:$A$1204,">="&Paramètres!$B$4,Présences!$A$5:$A$1204,"<"&Paramètres!$B$17,Présences!$E$5:$E$1204,">0")) -> 0 | G8: =IF(B8="","",SUMIFS(Présences!$E$5:$E$1204,Présences!$C$5:$C$1204,B8,Présences!$A$5:$A$1204,">="&Paramètres!$B$4,Présences!$A$5:$A$1204,"<"&Paramètres!$B$17)) -> 0
A9: 4 | B9: =IF(Employés!B8="","",Employés!B8) | C9: =IF(Employés!B8="","",IF(Employés!C8="","",Employés!C8)) | D9: =IF(Employés!B8="","",IF(Employés!D8="","",Employés!D8)) | E9: =IF(B9="","",COUNTIFS(Présences!$C$5:$C$1204,B9,Présences!$A$5:$A$1204,">="&Paramètres!$B$4,Présences!$A$5:$A$1204,"<"&Paramètres!$B$17)) | F9: =IF(B9="","",COUNTIFS(Présences!$C$5:$C$1204,B9,Présences!$A$5:$A$1204,">="&Paramètres!$B$4,Présences!$A$5:$A$1204,"<"&Paramètres!$B$17,Présences!$E$5:$E$1204,">0")) | G9: =IF(B9="","",SUMIFS(Présences!$E$5:$E$1204,Présences!$C$5:$C$1204,B9,Présences!$A$5:$A$1204,">="&Paramètres!$B$4,Présences!$A$5:$A$1204,"<"&Paramètres!$B$17))
A10: 5 | B10: =IF(Employés!B9="","",Employés!B9) | C10: =IF(Employés!B9="","",IF(Employés!C9="","",Employés!C9)) | D10: =IF(Employés!B9="","",IF(Employés!D9="","",Employés!D9)) | E10: =IF(B10="","",COUNTIFS(Présences!$C$5:$C$1204,B10,Présences!$A$5:$A$1204,">="&Paramètres!$B$4,Présences!$A$5:$A$1204,"<"&Paramètres!$B$17)) | F10: =IF(B10="","",COUNTIFS(Présences!$C$5:$C$1204,B10,Présences!$A$5:$A$1204,">="&Paramètres!$B$4,Présences!$A$5:$A$1204,"<"&Paramètres!$B$17,Présences!$E$5:$E$1204,">0")) | G10: =IF(B10="","",SUMIFS(Présences!$E$5:$E$1204,Présences!$C$5:$C$1204,B10,Présences!$A$5:$A$1204,">="&Paramètres!$B$4,Présences!$A$5:$A$1204,"<"&Paramètres!$B$17))
A11: 6 | B11: =IF(Employés!B10="","",Employés!B10) | C11: =IF(Employés!B10="","",IF(Employés!C10="","",Employés!C10)) | D11: =IF(Employés!B10="","",IF(Employés!D10="","",Employés!D10)) | E11: =IF(B11="","",COUNTIFS(Présences!$C$5:$C$1204,B11,Présences!$A$5:$A$1204,">="&Paramètres!$B$4,Présences!$A$5:$A$1204,"<"&Paramètres!$B$17)) | F11: =IF(B11="","",COUNTIFS(Présences!$C$5:$C$1204,B11,Présences!$A$5:$A$1204,">="&Paramètres!$B$4,Présences!$A$5:$A$1204,"<"&Paramètres!$B$17,Présences!$E$5:$E$1204,">0")) | G11: =IF(B11="","",SUMIFS(Présences!$E$5:$E$1204,Présences!$C$5:$C$1204,B11,Présences!$A$5:$A$1204,">="&Paramètres!$B$4,Présences!$A$5:$A$1204,"<"&Paramètres!$B$17))
A12: 7 | B12: =IF(Employés!B11="","",Employés!B11) | C12: =IF(Employés!B11="","",IF(Employés!C11="","",Employés!C11)) | D12: =IF(Employés!B11="","",IF(Employés!D11="","",Employés!D11)) | E12: =IF(B12="","",COUNTIFS(Présences!$C$5:$C$1204,B12,Présences!$A$5:$A$1204,">="&Paramètres!$B$4,Présences!$A$5:$A$1204,"<"&Paramètres!$B$17)) | F12: =IF(B12="","",COUNTIFS(Présences!$C$5:$C$1204,B12,Présences!$A$5:$A$1204,">="&Paramètres!$B$4,Présences!$A$5:$A$1204,"<"&Paramètres!$B$17,Présences!$E$5:$E$1204,">0")) | G12: =IF(B12="","",SUMIFS(Présences!$E$5:$E$1204,Présences!$C$5:$C$1204,B12,Présences!$A$5:$A$1204,">="&Paramètres!$B$4,Présences!$A$5:$A$1204,"<"&Paramètres!$B$17))
